Workbook

Sheet 어린이집수
A1: 시도별 어린이집 수 (단위: 개소, 2009~2026)
A2: 2026은 조회 시점 최신값(기준월 미확인). 2023년부터 포털이 광주+전남을 합쳐서 제공.
A4: 시도 | B4: 2009 | C4: 2010 | D4: 2011 | E4: 2012 | F4: 2013 | G4: 2014 | H4: 2015 | I4: 2016 | J4: 2017 | K4: 2018 | L4: 2019 | M4: 2020 | N4: 2021 | O4: 2022 | P4: 2023 | Q4: 2024 | R4: 2025 | S4: 2026
A5: 서울 | B5: =원자료!B5 -> 5684 | C5: =원자료!C5 -> 5870 | D5: =원자료!D5 -> 6105 | E5: =원자료!E5 -> 6538 | F5: =원자료!F5 -> 6742 | G5: =원자료!G5 -> 6787 | H5: =원자료!H5 -> 6598 | I5: =원자료!I5 -> 6368 | ... S5: =원자료!S5 -> 3875
A6: 부산 | B6: =원자료!B6 -> 1655 | C6: =원자료!C6 -> 1689 | D6: =원자료!D6 -> 1740 | E6: =원자료!E6 -> 1830 | F6: =원자료!F6 -> 1897 | G6: =원자료!G6 -> 1957 | H6: =원자료!H6 -> 1971 | I6: =원자료!I6 -> 1937 | ... S6: =원자료!S6 -> 1216
A7: 대구 | B7: =원자료!B7 -> 1500 | C7: =원자료!C7 -> 1544 | D7: =원자료!D7 -> 1561 | E7: =원자료!E7 -> 1580 | F7: =원자료!F7 -> 1590 | G7: =원자료!G7 -> 1588 | H7: =원자료!H7 -> 1539 | I7: =원자료!I7 -> 1483 | ... S7: =원자료!S7 -> 964
A8: 인천 | B8: =원자료!B8 -> 1773 | C8: =원자료!C8 -> 1857 | D8: =원자료!D8 -> 1998 | E8: =원자료!E8 -> 2181 | F8: =원자료!F8 -> 2263 | G8: =원자료!G8 -> 2308 | H8: =원자료!H8 -> 2278 | I8: =원자료!I8 -> 2231 | ... S8: =원자료!S8 -> 1529
A9: 대전 | B9: =원자료!B9 -> 1417 | C9: =원자료!C9 -> 1535 | D9: =원자료!D9 -> 1599 | E9: =원자료!E9 -> 1659 | F9: =원자료!F9 -> 1680 | G9: =원자료!G9 -> 1698 | H9: =원자료!H9 -> 1669 | I9: =원자료!I9 -> 1584 | ... S9: =원자료!S9 -> 791
A10: 울산 | B10: =원자료!B10 -> 660 | C10: =원자료!C10 -> 754 | D10: =원자료!D10 -> 818 | E10: =원자료!E10 -> 893 | F10: =원자료!F10 -> 933 | G10: =원자료!G10 -> 946 | H10: =원자료!H10 -> 934 | I10: =원자료!I10 -> 895 | ... S10: =원자료!S10 -> 512
A11: 세종 | B11: =원자료!B11 -> 0 | C11: =원자료!C11 -> 0 | D11: =원자료!D11 -> 0 | E11: =원자료!E11 -> 106 | F11: =원자료!F11 -> 118 | G11: =원자료!G11 -> 160 | H11: =원자료!H11 -> 216 | I11: =원자료!I11 -> 250 | ... S11: =원자료!S11 -> 269
A12: 경기 | B12: =원자료!B12 -> 10465 | C12: =원자료!C12 -> 11273 | D12: =원자료!D12 -> 11825 | E12: =원자료!E12 -> 12869 | F12: =원자료!F12 -> 13364 | G12: =원자료!G12 -> 13259 | H12: =원자료!H12 -> 12689 | I12: =원자료!I12 -> 12120 | ... S12: =원자료!S12 -> 7774
A13: 강원 | B13: =원자료!B13 -> 926 | C13: =원자료!C13 -> 1085 | D13: =원자료!D13 -> 1147 | E13: =원자료!E13 -> 1244 | F13: =원자료!F13 -> 1265 | G13: =원자료!G13 -> 1257 | H13: =원자료!H13 -> 1227 | I13: =원자료!I13 -> 1180 | ... S13: =원자료!S13 -> 748
A14: 충북 | B14: =원자료!B14 -> 1037 | C14: =원자료!C14 -> 1112 | D14: =원자료!D14 -> 1133 | E14: =원자료!E14 -> 1179 | F14: =원자료!F14 -> 1212 | G14: =원자료!G14 -> 1229 | H14: =원자료!H14 -> 1230 | I14: =원자료!I14 -> 1208 | ... S14: =원자료!S14 -> 800
A15: 충남 | B15: =원자료!B15 -> 1470 | C15: =원자료!C15 -> 1687 | D15: =원자료!D15 -> 1857 | E15: =원자료!E15 -> 1991 | F15: =원자료!F15 -> 2083 | G15: =원자료!G15 -> 2053 | H15: =원자료!H15 -> 1988 | I15: =원자료!I15 -> 1974 | ... S15: =원자료!S15 -> 1206
A16: 전북 | B16: =원자료!B16 -> 1506 | C16: =원자료!C16 -> 1531 | D16: =원자료!D16 -> 1580 | E16: =원자료!E16 -> 1620 | F16: =원자료!F16 -> 1647 | G16: =원자료!G16 -> 1654 | H16: =원자료!H16 -> 1623 | I16: =원자료!I16 -> 1562 | ... S16: =원자료!S16 -> 832
... A19: 제주 | B19: =원자료!B19 -> 502 | C19: =원자료!C19 -> 525 | D19: =원자료!D19 -> 552 | E19: =원자료!E19 -> 584 | F19: =원자료!F19 -> 604 | G19: =원자료!G19 -> 599 | H19: =원자료!H19 -> 574 | I19: =원자료!I19 -> 543 | ... S19: =원자료!S19 -> 365
A20: 전남광주(광주+전남) | B20: =원자료!B22 -> 2267 | C20: =원자료!C22 -> 2327 | D20: =원자료!D22 -> 2366 | E20: =원자료!E22 -> 2427 | F20: =원자료!F22 -> 2473 | G20: =원자료!G22 -> 2502 | H20: =원자료!H22 -> 2502 | I20: =원자료!I22 -> 2489 | ... S20: =원자료!S22 -> 1568
A21: 전국 합계(수식) | B21: =SUM(B5:B20) -> 35550 | C21: =SUM(C5:C20) -> 38021 | D21: =SUM(D5:D20) -> 39842 | E21: =SUM(E5:E20) -> 42527 | F21: =SUM(F5:F20) -> 43770 | G21: =SUM(G5:G20) -> 43742 | H21: =SUM(H5:H20) -> 42517 | I21: =SUM(I5:I20) -> 41084 | ... S21: =SUM(S5:S20) -> 25042
A22: 전국(공표값) | B22: =원자료!B23 -> 35550 | C22: =원자료!C23 -> 38021 | D22: =원자료!D23 -> 39842 | E22: =원자료!E23 -> 42527 | F22: =원자료!F23 -> 43770 | G22: =원자료!G23 -> 43742 | H22: =원자료!H23 -> 42517 | I22: =원자료!I23 -> 41084 | ... S22: =원자료!S23 -> 25042
A23: 검증(합계-공표값) | B23: =B21-B22 -> 0 | C23: =C21-C22 -> 0 | D23: =D21-D22 -> 0 | E23: =E21-E22 -> 0 | F23: =F21-F22 -> 0 | G23: =G21-G22 -> 0 | H23: =H21-H22 -> 0 | I23: =I21-I22 -> 0 | ... S23: =S21-S22 -> 0

Sheet 정원(명)
A1: 시도별 어린이집 정원 (단위: 명, 2010~2022)
A2: 정원 = 어린이집이 인가받은 최대 수용 인원의 합계.
A4: 시도 | B4: 2010 | C4: 2011 | D4: 2012 | E4: 2013 | F4: 2014 | G4: 2015 | H4: 2016 | I4: 2017 | J4: 2018 | K4: 2019 | L4: 2020 | M4: 2021 | N4: 2022
A5: 서울 | B5: =원자료!B28 -> 236339 | C5: =원자료!C28 -> 243440 | D5: =원자료!D28 -> 261870 | E5: =원자료!E28 -> 270458 | F5: =원자료!F28 -> 275464 | G5: =원자료!G28 -> 274132 | H5: =원자료!H28 -> 270231 | I5: =원자료!I28 -> 268100 | ... N5: =원자료!N28 -> 223628
A6: 부산 | B6: =원자료!B29 -> 79526 | C6: =원자료!C29 -> 80583 | D6: =원자료!D29 -> 84863 | E6: =원자료!E29 -> 87238 | F6: =원자료!F29 -> 89078 | G6: =원자료!G29 -> 90014 | H6: =원자료!H29 -> 89658 | I6: =원자료!I29 -> 89040 | ... N6: =원자료!N29 -> 76146
A7: 대구 | B7: =원자료!B30 -> 76276 | C7: =원자료!C30 -> 77218 | D7: =원자료!D30 -> 79769 | E7: =원자료!E30 -> 79638 | F7: =원자료!F30 -> 79274 | G7: =원자료!G30 -> 77547 | H7: =원자료!H30 -> 75255 | I7: =원자료!I30 -> 74696 | ... N7: =원자료!N30 -> 59434
A8: 인천 | B8: =원자료!B31 -> 75533 | C8: =원자료!C31 -> 82245 | D8: =원자료!D31 -> 88062 | E8: =원자료!E31 -> 92290 | F8: =원자료!F31 -> 94812 | G8: =원자료!G31 -> 94735 | H8: =원자료!H31 -> 94314 | I8: =원자료!I31 -> 93938 | ... N8: =원자료!N31 -> 80896
A9: 대전 | B9: =원자료!B32 -> 50719 | C9: =원자료!C32 -> 52812 | D9: =원자료!D32 -> 54343 | E9: =원자료!E32 -> 55106 | F9: =원자료!F32 -> 55553 | G9: =원자료!G32 -> 55635 | H9: =원자료!H32 -> 54514 | I9: =원자료!I32 -> 53688 | ... N9: =원자료!N32 -> 39145
A10: 울산 | B10: =원자료!B33 -> 33091 | C10: =원자료!C33 -> 35621 | D10: =원자료!D33 -> 38210 | E10: =원자료!E33 -> 39629 | F10: =원자료!F33 -> 40754 | G10: =원자료!G33 -> 40899 | H10: =원자료!H33 -> 40257 | I10: =원자료!I33 -> 40305 | ... N10: =원자료!N33 -> 31746
A11: 세종 | B11: =원자료!B34 -> 0 | C11: =원자료!C34 -> 0 | D11: =원자료!D34 -> 5558 | E11: =원자료!E34 -> 6321 | F11: =원자료!F34 -> 8407 | G11: =원자료!G34 -> 10913 | H11: =원자료!H34 -> 12587 | I11: =원자료!I34 -> 14658 | ... N11: =원자료!N34 -> 18789
A12: 경기 | B12: =원자료!B35 -> 387247 | C12: =원자료!C35 -> 409956 | D12: =원자료!D35 -> 447370 | E12: =원자료!E35 -> 472497 | F12: =원자료!F35 -> 479093 | G12: =원자료!G35 -> 474619 | H12: =원자료!H35 -> 467469 | I12: =원자료!I35 -> 466020 | ... N12: =원자료!N35 -> 424321
A13: 강원 | B13: =원자료!B36 -> 51927 | C13: =원자료!C36 -> 53498 | D13: =원자료!D36 -> 56259 | E13: =원자료!E36 -> 56846 | F13: =원자료!F36 -> 56446 | G13: =원자료!G36 -> 55718 | H13: =원자료!H36 -> 54408 | I13: =원자료!I36 -> 53468 | ... N13: =원자료!N36 -> 45475
A14: 충북 | B14: =원자료!B37 -> 58275 | C14: =원자료!C37 -> 59175 | D14: =원자료!D37 -> 61590 | E14: =원자료!E37 -> 62739 | F14: =원자료!F37 -> 63214 | G14: =원자료!G37 -> 63601 | H14: =원자료!H37 -> 63108 | I14: =원자료!I37 -> 62582 | ... N14: =원자료!N37 -> 54338
A15: 충남 | B15: =원자료!B38 -> 71851 | C15: =원자료!C38 -> 78245 | D15: =원자료!D38 -> 81169 | E15: =원자료!E38 -> 88126 | F15: =원자료!F38 -> 87915 | G15: =원자료!G38 -> 87524 | H15: =원자료!H38 -> 87635 | I15: =원자료!I38 -> 87488 | ... N15: =원자료!N38 -> 72870
A16: 전북 | B16: =원자료!B39 -> 72750 | C16: =원자료!C39 -> 72700 | D16: =원자료!D39 -> 74226 | E16: =원자료!E39 -> 75181 | F16: =원자료!F39 -> 75275 | G16: =원자료!G39 -> 73738 | H16: =원자료!H39 -> 71946 | I16: =원자료!I39 -> 69650 | ... N16: =원자료!N39 -> 51748
... A19: 제주 | B19: =원자료!B42 -> 29210 | C19: =원자료!C42 -> 30540 | D19: =원자료!D42 -> 32326 | E19: =원자료!E42 -> 33185 | F19: =원자료!F42 -> 33009 | G19: =원자료!G42 -> 32830 | H19: =원자료!H42 -> 31176 | I19: =원자료!I42 -> 30531 | ... N19: =원자료!N42 -> 26568
A20: 전남광주(광주+전남) | B20: =원자료!B45 -> 126900 | C20: =원자료!C45 -> 127598 | D20: =원자료!D45 -> 130626 | E20: =원자료!E45 -> 132353 | F20: =원자료!F45 -> 133549 | G20: =원자료!G45 -> 134273 | H20: =원자료!H45 -> 133391 | I20: =원자료!I45 -> 133409 | ... N20: =원자료!N45 -> 102578
A21: 전국 합계(수식) | B21: =SUM(B5:B20) -> 1556808 | C21: =SUM(C5:C20) -> 1621948 | D21: =SUM(D5:D20) -> 1721917 | E21: =SUM(E5:E20) -> 1782459 | F21: =SUM(F5:F20) -> 1800659 | G21: =SUM(G5:G20) -> 1790821 | H21: =SUM(H5:H20) -> 1767224 | I21: =SUM(I5:I20) -> 1756603 | ... N21: =SUM(N5:N20) -> 1476686
A22: 전국(공표값) | B22: =원자료!B46 -> 1556808 | C22: =원자료!C46 -> 1621948 | D22: =원자료!D46 -> 1721917 | E22: =원자료!E46 -> 1782459 | F22: =원자료!F46 -> 1800659 | G22: =원자료!G46 -> 1790821 | H22: =원자료!H46 -> 1767224 | I22: =원자료!I46 -> 1756603 | ... N22: =원자료!N46 -> 1476686
A23: 검증(합계-공표값) | B23: =B21-B22 -> 0 | C23: =C21-C22 -> 0 | D23: =D21-D22 -> 0 | E23: =E21-E22 -> 0 | F23: =F21-F22 -> 0 | G23: =G21-G22 -> 0 | H23: =H21-H22 -> 0 | I23: =I21-I22 -> 0 | ... N23: =N21-N22 -> 0

Sheet 현원(명)
A1: 시도별 어린이집 현원 (단위: 명, 2010~2022)
A2: 현원 = 실제 어린이집에 다니는 아동 수의 합계.
A4: 시도 | B4: 2010 | C4: 2011 | D4: 2012 | E4: 2013 | F4: 2014 | G4: 2015 | H4: 2016 | I4: 2017 | J4: 2018 | K4: 2019 | L4: 2020 | M4: 2021 | N4: 2022
A5: 서울 | B5: =원자료!B51 -> 206581 | C5: =원자료!C51 -> 214863 | D5: =원자료!D51 -> 239335 | E5: =원자료!E51 -> 242648 | F5: =원자료!F51 -> 243432 | G5: =원자료!G51 -> 238103 | H5: =원자료!H51 -> 236550 | I5: =원자료!I51 -> 234867 | ... N5: =원자료!N51 -> 167427
A6: 부산 | B6: =원자료!B52 -> 65822 | C6: =원자료!C52 -> 68050 | D6: =원자료!D52 -> 73991 | E6: =원자료!E52 -> 74317 | F6: =원자료!F52 -> 75407 | G6: =원자료!G52 -> 74003 | H6: =원자료!H52 -> 75006 | I6: =원자료!I52 -> 74971 | ... N6: =원자료!N52 -> 55850
A7: 대구 | B7: =원자료!B53 -> 61765 | C7: =원자료!C53 -> 63118 | D7: =원자료!D53 -> 66795 | E7: =원자료!E53 -> 63505 | F7: =원자료!F53 -> 62824 | G7: =원자료!G53 -> 59449 | H7: =원자료!H53 -> 58706 | I7: =원자료!I53 -> 58591 | ... N7: =원자료!N53 -> 42487
A8: 인천 | B8: =원자료!B54 -> 65075 | C8: =원자료!C54 -> 71381 | D8: =원자료!D54 -> 79751 | E8: =원자료!E54 -> 81796 | F8: =원자료!F54 -> 83731 | G8: =원자료!G54 -> 81353 | H8: =원자료!H54 -> 81096 | I8: =원자료!I54 -> 80895 | ... N8: =원자료!N54 -> 62200
A9: 대전 | B9: =원자료!B55 -> 42105 | C9: =원자료!C55 -> 44573 | D9: =원자료!D55 -> 48432 | E9: =원자료!E55 -> 47163 | F9: =원자료!F55 -> 46859 | G9: =원자료!G55 -> 44691 | H9: =원자료!H55 -> 44482 | I9: =원자료!I55 -> 43761 | ... N9: =원자료!N55 -> 28144
A10: 울산 | B10: =원자료!B56 -> 27350 | C10: =원자료!C56 -> 29976 | D10: =원자료!D56 -> 33800 | E10: =원자료!E56 -> 34269 | F10: =원자료!F56 -> 35383 | G10: =원자료!G56 -> 34676 | H10: =원자료!H56 -> 34762 | I10: =원자료!I56 -> 34657 | ... N10: =원자료!N56 -> 24892
A11: 세종 | B11: =원자료!B57 -> 0 | C11: =원자료!C57 -> 0 | D11: =원자료!D57 -> 4547 | E11: =원자료!E57 -> 5158 | F11: =원자료!F57 -> 6405 | G11: =원자료!G57 -> 8723 | H11: =원자료!H57 -> 10846 | I11: =원자료!I57 -> 12580 | ... N11: =원자료!N57 -> 14927
A12: 경기 | B12: =원자료!B58 -> 320056 | C12: =원자료!C58 -> 344326 | D12: =원자료!D58 -> 392515 | E12: =원자료!E58 -> 397656 | F12: =원자료!F58 -> 402945 | G12: =원자료!G58 -> 389398 | H12: =원자료!H58 -> 390870 | I12: =원자료!I58 -> 394882 | ... N12: =원자료!N58 -> 331516
A13: 강원 | B13: =원자료!B59 -> 41292 | C13: =원자료!C59 -> 42996 | D13: =원자료!D59 -> 46007 | E13: =원자료!E59 -> 45113 | F13: =원자료!F59 -> 44280 | G13: =원자료!G59 -> 42238 | H13: =원자료!H59 -> 41743 | I13: =원자료!I59 -> 41020 | ... N13: =원자료!N59 -> 32680
A14: 충북 | B14: =원자료!B60 -> 45983 | C14: =원자료!C60 -> 48251 | D14: =원자료!D60 -> 51467 | E14: =원자료!E60 -> 51476 | F14: =원자료!F60 -> 51491 | G14: =원자료!G60 -> 49787 | H14: =원자료!H60 -> 50014 | I14: =원자료!I60 -> 49896 | ... N14: =원자료!N60 -> 38884
A15: 충남 | B15: =원자료!B61 -> 58305 | C15: =원자료!C61 -> 63236 | D15: =원자료!D61 -> 67626 | E15: =원자료!E61 -> 69395 | F15: =원자료!F61 -> 70015 | G15: =원자료!G61 -> 68750 | H15: =원자료!H61 -> 69364 | I15: =원자료!I61 -> 69787 | ... N15: =원자료!N61 -> 52196
A16: 전북 | B16: =원자료!B62 -> 56531 | C16: =원자료!C62 -> 57114 | D16: =원자료!D62 -> 60401 | E16: =원자료!E62 -> 59050 | F16: =원자료!F62 -> 58328 | G16: =원자료!G62 -> 55226 | H16: =원자료!H62 -> 53798 | I16: =원자료!I62 -> 52105 | ... N16: =원자료!N62 -> 34789
... A19: 제주 | B19: =원자료!B65 -> 24809 | C19: =원자료!C65 -> 25513 | D19: =원자료!D65 -> 26894 | E19: =원자료!E65 -> 27256 | F19: =원자료!F65 -> 27402 | G19: =원자료!G65 -> 27109 | H19: =원자료!H65 -> 27231 | I19: =원자료!I65 -> 27191 | ... N19: =원자료!N65 -> 20970
A20: 전남광주(광주+전남) | B20: =원자료!B68 -> 101782 | C20: =원자료!C68 -> 103971 | D20: =원자료!D68 -> 109859 | E20: =원자료!E68 -> 107608 | F20: =원자료!F68 -> 106777 | G20: =원자료!G68 -> 103176 | H20: =원자료!H68 -> 101915 | I20: =원자료!I68 -> 100422 | ... N20: =원자료!N68 -> 70659
A21: 전국 합계(수식) | B21: =SUM(B5:B20) -> 1279910 | C21: =SUM(C5:C20) -> 1348729 | D21: =SUM(D5:D20) -> 1487361 | E21: =SUM(E5:E20) -> 1486980 | F21: =SUM(F5:F20) -> 1496671 | G21: =SUM(G5:G20) -> 1452813 | H21: =SUM(H5:H20) -> 1451215 | I21: =SUM(I5:I20) -> 1450243 | ... N21: =SUM(N5:N20) -> 1095450
A22: 전국(공표값) | B22: =원자료!B69 -> 1279910 | C22: =원자료!C69 -> 1348729 | D22: =원자료!D69 -> 1487361 | E22: =원자료!E69 -> 1486980 | F22: =원자료!F69 -> 1496671 | G22: =원자료!G69 -> 1452813 | H22: =원자료!H69 -> 1451215 | I22: =원자료!I69 -> 1450243 | ... N22: =원자료!N69 -> 1095450
A23: 검증(합계-공표값) | B23: =B21-B22 -> 0 | C23: =C21-C22 -> 0 | D23: =D21-D22 -> 0 | E23: =E21-E22 -> 0 | F23: =F21-F22 -> 0 | G23: =G21-G22 -> 0 | H23: =H21-H22 -> 0 | I23: =I21-I22 -> 0 | ... N23: =N21-N22 -> 0

Sheet 충족률
A1: 정원 충족률 (현원 ÷ 정원)
A2: 정원 대비 실제 다니는 아동 비율. 낮을수록 빈자리가 많음. 세종 2010~2011은 해당 없음.
A4: 정원 충족률(%)
A5: 시도 | B5: 2010 | C5: 2011 | D5: 2012 | E5: 2013 | F5: 2014 | G5: 2015 | H5: 2016 | I5: 2017 | J5: 2018 | K5: 2019 | L5: 2020 | M5: 2021 | N5: 2022
A6: 서울 | B6: =IF(OR('정원(명)'!B5=0,'현원(명)'!B5=0),"",'현원(명)'!B5/'정원(명)'!B5) -> 0.87408765 | C6: =IF(OR('정원(명)'!C5=0,'현원(명)'!C5=0),"",'현원(명)'!C5/'정원(명)'!C5) -> 0.88261173 | D6: =IF(OR('정원(명)'!D5=0,'현원(명)'!D5=0),"",'현원(명)'!D5/'정원(명)'!D5) -> 0.91394585 | E6: =IF(OR('정원(명)'!E5=0,'현원(명)'!E5=0),"",'현원(명)'!E5/'정원(명)'!E5) -> 0.89717442 | F6: =IF(OR('정원(명)'!F5=0,'현원(명)'!F5=0),"",'현원(명)'!F5/'정원(명)'!F5) -> 0.8837162 | G6: =IF(OR('정원(명)'!G5=0,'현원(명)'!G5=0),"",'현원(명)'!G5/'정원(명)'!G5) -> 0.86857062 | H6: =IF(OR('정원(명)'!H5=0,'현원(명)'!H5=0),"",'현원(명)'!H5/'정원(명)'!H5) -> 0.87536219 | I6: =IF(OR('정원(명)'!I5=0,'현원(명)'!I5=0),"",'현원(명)'!I5/'정원(명)'!I5) -> 0.87604252 | ... N6: =IF(OR('정원(명)'!N5=0,'현원(명)'!N5=0),"",'현원(명)'!N5/'정원(명)'!N5) -> 0.74868532
A7: 부산 | B7: =IF(OR('정원(명)'!B6=0,'현원(명)'!B6=0),"",'현원(명)'!B6/'정원(명)'!B6) -> 0.827679 | C7: =IF(OR('정원(명)'!C6=0,'현원(명)'!C6=0),"",'현원(명)'!C6/'정원(명)'!C6) -> 0.84447092 | D7: =IF(OR('정원(명)'!D6=0,'현원(명)'!D6=0),"",'현원(명)'!D6/'정원(명)'!D6) -> 0.87188763 | E7: =IF(OR('정원(명)'!E6=0,'현원(명)'!E6=0),"",'현원(명)'!E6/'정원(명)'!E6) -> 0.85188794 | F7: =IF(OR('정원(명)'!F6=0,'현원(명)'!F6=0),"",'현원(명)'!F6/'정원(명)'!F6) -> 0.84652776 | G7: =IF(OR('정원(명)'!G6=0,'현원(명)'!G6=0),"",'현원(명)'!G6/'정원(명)'!G6) -> 0.82212767 | H7: =IF(OR('정원(명)'!H6=0,'현원(명)'!H6=0),"",'현원(명)'!H6/'정원(명)'!H6) -> 0.836579 | I7: =IF(OR('정원(명)'!I6=0,'현원(명)'!I6=0),"",'현원(명)'!I6/'정원(명)'!I6) -> 0.84199236 | ... N7: =IF(OR('정원(명)'!N6=0,'현원(명)'!N6=0),"",'현원(명)'!N6/'정원(명)'!N6) -> 0.73345941
A8: 대구 | B8: =IF(OR('정원(명)'!B7=0,'현원(명)'!B7=0),"",'현원(명)'!B7/'정원(명)'!B7) -> 0.80975667 | C8: =IF(OR('정원(명)'!C7=0,'현원(명)'!C7=0),"",'현원(명)'!C7/'정원(명)'!C7) -> 0.81740009 | D8: =IF(OR('정원(명)'!D7=0,'현원(명)'!D7=0),"",'현원(명)'!D7/'정원(명)'!D7) -> 0.83735536 | E8: =IF(OR('정원(명)'!E7=0,'현원(명)'!E7=0),"",'현원(명)'!E7/'정원(명)'!E7) -> 0.79742083 | F8: =IF(OR('정원(명)'!F7=0,'현원(명)'!F7=0),"",'현원(명)'!F7/'정원(명)'!F7) -> 0.79249186 | G8: =IF(OR('정원(명)'!G7=0,'현원(명)'!G7=0),"",'현원(명)'!G7/'정원(명)'!G7) -> 0.76661895 | H8: =IF(OR('정원(명)'!H7=0,'현원(명)'!H7=0),"",'현원(명)'!H7/'정원(명)'!H7) -> 0.78009435 | I8: =IF(OR('정원(명)'!I7=0,'현원(명)'!I7=0),"",'현원(명)'!I7/'정원(명)'!I7) -> 0.78439274 | ... N8: =IF(OR('정원(명)'!N7=0,'현원(명)'!N7=0),"",'현원(명)'!N7/'정원(명)'!N7) -> 0.71486018
A9: 인천 | B9: =IF(OR('정원(명)'!B8=0,'현원(명)'!B8=0),"",'현원(명)'!B8/'정원(명)'!B8) -> 0.86154396 | C9: =IF(OR('정원(명)'!C8=0,'현원(명)'!C8=0),"",'현원(명)'!C8/'정원(명)'!C8) -> 0.86790686 | D9: =IF(OR('정원(명)'!D8=0,'현원(명)'!D8=0),"",'현원(명)'!D8/'정원(명)'!D8) -> 0.90562331 | E9: =IF(OR('정원(명)'!E8=0,'현원(명)'!E8=0),"",'현원(명)'!E8/'정원(명)'!E8) -> 0.88629321 | F9: =IF(OR('정원(명)'!F8=0,'현원(명)'!F8=0),"",'현원(명)'!F8/'정원(명)'!F8) -> 0.88312661 | G9: =IF(OR('정원(명)'!G8=0,'현원(명)'!G8=0),"",'현원(명)'!G8/'정원(명)'!G8) -> 0.85874281 | H9: =IF(OR('정원(명)'!H8=0,'현원(명)'!H8=0),"",'현원(명)'!H8/'정원(명)'!H8) -> 0.85985114 | I9: =IF(OR('정원(명)'!I8=0,'현원(명)'!I8=0),"",'현원(명)'!I8/'정원(명)'!I8) -> 0.8611531 | ... N9: =IF(OR('정원(명)'!N8=0,'현원(명)'!N8=0),"",'현원(명)'!N8/'정원(명)'!N8) -> 0.76888845
A10: 대전 | B10: =IF(OR('정원(명)'!B9=0,'현원(명)'!B9=0),"",'현원(명)'!B9/'정원(명)'!B9) -> 0.83016227 | C10: =IF(OR('정원(명)'!C9=0,'현원(명)'!C9=0),"",'현원(명)'!C9/'정원(명)'!C9) -> 0.84399379 | D10: =IF(OR('정원(명)'!D9=0,'현원(명)'!D9=0),"",'현원(명)'!D9/'정원(명)'!D9) -> 0.89122794 | E10: =IF(OR('정원(명)'!E9=0,'현원(명)'!E9=0),"",'현원(명)'!E9/'정원(명)'!E9) -> 0.85585962 | F10: =IF(OR('정원(명)'!F9=0,'현원(명)'!F9=0),"",'현원(명)'!F9/'정원(명)'!F9) -> 0.8435008 | G10: =IF(OR('정원(명)'!G9=0,'현원(명)'!G9=0),"",'현원(명)'!G9/'정원(명)'!G9) -> 0.8032893 | H10: =IF(OR('정원(명)'!H9=0,'현원(명)'!H9=0),"",'현원(명)'!H9/'정원(명)'!H9) -> 0.81597388 | I10: =IF(OR('정원(명)'!I9=0,'현원(명)'!I9=0),"",'현원(명)'!I9/'정원(명)'!I9) -> 0.81509835 | ... N10: =IF(OR('정원(명)'!N9=0,'현원(명)'!N9=0),"",'현원(명)'!N9/'정원(명)'!N9) -> 0.71896794
A11: 울산 | B11: =IF(OR('정원(명)'!B10=0,'현원(명)'!B10=0),"",'현원(명)'!B10/'정원(명)'!B10) -> 0.82650872 | C11: =IF(OR('정원(명)'!C10=0,'현원(명)'!C10=0),"",'현원(명)'!C10/'정원(명)'!C10) -> 0.84152607 | D11: =IF(OR('정원(명)'!D10=0,'현원(명)'!D10=0),"",'현원(명)'!D10/'정원(명)'!D10) -> 0.88458519 | E11: =IF(OR('정원(명)'!E10=0,'현원(명)'!E10=0),"",'현원(명)'!E10/'정원(명)'!E10) -> 0.86474551 | F11: =IF(OR('정원(명)'!F10=0,'현원(명)'!F10=0),"",'현원(명)'!F10/'정원(명)'!F10) -> 0.86820926 | G11: =IF(OR('정원(명)'!G10=0,'현원(명)'!G10=0),"",'현원(명)'!G10/'정원(명)'!G10) -> 0.84784469 | H11: =IF(OR('정원(명)'!H10=0,'현원(명)'!H10=0),"",'현원(명)'!H10/'정원(명)'!H10) -> 0.863502 | I11: =IF(OR('정원(명)'!I10=0,'현원(명)'!I10=0),"",'현원(명)'!I10/'정원(명)'!I10) -> 0.8598685 | ... N11: =IF(OR('정원(명)'!N10=0,'현원(명)'!N10=0),"",'현원(명)'!N10/'정원(명)'!N10) -> 0.78409878
A12: 세종 | B12: =IF(OR('정원(명)'!B11=0,'현원(명)'!B11=0),"",'현원(명)'!B11/'정원(명)'!B11) | C12: =IF(OR('정원(명)'!C11=0,'현원(명)'!C11=0),"",'현원(명)'!C11/'정원(명)'!C11) | D12: =IF(OR('정원(명)'!D11=0,'현원(명)'!D11=0),"",'현원(명)'!D11/'정원(명)'!D11) -> 0.81810004 | E12: =IF(OR('정원(명)'!E11=0,'현원(명)'!E11=0),"",'현원(명)'!E11/'정원(명)'!E11) -> 0.81601012 | F12: =IF(OR('정원(명)'!F11=0,'현원(명)'!F11=0),"",'현원(명)'!F11/'정원(명)'!F11) -> 0.76186511 | G12: =IF(OR('정원(명)'!G11=0,'현원(명)'!G11=0),"",'현원(명)'!G11/'정원(명)'!G11) -> 0.79932191 | H12: =IF(OR('정원(명)'!H11=0,'현원(명)'!H11=0),"",'현원(명)'!H11/'정원(명)'!H11) -> 0.86168269 | I12: =IF(OR('정원(명)'!I11=0,'현원(명)'!I11=0),"",'현원(명)'!I11/'정원(명)'!I11) -> 0.85823441 | ... N12: =IF(OR('정원(명)'!N11=0,'현원(명)'!N11=0),"",'현원(명)'!N11/'정원(명)'!N11) -> 0.7944542
A13: 경기 | B13: =IF(OR('정원(명)'!B12=0,'현원(명)'!B12=0),"",'현원(명)'!B12/'정원(명)'!B12) -> 0.82649059 | C13: =IF(OR('정원(명)'!C12=0,'현원(명)'!C12=0),"",'현원(명)'!C12/'정원(명)'!C12) -> 0.83990965 | D13: =IF(OR('정원(명)'!D12=0,'현원(명)'!D12=0),"",'현원(명)'!D12/'정원(명)'!D12) -> 0.87738337 | E13: =IF(OR('정원(명)'!E12=0,'현원(명)'!E12=0),"",'현원(명)'!E12/'정원(명)'!E12) -> 0.84160534 | F13: =IF(OR('정원(명)'!F12=0,'현원(명)'!F12=0),"",'현원(명)'!F12/'정원(명)'!F12) -> 0.841058 | G13: =IF(OR('정원(명)'!G12=0,'현원(명)'!G12=0),"",'현원(명)'!G12/'정원(명)'!G12) -> 0.82044335 | H13: =IF(OR('정원(명)'!H12=0,'현원(명)'!H12=0),"",'현원(명)'!H12/'정원(명)'!H12) -> 0.83614101 | I13: =IF(OR('정원(명)'!I12=0,'현원(명)'!I12=0),"",'현원(명)'!I12/'정원(명)'!I12) -> 0.8473499 | ... N13: =IF(OR('정원(명)'!N12=0,'현원(명)'!N12=0),"",'현원(명)'!N12/'정원(명)'!N12) -> 0.78128587
A14: 강원 | B14: =IF(OR('정원(명)'!B13=0,'현원(명)'!B13=0),"",'현원(명)'!B13/'정원(명)'!B13) -> 0.79519325 | C14: =IF(OR('정원(명)'!C13=0,'현원(명)'!C13=0),"",'현원(명)'!C13/'정원(명)'!C13) -> 0.8036936 | D14: =IF(OR('정원(명)'!D13=0,'현원(명)'!D13=0),"",'현원(명)'!D13/'정원(명)'!D13) -> 0.81777138 | E14: =IF(OR('정원(명)'!E13=0,'현원(명)'!E13=0),"",'현원(명)'!E13/'정원(명)'!E13) -> 0.79360025 | F14: =IF(OR('정원(명)'!F13=0,'현원(명)'!F13=0),"",'현원(명)'!F13/'정원(명)'!F13) -> 0.78446657 | G14: =IF(OR('정원(명)'!G13=0,'현원(명)'!G13=0),"",'현원(명)'!G13/'정원(명)'!G13) -> 0.75806741 | H14: =IF(OR('정원(명)'!H13=0,'현원(명)'!H13=0),"",'현원(명)'!H13/'정원(명)'!H13) -> 0.76722173 | I14: =IF(OR('정원(명)'!I13=0,'현원(명)'!I13=0),"",'현원(명)'!I13/'정원(명)'!I13) -> 0.76718785 | ... N14: =IF(OR('정원(명)'!N13=0,'현원(명)'!N13=0),"",'현원(명)'!N13/'정원(명)'!N13) -> 0.71863661
A15: 충북 | B15: =IF(OR('정원(명)'!B14=0,'현원(명)'!B14=0),"",'현원(명)'!B14/'정원(명)'!B14) -> 0.78906907 | C15: =IF(OR('정원(명)'!C14=0,'현원(명)'!C14=0),"",'현원(명)'!C14/'정원(명)'!C14) -> 0.81539501 | D15: =IF(OR('정원(명)'!D14=0,'현원(명)'!D14=0),"",'현원(명)'!D14/'정원(명)'!D14) -> 0.8356389 | E15: =IF(OR('정원(명)'!E14=0,'현원(명)'!E14=0),"",'현원(명)'!E14/'정원(명)'!E14) -> 0.82047849 | F15: =IF(OR('정원(명)'!F14=0,'현원(명)'!F14=0),"",'현원(명)'!F14/'정원(명)'!F14) -> 0.81455057 | G15: =IF(OR('정원(명)'!G14=0,'현원(명)'!G14=0),"",'현원(명)'!G14/'정원(명)'!G14) -> 0.78280216 | H15: =IF(OR('정원(명)'!H14=0,'현원(명)'!H14=0),"",'현원(명)'!H14/'정원(명)'!H14) -> 0.79251442 | I15: =IF(OR('정원(명)'!I14=0,'현원(명)'!I14=0),"",'현원(명)'!I14/'정원(명)'!I14) -> 0.79728996 | ... N15: =IF(OR('정원(명)'!N14=0,'현원(명)'!N14=0),"",'현원(명)'!N14/'정원(명)'!N14) -> 0.71559498
A16: 충남 | B16: =IF(OR('정원(명)'!B15=0,'현원(명)'!B15=0),"",'현원(명)'!B15/'정원(명)'!B15) -> 0.81147096 | C16: =IF(OR('정원(명)'!C15=0,'현원(명)'!C15=0),"",'현원(명)'!C15/'정원(명)'!C15) -> 0.80817944 | D16: =IF(OR('정원(명)'!D15=0,'현원(명)'!D15=0),"",'현원(명)'!D15/'정원(명)'!D15) -> 0.83315059 | E16: =IF(OR('정원(명)'!E15=0,'현원(명)'!E15=0),"",'현원(명)'!E15/'정원(명)'!E15) -> 0.78745206 | F16: =IF(OR('정원(명)'!F15=0,'현원(명)'!F15=0),"",'현원(명)'!F15/'정원(명)'!F15) -> 0.79639424 | G16: =IF(OR('정원(명)'!G15=0,'현원(명)'!G15=0),"",'현원(명)'!G15/'정원(명)'!G15) -> 0.78549883 | H16: =IF(OR('정원(명)'!H15=0,'현원(명)'!H15=0),"",'현원(명)'!H15/'정원(명)'!H15) -> 0.79151024 | I16: =IF(OR('정원(명)'!I15=0,'현원(명)'!I15=0),"",'현원(명)'!I15/'정원(명)'!I15) -> 0.79767511 | ... N16: =IF(OR('정원(명)'!N15=0,'현원(명)'!N15=0),"",'현원(명)'!N15/'정원(명)'!N15) -> 0.71628928
A17: 전북 | B17: =IF(OR('정원(명)'!B16=0,'현원(명)'!B16=0),"",'현원(명)'!B16/'정원(명)'!B16) -> 0.77705842 | C17: =IF(OR('정원(명)'!C16=0,'현원(명)'!C16=0),"",'현원(명)'!C16/'정원(명)'!C16) -> 0.7856121 | D17: =IF(OR('정원(명)'!D16=0,'현원(명)'!D16=0),"",'현원(명)'!D16/'정원(명)'!D16) -> 0.81374451 | E17: =IF(OR('정원(명)'!E16=0,'현원(명)'!E16=0),"",'현원(명)'!E16/'정원(명)'!E16) -> 0.78543781 | F17: =IF(OR('정원(명)'!F16=0,'현원(명)'!F16=0),"",'현원(명)'!F16/'정원(명)'!F16) -> 0.77486549 | G17: =IF(OR('정원(명)'!G16=0,'현원(명)'!G16=0),"",'현원(명)'!G16/'정원(명)'!G16) -> 0.74894898 | H17: =IF(OR('정원(명)'!H16=0,'현원(명)'!H16=0),"",'현원(명)'!H16/'정원(명)'!H16) -> 0.74775526 | I17: =IF(OR('정원(명)'!I16=0,'현원(명)'!I16=0),"",'현원(명)'!I16/'정원(명)'!I16) -> 0.74809763 | ... N17: =IF(OR('정원(명)'!N16=0,'현원(명)'!N16=0),"",'현원(명)'!N16/'정원(명)'!N16) -> 0.67227719
... A22: 전국 | B22: =IF(OR('정원(명)'!B21=0,'현원(명)'!B21=0),"",'현원(명)'!B21/'정원(명)'!B21) -> 0.82213735 | C22: =IF(OR('정원(명)'!C21=0,'현원(명)'!C21=0),"",'현원(명)'!C21/'정원(명)'!C21) -> 0.83154885 | D22: =IF(OR('정원(명)'!D21=0,'현원(명)'!D21=0),"",'현원(명)'!D21/'정원(명)'!D21) -> 0.86378205 | E22: =IF(OR('정원(명)'!E21=0,'현원(명)'!E21=0),"",'현원(명)'!E21/'정원(명)'!E21) -> 0.83422957 | F22: =IF(OR('정원(명)'!F21=0,'현원(명)'!F21=0),"",'현원(명)'!F21/'정원(명)'!F21) -> 0.83117958 | G22: =IF(OR('정원(명)'!G21=0,'현원(명)'!G21=0),"",'현원(명)'!G21/'정원(명)'!G21) -> 0.81125528 | H22: =IF(OR('정원(명)'!H21=0,'현원(명)'!H21=0),"",'현원(명)'!H21/'정원(명)'!H21) -> 0.82118339 | I22: =IF(OR('정원(명)'!I21=0,'현원(명)'!I21=0),"",'현원(명)'!I21/'정원(명)'!I21) -> 0.8255952 | ... N22: =IF(OR('정원(명)'!N21=0,'현원(명)'!N21=0),"",'현원(명)'!N21/'정원(명)'!N21) -> 0.74183002

Sheet 어린이집당 평균
A1: 어린이집당 평균 정원·현원 (단위: 명/개소)
A2: 정원(또는 현원) ÷ 어린이집 수.
A4: 어린이집당 평균 정원(명)
A5: 시도 | B5: 2010 | C5: 2011 | D5: 2012 | E5: 2013 | F5: 2014 | G5: 2015 | H5: 2016 | I5: 2017 | J5: 2018 | K5: 2019 | L5: 2020 | M5: 2021 | N5: 2022
A6: 서울 | B6: =IF(OR(어린이집수!C5=0,'정원(명)'!B5=0),"",'정원(명)'!B5/어린이집수!C5) -> 40.262181 | C6: =IF(OR(어린이집수!D5=0,'정원(명)'!C5=0),"",'정원(명)'!C5/어린이집수!D5) -> 39.875512 | D6: =IF(OR(어린이집수!E5=0,'정원(명)'!D5=0),"",'정원(명)'!D5/어린이집수!E5) -> 40.053533 | E6: =IF(OR(어린이집수!F5=0,'정원(명)'!E5=0),"",'정원(명)'!E5/어린이집수!F5) -> 40.115396 | F6: =IF(OR(어린이집수!G5=0,'정원(명)'!F5=0),"",'정원(명)'!F5/어린이집수!G5) -> 40.587005 | G6: =IF(OR(어린이집수!H5=0,'정원(명)'!G5=0),"",'정원(명)'!G5/어린이집수!H5) -> 41.547742 | H6: =IF(OR(어린이집수!I5=0,'정원(명)'!H5=0),"",'정원(명)'!H5/어린이집수!I5) -> 42.435773 | I6: =IF(OR(어린이집수!J5=0,'정원(명)'!I5=0),"",'정원(명)'!I5/어린이집수!J5) -> 43.061356 | ... N6: =IF(OR(어린이집수!O5=0,'정원(명)'!N5=0),"",'정원(명)'!N5/어린이집수!O5) -> 47.459253
A7: 부산 | B7: =IF(OR(어린이집수!C6=0,'정원(명)'!B6=0),"",'정원(명)'!B6/어린이집수!C6) -> 47.084665 | C7: =IF(OR(어린이집수!D6=0,'정원(명)'!C6=0),"",'정원(명)'!C6/어린이집수!D6) -> 46.312069 | D7: =IF(OR(어린이집수!E6=0,'정원(명)'!D6=0),"",'정원(명)'!D6/어린이집수!E6) -> 46.373224 | E7: =IF(OR(어린이집수!F6=0,'정원(명)'!E6=0),"",'정원(명)'!E6/어린이집수!F6) -> 45.987348 | F7: =IF(OR(어린이집수!G6=0,'정원(명)'!F6=0),"",'정원(명)'!F6/어린이집수!G6) -> 45.517629 | G7: =IF(OR(어린이집수!H6=0,'정원(명)'!G6=0),"",'정원(명)'!G6/어린이집수!H6) -> 45.669203 | H7: =IF(OR(어린이집수!I6=0,'정원(명)'!H6=0),"",'정원(명)'!H6/어린이집수!I6) -> 46.287042 | I7: =IF(OR(어린이집수!J6=0,'정원(명)'!I6=0),"",'정원(명)'!I6/어린이집수!J6) -> 46.375 | ... N7: =IF(OR(어린이집수!O6=0,'정원(명)'!N6=0),"",'정원(명)'!N6/어린이집수!O6) -> 49.221719
A8: 대구 | B8: =IF(OR(어린이집수!C7=0,'정원(명)'!B7=0),"",'정원(명)'!B7/어린이집수!C7) -> 49.401554 | C8: =IF(OR(어린이집수!D7=0,'정원(명)'!C7=0),"",'정원(명)'!C7/어린이집수!D7) -> 49.467008 | D8: =IF(OR(어린이집수!E7=0,'정원(명)'!D7=0),"",'정원(명)'!D7/어린이집수!E7) -> 50.486709 | E8: =IF(OR(어린이집수!F7=0,'정원(명)'!E7=0),"",'정원(명)'!E7/어린이집수!F7) -> 50.086792 | F8: =IF(OR(어린이집수!G7=0,'정원(명)'!F7=0),"",'정원(명)'!F7/어린이집수!G7) -> 49.920655 | G8: =IF(OR(어린이집수!H7=0,'정원(명)'!G7=0),"",'정원(명)'!G7/어린이집수!H7) -> 50.387914 | H8: =IF(OR(어린이집수!I7=0,'정원(명)'!H7=0),"",'정원(명)'!H7/어린이집수!I7) -> 50.745111 | I8: =IF(OR(어린이집수!J7=0,'정원(명)'!I7=0),"",'정원(명)'!I7/어린이집수!J7) -> 51.021858 | ... N8: =IF(OR(어린이집수!O7=0,'정원(명)'!N7=0),"",'정원(명)'!N7/어린이집수!O7) -> 52.18086
A9: 인천 | B9: =IF(OR(어린이집수!C8=0,'정원(명)'!B8=0),"",'정원(명)'!B8/어린이집수!C8) -> 40.674744 | C9: =IF(OR(어린이집수!D8=0,'정원(명)'!C8=0),"",'정원(명)'!C8/어린이집수!D8) -> 41.163664 | D9: =IF(OR(어린이집수!E8=0,'정원(명)'!D8=0),"",'정원(명)'!D8/어린이집수!E8) -> 40.376891 | E9: =IF(OR(어린이집수!F8=0,'정원(명)'!E8=0),"",'정원(명)'!E8/어린이집수!F8) -> 40.782148 | F9: =IF(OR(어린이집수!G8=0,'정원(명)'!F8=0),"",'정원(명)'!F8/어린이집수!G8) -> 41.079723 | G9: =IF(OR(어린이집수!H8=0,'정원(명)'!G8=0),"",'정원(명)'!G8/어린이집수!H8) -> 41.586918 | H9: =IF(OR(어린이집수!I8=0,'정원(명)'!H8=0),"",'정원(명)'!H8/어린이집수!I8) -> 42.274316 | I9: =IF(OR(어린이집수!J8=0,'정원(명)'!I8=0),"",'정원(명)'!I8/어린이집수!J8) -> 42.972553 | ... N9: =IF(OR(어린이집수!O8=0,'정원(명)'!N8=0),"",'정원(명)'!N8/어린이집수!O8) -> 47.670006
A10: 대전 | B10: =IF(OR(어린이집수!C9=0,'정원(명)'!B9=0),"",'정원(명)'!B9/어린이집수!C9) -> 33.041694 | C10: =IF(OR(어린이집수!D9=0,'정원(명)'!C9=0),"",'정원(명)'!C9/어린이집수!D9) -> 33.028143 | D10: =IF(OR(어린이집수!E9=0,'정원(명)'!D9=0),"",'정원(명)'!D9/어린이집수!E9) -> 32.75648 | E10: =IF(OR(어린이집수!F9=0,'정원(명)'!E9=0),"",'정원(명)'!E9/어린이집수!F9) -> 32.80119 | F10: =IF(OR(어린이집수!G9=0,'정원(명)'!F9=0),"",'정원(명)'!F9/어린이집수!G9) -> 32.716726 | G10: =IF(OR(어린이집수!H9=0,'정원(명)'!G9=0),"",'정원(명)'!G9/어린이집수!H9) -> 33.334332 | H10: =IF(OR(어린이집수!I9=0,'정원(명)'!H9=0),"",'정원(명)'!H9/어린이집수!I9) -> 34.415404 | I10: =IF(OR(어린이집수!J9=0,'정원(명)'!I9=0),"",'정원(명)'!I9/어린이집수!J9) -> 35.67309 | ... N10: =IF(OR(어린이집수!O9=0,'정원(명)'!N9=0),"",'정원(명)'!N9/어린이집수!O9) -> 38.642646
A11: 울산 | B11: =IF(OR(어린이집수!C10=0,'정원(명)'!B10=0),"",'정원(명)'!B10/어린이집수!C10) -> 43.887268 | C11: =IF(OR(어린이집수!D10=0,'정원(명)'!C10=0),"",'정원(명)'!C10/어린이집수!D10) -> 43.546455 | D11: =IF(OR(어린이집수!E10=0,'정원(명)'!D10=0),"",'정원(명)'!D10/어린이집수!E10) -> 42.788354 | E11: =IF(OR(어린이집수!F10=0,'정원(명)'!E10=0),"",'정원(명)'!E10/어린이집수!F10) -> 42.474812 | F11: =IF(OR(어린이집수!G10=0,'정원(명)'!F10=0),"",'정원(명)'!F10/어린이집수!G10) -> 43.080338 | G11: =IF(OR(어린이집수!H10=0,'정원(명)'!G10=0),"",'정원(명)'!G10/어린이집수!H10) -> 43.789079 | H11: =IF(OR(어린이집수!I10=0,'정원(명)'!H10=0),"",'정원(명)'!H10/어린이집수!I10) -> 44.979888 | I11: =IF(OR(어린이집수!J10=0,'정원(명)'!I10=0),"",'정원(명)'!I10/어린이집수!J10) -> 45.749149 | ... N11: =IF(OR(어린이집수!O10=0,'정원(명)'!N10=0),"",'정원(명)'!N10/어린이집수!O10) -> 48.393293
A12: 세종 | B12: =IF(OR(어린이집수!C11=0,'정원(명)'!B11=0),"",'정원(명)'!B11/어린이집수!C11) | C12: =IF(OR(어린이집수!D11=0,'정원(명)'!C11=0),"",'정원(명)'!C11/어린이집수!D11) | D12: =IF(OR(어린이집수!E11=0,'정원(명)'!D11=0),"",'정원(명)'!D11/어린이집수!E11) -> 52.433962 | E12: =IF(OR(어린이집수!F11=0,'정원(명)'!E11=0),"",'정원(명)'!E11/어린이집수!F11) -> 53.567797 | F12: =IF(OR(어린이집수!G11=0,'정원(명)'!F11=0),"",'정원(명)'!F11/어린이집수!G11) -> 52.54375 | G12: =IF(OR(어린이집수!H11=0,'정원(명)'!G11=0),"",'정원(명)'!G11/어린이집수!H11) -> 50.523148 | H12: =IF(OR(어린이집수!I11=0,'정원(명)'!H11=0),"",'정원(명)'!H11/어린이집수!I11) -> 50.348 | I12: =IF(OR(어린이집수!J11=0,'정원(명)'!I11=0),"",'정원(명)'!I11/어린이집수!J11) -> 50.719723 | ... N12: =IF(OR(어린이집수!O11=0,'정원(명)'!N11=0),"",'정원(명)'!N11/어린이집수!O11) -> 57.458716
A13: 경기 | B13: =IF(OR(어린이집수!C12=0,'정원(명)'!B12=0),"",'정원(명)'!B12/어린이집수!C12) -> 34.351725 | C13: =IF(OR(어린이집수!D12=0,'정원(명)'!C12=0),"",'정원(명)'!C12/어린이집수!D12) -> 34.668584 | D13: =IF(OR(어린이집수!E12=0,'정원(명)'!D12=0),"",'정원(명)'!D12/어린이집수!E12) -> 34.763385 | E13: =IF(OR(어린이집수!F12=0,'정원(명)'!E12=0),"",'정원(명)'!E12/어린이집수!F12) -> 35.355956 | F13: =IF(OR(어린이집수!G12=0,'정원(명)'!F12=0),"",'정원(명)'!F12/어린이집수!G12) -> 36.133419 | G13: =IF(OR(어린이집수!H12=0,'정원(명)'!G12=0),"",'정원(명)'!G12/어린이집수!H12) -> 37.403972 | H13: =IF(OR(어린이집수!I12=0,'정원(명)'!H12=0),"",'정원(명)'!H12/어린이집수!I12) -> 38.57005 | I13: =IF(OR(어린이집수!J12=0,'정원(명)'!I12=0),"",'정원(명)'!I12/어린이집수!J12) -> 39.409725 | ... N13: =IF(OR(어린이집수!O12=0,'정원(명)'!N12=0),"",'정원(명)'!N12/어린이집수!O12) -> 44.958784
A14: 강원 | B14: =IF(OR(어린이집수!C13=0,'정원(명)'!B13=0),"",'정원(명)'!B13/어린이집수!C13) -> 47.858986 | C14: =IF(OR(어린이집수!D13=0,'정원(명)'!C13=0),"",'정원(명)'!C13/어린이집수!D13) -> 46.641674 | D14: =IF(OR(어린이집수!E13=0,'정원(명)'!D13=0),"",'정원(명)'!D13/어린이집수!E13) -> 45.224277 | E14: =IF(OR(어린이집수!F13=0,'정원(명)'!E13=0),"",'정원(명)'!E13/어린이집수!F13) -> 44.937549 | F14: =IF(OR(어린이집수!G13=0,'정원(명)'!F13=0),"",'정원(명)'!F13/어린이집수!G13) -> 44.90533 | G14: =IF(OR(어린이집수!H13=0,'정원(명)'!G13=0),"",'정원(명)'!G13/어린이집수!H13) -> 45.409943 | H14: =IF(OR(어린이집수!I13=0,'정원(명)'!H13=0),"",'정원(명)'!H13/어린이집수!I13) -> 46.108475 | I14: =IF(OR(어린이집수!J13=0,'정원(명)'!I13=0),"",'정원(명)'!I13/어린이집수!J13) -> 46.534378 | ... N14: =IF(OR(어린이집수!O13=0,'정원(명)'!N13=0),"",'정원(명)'!N13/어린이집수!O13) -> 50.193157
A15: 충북 | B15: =IF(OR(어린이집수!C14=0,'정원(명)'!B14=0),"",'정원(명)'!B14/어린이집수!C14) -> 52.405576 | C15: =IF(OR(어린이집수!D14=0,'정원(명)'!C14=0),"",'정원(명)'!C14/어린이집수!D14) -> 52.228597 | D15: =IF(OR(어린이집수!E14=0,'정원(명)'!D14=0),"",'정원(명)'!D14/어린이집수!E14) -> 52.239186 | E15: =IF(OR(어린이집수!F14=0,'정원(명)'!E14=0),"",'정원(명)'!E14/어린이집수!F14) -> 51.764851 | F15: =IF(OR(어린이집수!G14=0,'정원(명)'!F14=0),"",'정원(명)'!F14/어린이집수!G14) -> 51.435313 | G15: =IF(OR(어린이집수!H14=0,'정원(명)'!G14=0),"",'정원(명)'!G14/어린이집수!H14) -> 51.70813 | H15: =IF(OR(어린이집수!I14=0,'정원(명)'!H14=0),"",'정원(명)'!H14/어린이집수!I14) -> 52.241722 | I15: =IF(OR(어린이집수!J14=0,'정원(명)'!I14=0),"",'정원(명)'!I14/어린이집수!J14) -> 52.767285 | ... N15: =IF(OR(어린이집수!O14=0,'정원(명)'!N14=0),"",'정원(명)'!N14/어린이집수!O14) -> 55.903292
A16: 충남 | B16: =IF(OR(어린이집수!C15=0,'정원(명)'!B15=0),"",'정원(명)'!B15/어린이집수!C15) -> 42.59099 | C16: =IF(OR(어린이집수!D15=0,'정원(명)'!C15=0),"",'정원(명)'!C15/어린이집수!D15) -> 42.135164 | D16: =IF(OR(어린이집수!E15=0,'정원(명)'!D15=0),"",'정원(명)'!D15/어린이집수!E15) -> 40.767956 | E16: =IF(OR(어린이집수!F15=0,'정원(명)'!E15=0),"",'정원(명)'!E15/어린이집수!F15) -> 42.307249 | F16: =IF(OR(어린이집수!G15=0,'정원(명)'!F15=0),"",'정원(명)'!F15/어린이집수!G15) -> 42.822698 | G16: =IF(OR(어린이집수!H15=0,'정원(명)'!G15=0),"",'정원(명)'!G15/어린이집수!H15) -> 44.026157 | H16: =IF(OR(어린이집수!I15=0,'정원(명)'!H15=0),"",'정원(명)'!H15/어린이집수!I15) -> 44.39463 | I16: =IF(OR(어린이집수!J15=0,'정원(명)'!I15=0),"",'정원(명)'!I15/어린이집수!J15) -> 44.750895 | ... N16: =IF(OR(어린이집수!O15=0,'정원(명)'!N15=0),"",'정원(명)'!N15/어린이집수!O15) -> 48.067282
A17: 전북 | B17: =IF(OR(어린이집수!C16=0,'정원(명)'!B16=0),"",'정원(명)'!B16/어린이집수!C16) -> 47.517962 | C17: =IF(OR(어린이집수!D16=0,'정원(명)'!C16=0),"",'정원(명)'!C16/어린이집수!D16) -> 46.012658 | D17: =IF(OR(어린이집수!E16=0,'정원(명)'!D16=0),"",'정원(명)'!D16/어린이집수!E16) -> 45.818519 | E17: =IF(OR(어린이집수!F16=0,'정원(명)'!E16=0),"",'정원(명)'!E16/어린이집수!F16) -> 45.647237 | F17: =IF(OR(어린이집수!G16=0,'정원(명)'!F16=0),"",'정원(명)'!F16/어린이집수!G16) -> 45.510883 | G17: =IF(OR(어린이집수!H16=0,'정원(명)'!G16=0),"",'정원(명)'!G16/어린이집수!H16) -> 45.433148 | H17: =IF(OR(어린이집수!I16=0,'정원(명)'!H16=0),"",'정원(명)'!H16/어린이집수!I16) -> 46.060179 | I17: =IF(OR(어린이집수!J16=0,'정원(명)'!I16=0),"",'정원(명)'!I16/어린이집수!J16) -> 46.526386 | ... N17: =IF(OR(어린이집수!O16=0,'정원(명)'!N16=0),"",'정원(명)'!N16/어린이집수!O16) -> 50.535156
... A22: 전국 | B22: =IF(OR(어린이집수!C21=0,'정원(명)'!B21=0),"",'정원(명)'!B21/어린이집수!C21) -> 40.946004 | C22: =IF(OR(어린이집수!D21=0,'정원(명)'!C21=0),"",'정원(명)'!C21/어린이집수!D21) -> 40.709503 | D22: =IF(OR(어린이집수!E21=0,'정원(명)'!D21=0),"",'정원(명)'!D21/어린이집수!E21) -> 40.489971 | E22: =IF(OR(어린이집수!F21=0,'정원(명)'!E21=0),"",'정원(명)'!E21/어린이집수!F21) -> 40.723304 | F22: =IF(OR(어린이집수!G21=0,'정원(명)'!F21=0),"",'정원(명)'!F21/어린이집수!G21) -> 41.165447 | G22: =IF(OR(어린이집수!H21=0,'정원(명)'!G21=0),"",'정원(명)'!G21/어린이집수!H21) -> 42.120117 | H22: =IF(OR(어린이집수!I21=0,'정원(명)'!H21=0),"",'정원(명)'!H21/어린이집수!I21) -> 43.014896 | I22: =IF(OR(어린이집수!J21=0,'정원(명)'!I21=0),"",'정원(명)'!I21/어린이집수!J21) -> 43.655326 | ... N22: =IF(OR(어린이집수!O21=0,'정원(명)'!N21=0),"",'정원(명)'!N21/어린이집수!O21) -> 47.753646
A25: 어린이집당 평균 현원(명)
A26: 시도 | B26: 2010 | C26: 2011 | D26: 2012 | E26: 2013 | F26: 2014 | G26: 2015 | H26: 2016 | I26: 2017 | J26: 2018 | K26: 2019 | L26: 2020 | M26: 2021 | N26: 2022
A27: 서울 | B27: =IF(OR(어린이집수!C5=0,'현원(명)'!B5=0),"",'현원(명)'!B5/어린이집수!C5) -> 35.192675 | C27: =IF(OR(어린이집수!D5=0,'현원(명)'!C5=0),"",'현원(명)'!C5/어린이집수!D5) -> 35.194595 | D27: =IF(OR(어린이집수!E5=0,'현원(명)'!D5=0),"",'현원(명)'!D5/어린이집수!E5) -> 36.60676 | E27: =IF(OR(어린이집수!F5=0,'현원(명)'!E5=0),"",'현원(명)'!E5/어린이집수!F5) -> 35.990507 | F27: =IF(OR(어린이집수!G5=0,'현원(명)'!F5=0),"",'현원(명)'!F5/어린이집수!G5) -> 35.867394 | G27: =IF(OR(어린이집수!H5=0,'현원(명)'!G5=0),"",'현원(명)'!G5/어린이집수!H5) -> 36.087148 | H27: =IF(OR(어린이집수!I5=0,'현원(명)'!H5=0),"",'현원(명)'!H5/어린이집수!I5) -> 37.146671 | I27: =IF(OR(어린이집수!J5=0,'현원(명)'!I5=0),"",'현원(명)'!I5/어린이집수!J5) -> 37.723579 | ... N27: =IF(OR(어린이집수!O5=0,'현원(명)'!N5=0),"",'현원(명)'!N5/어린이집수!O5) -> 35.532046
A28: 부산 | B28: =IF(OR(어린이집수!C6=0,'현원(명)'!B6=0),"",'현원(명)'!B6/어린이집수!C6) -> 38.970989 | C28: =IF(OR(어린이집수!D6=0,'현원(명)'!C6=0),"",'현원(명)'!C6/어린이집수!D6) -> 39.109195 | D28: =IF(OR(어린이집수!E6=0,'현원(명)'!D6=0),"",'현원(명)'!D6/어린이집수!E6) -> 40.43224 | E28: =IF(OR(어린이집수!F6=0,'현원(명)'!E6=0),"",'현원(명)'!E6/어린이집수!F6) -> 39.176067 | F28: =IF(OR(어린이집수!G6=0,'현원(명)'!F6=0),"",'현원(명)'!F6/어린이집수!G6) -> 38.531937 | G28: =IF(OR(어린이집수!H6=0,'현원(명)'!G6=0),"",'현원(명)'!G6/어린이집수!H6) -> 37.545916 | H28: =IF(OR(어린이집수!I6=0,'현원(명)'!H6=0),"",'현원(명)'!H6/어린이집수!I6) -> 38.722767 | I28: =IF(OR(어린이집수!J6=0,'현원(명)'!I6=0),"",'현원(명)'!I6/어린이집수!J6) -> 39.047396 | ... N28: =IF(OR(어린이집수!O6=0,'현원(명)'!N6=0),"",'현원(명)'!N6/어린이집수!O6) -> 36.102133
A29: 대구 | B29: =IF(OR(어린이집수!C7=0,'현원(명)'!B7=0),"",'현원(명)'!B7/어린이집수!C7) -> 40.003238 | C29: =IF(OR(어린이집수!D7=0,'현원(명)'!C7=0),"",'현원(명)'!C7/어린이집수!D7) -> 40.434337 | D29: =IF(OR(어린이집수!E7=0,'현원(명)'!D7=0),"",'현원(명)'!D7/어린이집수!E7) -> 42.275316 | E29: =IF(OR(어린이집수!F7=0,'현원(명)'!E7=0),"",'현원(명)'!E7/어린이집수!F7) -> 39.940252 | F29: =IF(OR(어린이집수!G7=0,'현원(명)'!F7=0),"",'현원(명)'!F7/어린이집수!G7) -> 39.561713 | G29: =IF(OR(어린이집수!H7=0,'현원(명)'!G7=0),"",'현원(명)'!G7/어린이집수!H7) -> 38.62833 | H29: =IF(OR(어린이집수!I7=0,'현원(명)'!H7=0),"",'현원(명)'!H7/어린이집수!I7) -> 39.585974 | I29: =IF(OR(어린이집수!J7=0,'현원(명)'!I7=0),"",'현원(명)'!I7/어린이집수!J7) -> 40.021175 | ... N29: =IF(OR(어린이집수!O7=0,'현원(명)'!N7=0),"",'현원(명)'!N7/어린이집수!O7) -> 37.302019
A30: 인천 | B30: =IF(OR(어린이집수!C8=0,'현원(명)'!B8=0),"",'현원(명)'!B8/어린이집수!C8) -> 35.04308 | C30: =IF(OR(어린이집수!D8=0,'현원(명)'!C8=0),"",'현원(명)'!C8/어린이집수!D8) -> 35.726226 | D30: =IF(OR(어린이집수!E8=0,'현원(명)'!D8=0),"",'현원(명)'!D8/어린이집수!E8) -> 36.566254 | E30: =IF(OR(어린이집수!F8=0,'현원(명)'!E8=0),"",'현원(명)'!E8/어린이집수!F8) -> 36.14494 | F30: =IF(OR(어린이집수!G8=0,'현원(명)'!F8=0),"",'현원(명)'!F8/어린이집수!G8) -> 36.278596 | G30: =IF(OR(어린이집수!H8=0,'현원(명)'!G8=0),"",'현원(명)'!G8/어린이집수!H8) -> 35.712467 | H30: =IF(OR(어린이집수!I8=0,'현원(명)'!H8=0),"",'현원(명)'!H8/어린이집수!I8) -> 36.349619 | I30: =IF(OR(어린이집수!J8=0,'현원(명)'!I8=0),"",'현원(명)'!I8/어린이집수!J8) -> 37.005947 | ... N30: =IF(OR(어린이집수!O8=0,'현원(명)'!N8=0),"",'현원(명)'!N8/어린이집수!O8) -> 36.652917
A31: 대전 | B31: =IF(OR(어린이집수!C9=0,'현원(명)'!B9=0),"",'현원(명)'!B9/어린이집수!C9) -> 27.429967 | C31: =IF(OR(어린이집수!D9=0,'현원(명)'!C9=0),"",'현원(명)'!C9/어린이집수!D9) -> 27.875547 | D31: =IF(OR(어린이집수!E9=0,'현원(명)'!D9=0),"",'현원(명)'!D9/어린이집수!E9) -> 29.19349 | E31: =IF(OR(어린이집수!F9=0,'현원(명)'!E9=0),"",'현원(명)'!E9/어린이집수!F9) -> 28.073214 | F31: =IF(OR(어린이집수!G9=0,'현원(명)'!F9=0),"",'현원(명)'!F9/어린이집수!G9) -> 27.596584 | G31: =IF(OR(어린이집수!H9=0,'현원(명)'!G9=0),"",'현원(명)'!G9/어린이집수!H9) -> 26.777112 | H31: =IF(OR(어린이집수!I9=0,'현원(명)'!H9=0),"",'현원(명)'!H9/어린이집수!I9) -> 28.082071 | I31: =IF(OR(어린이집수!J9=0,'현원(명)'!I9=0),"",'현원(명)'!I9/어린이집수!J9) -> 29.077076 | ... N31: =IF(OR(어린이집수!O9=0,'현원(명)'!N9=0),"",'현원(명)'!N9/어린이집수!O9) -> 27.782823
A32: 울산 | B32: =IF(OR(어린이집수!C10=0,'현원(명)'!B10=0),"",'현원(명)'!B10/어린이집수!C10) -> 36.27321 | C32: =IF(OR(어린이집수!D10=0,'현원(명)'!C10=0),"",'현원(명)'!C10/어린이집수!D10) -> 36.645477 | D32: =IF(OR(어린이집수!E10=0,'현원(명)'!D10=0),"",'현원(명)'!D10/어린이집수!E10) -> 37.849944 | E32: =IF(OR(어린이집수!F10=0,'현원(명)'!E10=0),"",'현원(명)'!E10/어린이집수!F10) -> 36.729904 | F32: =IF(OR(어린이집수!G10=0,'현원(명)'!F10=0),"",'현원(명)'!F10/어린이집수!G10) -> 37.402748 | G32: =IF(OR(어린이집수!H10=0,'현원(명)'!G10=0),"",'현원(명)'!G10/어린이집수!H10) -> 37.126338 | H32: =IF(OR(어린이집수!I10=0,'현원(명)'!H10=0),"",'현원(명)'!H10/어린이집수!I10) -> 38.840223 | I32: =IF(OR(어린이집수!J10=0,'현원(명)'!I10=0),"",'현원(명)'!I10/어린이집수!J10) -> 39.338252 | ... N32: =IF(OR(어린이집수!O10=0,'현원(명)'!N10=0),"",'현원(명)'!N10/어린이집수!O10) -> 37.945122
A33: 세종 | B33: =IF(OR(어린이집수!C11=0,'현원(명)'!B11=0),"",'현원(명)'!B11/어린이집수!C11) | C33: =IF(OR(어린이집수!D11=0,'현원(명)'!C11=0),"",'현원(명)'!C11/어린이집수!D11) | D33: =IF(OR(어린이집수!E11=0,'현원(명)'!D11=0),"",'현원(명)'!D11/어린이집수!E11) -> 42.896226 | E33: =IF(OR(어린이집수!F11=0,'현원(명)'!E11=0),"",'현원(명)'!E11/어린이집수!F11) -> 43.711864 | F33: =IF(OR(어린이집수!G11=0,'현원(명)'!F11=0),"",'현원(명)'!F11/어린이집수!G11) -> 40.03125 | G33: =IF(OR(어린이집수!H11=0,'현원(명)'!G11=0),"",'현원(명)'!G11/어린이집수!H11) -> 40.384259 | H33: =IF(OR(어린이집수!I11=0,'현원(명)'!H11=0),"",'현원(명)'!H11/어린이집수!I11) -> 43.384 | I33: =IF(OR(어린이집수!J11=0,'현원(명)'!I11=0),"",'현원(명)'!I11/어린이집수!J11) -> 43.529412 | ... N33: =IF(OR(어린이집수!O11=0,'현원(명)'!N11=0),"",'현원(명)'!N11/어린이집수!O11) -> 45.648318
A34: 경기 | B34: =IF(OR(어린이집수!C12=0,'현원(명)'!B12=0),"",'현원(명)'!B12/어린이집수!C12) -> 28.391378 | C34: =IF(OR(어린이집수!D12=0,'현원(명)'!C12=0),"",'현원(명)'!C12/어린이집수!D12) -> 29.118478 | D34: =IF(OR(어린이집수!E12=0,'현원(명)'!D12=0),"",'현원(명)'!D12/어린이집수!E12) -> 30.500816 | E34: =IF(OR(어린이집수!F12=0,'현원(명)'!E12=0),"",'현원(명)'!E12/어린이집수!F12) -> 29.755762 | F34: =IF(OR(어린이집수!G12=0,'현원(명)'!F12=0),"",'현원(명)'!F12/어린이집수!G12) -> 30.390301 | G34: =IF(OR(어린이집수!H12=0,'현원(명)'!G12=0),"",'현원(명)'!G12/어린이집수!H12) -> 30.68784 | H34: =IF(OR(어린이집수!I12=0,'현원(명)'!H12=0),"",'현원(명)'!H12/어린이집수!I12) -> 32.25 | I34: =IF(OR(어린이집수!J12=0,'현원(명)'!I12=0),"",'현원(명)'!I12/어린이집수!J12) -> 33.393827 | ... N34: =IF(OR(어린이집수!O12=0,'현원(명)'!N12=0),"",'현원(명)'!N12/어린이집수!O12) -> 35.125662
A35: 강원 | B35: =IF(OR(어린이집수!C13=0,'현원(명)'!B13=0),"",'현원(명)'!B13/어린이집수!C13) -> 38.057143 | C35: =IF(OR(어린이집수!D13=0,'현원(명)'!C13=0),"",'현원(명)'!C13/어린이집수!D13) -> 37.485615 | D35: =IF(OR(어린이집수!E13=0,'현원(명)'!D13=0),"",'현원(명)'!D13/어린이집수!E13) -> 36.983119 | E35: =IF(OR(어린이집수!F13=0,'현원(명)'!E13=0),"",'현원(명)'!E13/어린이집수!F13) -> 35.662451 | F35: =IF(OR(어린이집수!G13=0,'현원(명)'!F13=0),"",'현원(명)'!F13/어린이집수!G13) -> 35.22673 | G35: =IF(OR(어린이집수!H13=0,'현원(명)'!G13=0),"",'현원(명)'!G13/어린이집수!H13) -> 34.423798 | H35: =IF(OR(어린이집수!I13=0,'현원(명)'!H13=0),"",'현원(명)'!H13/어린이집수!I13) -> 35.375424 | I35: =IF(OR(어린이집수!J13=0,'현원(명)'!I13=0),"",'현원(명)'!I13/어린이집수!J13) -> 35.700609 | ... N35: =IF(OR(어린이집수!O13=0,'현원(명)'!N13=0),"",'현원(명)'!N13/어린이집수!O13) -> 36.07064
A36: 충북 | B36: =IF(OR(어린이집수!C14=0,'현원(명)'!B14=0),"",'현원(명)'!B14/어린이집수!C14) -> 41.351619 | C36: =IF(OR(어린이집수!D14=0,'현원(명)'!C14=0),"",'현원(명)'!C14/어린이집수!D14) -> 42.586937 | D36: =IF(OR(어린이집수!E14=0,'현원(명)'!D14=0),"",'현원(명)'!D14/어린이집수!E14) -> 43.653096 | E36: =IF(OR(어린이집수!F14=0,'현원(명)'!E14=0),"",'현원(명)'!E14/어린이집수!F14) -> 42.471947 | F36: =IF(OR(어린이집수!G14=0,'현원(명)'!F14=0),"",'현원(명)'!F14/어린이집수!G14) -> 41.896664 | G36: =IF(OR(어린이집수!H14=0,'현원(명)'!G14=0),"",'현원(명)'!G14/어린이집수!H14) -> 40.477236 | H36: =IF(OR(어린이집수!I14=0,'현원(명)'!H14=0),"",'현원(명)'!H14/어린이집수!I14) -> 41.402318 | I36: =IF(OR(어린이집수!J14=0,'현원(명)'!I14=0),"",'현원(명)'!I14/어린이집수!J14) -> 42.070826 | ... N36: =IF(OR(어린이집수!O14=0,'현원(명)'!N14=0),"",'현원(명)'!N14/어린이집수!O14) -> 40.004115
A37: 충남 | B37: =IF(OR(어린이집수!C15=0,'현원(명)'!B15=0),"",'현원(명)'!B15/어린이집수!C15) -> 34.561352 | C37: =IF(OR(어린이집수!D15=0,'현원(명)'!C15=0),"",'현원(명)'!C15/어린이집수!D15) -> 34.052773 | D37: =IF(OR(어린이집수!E15=0,'현원(명)'!D15=0),"",'현원(명)'!D15/어린이집수!E15) -> 33.965846 | E37: =IF(OR(어린이집수!F15=0,'현원(명)'!E15=0),"",'현원(명)'!E15/어린이집수!F15) -> 33.31493 | F37: =IF(OR(어린이집수!G15=0,'현원(명)'!F15=0),"",'현원(명)'!F15/어린이집수!G15) -> 34.103751 | G37: =IF(OR(어린이집수!H15=0,'현원(명)'!G15=0),"",'현원(명)'!G15/어린이집수!H15) -> 34.582495 | H37: =IF(OR(어린이집수!I15=0,'현원(명)'!H15=0),"",'현원(명)'!H15/어린이집수!I15) -> 35.138804 | I37: =IF(OR(어린이집수!J15=0,'현원(명)'!I15=0),"",'현원(명)'!I15/어린이집수!J15) -> 35.696675 | ... N37: =IF(OR(어린이집수!O15=0,'현원(명)'!N15=0),"",'현원(명)'!N15/어린이집수!O15) -> 34.430079
A38: 전북 | B38: =IF(OR(어린이집수!C16=0,'현원(명)'!B16=0),"",'현원(명)'!B16/어린이집수!C16) -> 36.924233 | C38: =IF(OR(어린이집수!D16=0,'현원(명)'!C16=0),"",'현원(명)'!C16/어린이집수!D16) -> 36.148101 | D38: =IF(OR(어린이집수!E16=0,'현원(명)'!D16=0),"",'현원(명)'!D16/어린이집수!E16) -> 37.284568 | E38: =IF(OR(어린이집수!F16=0,'현원(명)'!E16=0),"",'현원(명)'!E16/어린이집수!F16) -> 35.853066 | F38: =IF(OR(어린이집수!G16=0,'현원(명)'!F16=0),"",'현원(명)'!F16/어린이집수!G16) -> 35.264813 | G38: =IF(OR(어린이집수!H16=0,'현원(명)'!G16=0),"",'현원(명)'!G16/어린이집수!H16) -> 34.02711 | H38: =IF(OR(어린이집수!I16=0,'현원(명)'!H16=0),"",'현원(명)'!H16/어린이집수!I16) -> 34.441741 | I38: =IF(OR(어린이집수!J16=0,'현원(명)'!I16=0),"",'현원(명)'!I16/어린이집수!J16) -> 34.806279 | ... N38: =IF(OR(어린이집수!O16=0,'현원(명)'!N16=0),"",'현원(명)'!N16/어린이집수!O16) -> 33.973633
... A43: 전국 | B43: =IF(OR(어린이집수!C21=0,'현원(명)'!B21=0),"",'현원(명)'!B21/어린이집수!C21) -> 33.663239 | C43: =IF(OR(어린이집수!D21=0,'현원(명)'!C21=0),"",'현원(명)'!C21/어린이집수!D21) -> 33.85194 | D43: =IF(OR(어린이집수!E21=0,'현원(명)'!D21=0),"",'현원(명)'!D21/어린이집수!E21) -> 34.97451 | E43: =IF(OR(어린이집수!F21=0,'현원(명)'!E21=0),"",'현원(명)'!E21/어린이집수!F21) -> 33.972584 | F43: =IF(OR(어린이집수!G21=0,'현원(명)'!F21=0),"",'현원(명)'!F21/어린이집수!G21) -> 34.215879 | G43: =IF(OR(어린이집수!H21=0,'현원(명)'!G21=0),"",'현원(명)'!G21/어린이집수!H21) -> 34.170167 | H43: =IF(OR(어린이집수!I21=0,'현원(명)'!H21=0),"",'현원(명)'!H21/어린이집수!I21) -> 35.323118 | I43: =IF(OR(어린이집수!J21=0,'현원(명)'!I21=0),"",'현원(명)'!I21/어린이집수!J21) -> 36.041627 | ... N43: =IF(OR(어린이집수!O21=0,'현원(명)'!N21=0),"",'현원(명)'!N21/어린이집수!O21) -> 35.425088

Sheet 원자료
A1: 원자료 (파란 글씨 = 입력값, 검정 = 수식)
A3: 어린이집 수(개소)
A4: 시도 | B4: 2009 | C4: 2010 | D4: 2011 | E4: 2012 | F4: 2013 | G4: 2014 | H4: 2015 | I4: 2016 | J4: 2017 | K4: 2018 | L4: 2019 | M4: 2020 | N4: 2021 | O4: 2022 | P4: 2023 | Q4: 2024 | R4: 2025 | S4: 2026
A5: 서울 | B5: 5684 | C5: 5870 | D5: 6105 | E5: 6538 | F5: 6742 | G5: 6787 | H5: 6598 | I5: 6368 | J5: 6226 | K5: 6008 | L5: 5698 | M5: 5370 | N5: 5049 | O5: 4712 | P5: 4431 | Q5: 4212 | R5: 4010 | S5: 3875
A6: 부산 | B6: 1655 | C6: 1689 | D6: 1740 | E6: 1830 | F6: 1897 | G6: 1957 | H6: 1971 | I6: 1937 | J6: 1920 | K6: 1891 | L6: 1848 | M6: 1778 | N6: 1668 | O6: 1547 | P6: 1447 | Q6: 1354 | R6: 1278 | S6: 1216
A7: 대구 | B7: 1500 | C7: 1544 | D7: 1561 | E7: 1580 | F7: 1590 | G7: 1588 | H7: 1539 | I7: 1483 | J7: 1464 | K7: 1405 | L7: 1322 | M7: 1268 | N7: 1187 | O7: 1139 | P7: 1079 | Q7: 1035 | R7: 992 | S7: 964
A8: 인천 | B8: 1773 | C8: 1857 | D8: 1998 | E8: 2181 | F8: 2263 | G8: 2308 | H8: 2278 | I8: 2231 | J8: 2186 | K8: 2141 | L8: 2049 | M8: 1943 | N8: 1803 | O8: 1697 | P8: 1652 | Q8: 1613 | R8: 1556 | S8: 1529
A9: 대전 | B9: 1417 | C9: 1535 | D9: 1599 | E9: 1659 | F9: 1680 | G9: 1698 | H9: 1669 | I9: 1584 | J9: 1505 | K9: 1406 | L9: 1288 | M9: 1185 | N9: 1101 | O9: 1013 | P9: 916 | Q9: 864 | R9: 826 | S9: 791
A10: 울산 | B10: 660 | C10: 754 | D10: 818 | E10: 893 | F10: 933 | G10: 946 | H10: 934 | I10: 895 | J10: 881 | K10: 868 | L10: 842 | M10: 790 | N10: 720 | O10: 656 | P10: 612 | Q10: 569 | R10: 535 | S10: 512
A11: 세종 | B11: 0 | C11: 0 | D11: 0 | E11: 106 | F11: 118 | G11: 160 | H11: 216 | I11: 250 | J11: 289 | K11: 343 | L11: 359 | M11: 350 | N11: 343 | O11: 327 | P11: 314 | Q11: 305 | R11: 286 | S11: 269
A12: 경기 | B12: 10465 | C12: 11273 | D12: 11825 | E12: 12869 | F12: 13364 | G12: 13259 | H12: 12689 | I12: 12120 | J12: 11825 | K12: 11682 | L12: 11305 | M12: 10761 | N12: 10136 | O12: 9438 | P12: 8903 | Q12: 8407 | R12: 8030 | S12: 7774
A13: 강원 | B13: 926 | C13: 1085 | D13: 1147 | E13: 1244 | F13: 1265 | G13: 1257 | H13: 1227 | I13: 1180 | J13: 1149 | K13: 1086 | L13: 1036 | M13: 999 | N13: 954 | O13: 906 | P13: 847 | Q13: 816 | R13: 779 | S13: 748
A14: 충북 | B14: 1037 | C14: 1112 | D14: 1133 | E14: 1179 | F14: 1212 | G14: 1229 | H14: 1230 | I14: 1208 | J14: 1186 | K14: 1157 | L14: 1130 | M14: 1082 | N14: 1042 | O14: 972 | P14: 921 | Q14: 877 | R14: 837 | S14: 800
A15: 충남 | B15: 1470 | C15: 1687 | D15: 1857 | E15: 1991 | F15: 2083 | G15: 2053 | H15: 1988 | I15: 1974 | J15: 1955 | K15: 1916 | L15: 1812 | M15: 1717 | N15: 1625 | O15: 1516 | P15: 1421 | Q15: 1338 | R15: 1272 | S15: 1206
... A19: 제주 | B19: 502 | C19: 525 | D19: 552 | E19: 584 | F19: 604 | G19: 599 | H19: 574 | I19: 543 | J19: 527 | K19: 513 | L19: 504 | M19: 489 | N19: 476 | O19: 451 | P19: 423 | Q19: 399 | R19: 378 | S19: 365
A20: 광주 | B20: 1153 | C20: 1192 | D20: 1205 | E20: 1239 | F20: 1251 | G20: 1260 | H20: 1264 | I20: 1238 | J20: 1240 | K20: 1195 | L20: 1122 | M20: 1072 | N20: 1002 | O20: 940
A21: 전남 | B21: 1114 | C21: 1135 | D21: 1161 | E21: 1188 | F21: 1222 | G21: 1242 | H21: 1238 | I21: 1251 | J21: 1241 | K21: 1205 | L21: 1147 | M21: 1084 | N21: 1051 | O21: 999
A22: 전남광주(합계) | B22: =B20+B21 -> 2267 | C22: =C20+C21 -> 2327 | D22: =D20+D21 -> 2366 | E22: =E20+E21 -> 2427 | F22: =F20+F21 -> 2473 | G22: =G20+G21 -> 2502 | H22: =H20+H21 -> 2502 | I22: =I20+I21 -> 2489 | ... O22: =O20+O21 -> 1939 | P22: 1830 | Q22: 1739 | R22: 1654 | S22: 1568
A23: 전국(공표값) | B23: 35550 | C23: 38021 | D23: 39842 | E23: 42527 | F23: 43770 | G23: 43742 | H23: 42517 | I23: 41084 | J23: 40238 | K23: 39171 | L23: 37371 | M23: 35352 | N23: 33246 | O23: 30923 | P23: 28954 | Q23: 27387 | R23: 26064 | S23: 25042
A26: 정원(명)
A27: 시도 | B27: 2010 | C27: 2011 | D27: 2012 | E27: 2013 | F27: 2014 | G27: 2015 | H27: 2016 | I27: 2017 | J27: 2018 | K27: 2019 | L27: 2020 | M27: 2021 | N27: 2022
A28: 서울 | B28: 236339 | C28: 243440 | D28: 261870 | E28: 270458 | F28: 275464 | G28: 274132 | H28: 270231 | I28: 268100 | J28: 263157 | K28: 254538 | L28: 245863 | M28: 235682 | N28: 223628
A29: 부산 | B29: 79526 | C29: 80583 | D29: 84863 | E29: 87238 | F29: 89078 | G29: 90014 | H29: 89658 | I29: 89040 | J29: 88222 | K29: 86553 | L29: 84008 | M29: 80248 | N29: 76146
A30: 대구 | B30: 76276 | C30: 77218 | D30: 79769 | E30: 79638 | F30: 79274 | G30: 77547 | H30: 75255 | I30: 74696 | J30: 72500 | K30: 69390 | L30: 66727 | M30: 62125 | N30: 59434
A31: 인천 | B31: 75533 | C31: 82245 | D31: 88062 | E31: 92290 | F31: 94812 | G31: 94735 | H31: 94314 | I31: 93938 | J31: 93888 | K31: 91615 | L31: 88002 | M31: 84877 | N31: 80896
A32: 대전 | B32: 50719 | C32: 52812 | D32: 54343 | E32: 55106 | F32: 55553 | G32: 55635 | H32: 54514 | I32: 53688 | J32: 51025 | K32: 47923 | L32: 45160 | M32: 42171 | N32: 39145
A33: 울산 | B33: 33091 | C33: 35621 | D33: 38210 | E33: 39629 | F33: 40754 | G33: 40899 | H33: 40257 | I33: 40305 | J33: 39894 | K33: 39650 | L33: 37491 | M33: 34583 | N33: 31746
A34: 세종 | B34: 0 | C34: 0 | D34: 5558 | E34: 6321 | F34: 8407 | G34: 10913 | H34: 12587 | I34: 14658 | J34: 17687 | K34: 19300 | L34: 19532 | M34: 19497 | N34: 18789
A35: 경기 | B35: 387247 | C35: 409956 | D35: 447370 | E35: 472497 | F35: 479093 | G35: 474619 | H35: 467469 | I35: 466020 | J35: 467296 | K35: 464409 | L35: 455556 | M35: 441927 | N35: 424321
A36: 강원 | B36: 51927 | C36: 53498 | D36: 56259 | E36: 56846 | F36: 56446 | G36: 55718 | H36: 54408 | I36: 53468 | J36: 51285 | K36: 49912 | L36: 48591 | M36: 47021 | N36: 45475
A37: 충북 | B37: 58275 | C37: 59175 | D37: 61590 | E37: 62739 | F37: 63214 | G37: 63601 | H37: 63108 | I37: 62582 | J37: 61211 | K37: 60113 | L37: 58541 | M37: 57092 | N37: 54338
A38: 충남 | B38: 71851 | C38: 78245 | D38: 81169 | E38: 88126 | F38: 87915 | G38: 87524 | H38: 87635 | I38: 87488 | J38: 86149 | K38: 82697 | L38: 79979 | M38: 76555 | N38: 72870
... A44: 전남 | B44: 66067 | C44: 66655 | D44: 68651 | E44: 69771 | F44: 70873 | G44: 70802 | H44: 70863 | I44: 70248 | J44: 68425 | K44: 66001 | L44: 61869 | M44: 59669 | N44: 56047
A45: 전남광주(합계) | B45: =B43+B44 -> 126900 | C45: =C43+C44 -> 127598 | D45: =D43+D44 -> 130626 | E45: =E43+E44 -> 132353 | F45: =F43+F44 -> 133549 | G45: =G43+G44 -> 134273 | H45: =H43+H44 -> 133391 | I45: =I43+I44 -> 133409 | ... N45: =N43+N44 -> 102578
A46: 전국(공표값) | B46: 1556808 | C46: 1621948 | D46: 1721917 | E46: 1782459 | F46: 1800659 | G46: 1790821 | H46: 1767224 | I46: 1756603 | J46: 1732324 | K46: 1686873 | L46: 1628260 | M46: 1557496 | N46: 1476686
A49: 현원(명)
A50: 시도 | B50: 2010 | C50: 2011 | D50: 2012 | E50: 2013 | F50: 2014 | G50: 2015 | H50: 2016 | I50: 2017 | J50: 2018 | K50: 2019 | L50: 2020 | M50: 2021 | N50: 2022
A51: 서울 | B51: 206581 | C51: 214863 | D51: 239335 | E51: 242648 | F51: 243432 | G51: 238103 | H51: 236550 | I51: 234867 | J51: 226959 | K51: 217444 | L51: 196260 | M51: 182922 | N51: 167427
A52: 부산 | B52: 65822 | C52: 68050 | D52: 73991 | E52: 74317 | F52: 75407 | G52: 74003 | H52: 75006 | I52: 74971 | J52: 73586 | K52: 70977 | L52: 65290 | M52: 61611 | N52: 55850
A53: 대구 | B53: 61765 | C53: 63118 | D53: 66795 | E53: 63505 | F53: 62824 | G53: 59449 | H53: 58706 | I53: 58591 | J53: 56943 | K53: 54641 | L53: 49029 | M53: 46211 | N53: 42487
...

Sheet 출처·메모
A1: 출처 및 주의사항
A3: 정원·현원(명) | B3: 어린이집정보공개포털 > 보육정보공개 API > OPEN API > FILE "전국 어린이집 정현원 현황" (전국어린이집정현원현황_20230102.xlsx, 출처: 보육통합정보시스템, 단위: 명). 2010~2022년만 제공. 17개 시도 합계가 매년 전국(계)와 일치함을 확인.
A4: 어린이집 수(개소) | B4: FILE "어린이집 현황(시·도)"(2009~2022)와 포털 통계 SHEET 파일(2023~2026)을 합친 값. 이전에 만든 "시도별_어린이집수_2009-2026.xlsx"와 동일.
A5: 원본 오류 정정 | B5: 경기 2018년 정원이 원본 파일에 497,296으로 입력되어 있는데, 이 값을 쓰면 17개 시도 합계가 전국(계)보다 정확히 30,000 큽니다. 앞뒤 연도(2017 466,020 / 2019 464,409)와도 맞지 않아 오타로 보고 467,296으로 정정했습니다(원자료 시트 주황색 칸, 메모 표시). 원본을 그대로 쓰려면 이 칸을 497,296으로 바꾸면 됩니다.
A6: 2026 | B6: 포털 조회 시점 최신값(기준월 미확인). 연도 비교에는 2025년까지를 권장.
A7: 광주·전남 | B7: 원자료는 분리되어 있고 2023년부터 어린이집 수는 합쳐서만 제공됨. 모든 시트는 "전남광주(광주+전남)" 합계 행으로 통일.
A8: 충족률 | B8: 현원÷정원. 각 시설이 정원을 다 채우는 것이 아니라 시도 합계의 비율이며, 시설별 빈자리 분포는 알 수 없음.
A9: 한계 | B9: 2023년 이후 정원·현원(명)은 이 파일에 없음. 시도별 현원은 포털 "연령별 아동 현황"(SHEET)에서, 시설별 정원·현원은 "어린이집 기본정보"에서 구할 수 있을 것으로 보이나 아직 확인하지 않음. 시군구 단위 아님.
