Workbook

Sheet 데이터셋
A1: 시군구코드 | B1: 시도 | C1: 시군구 | D1: 기준연도 | E1: 0~5세 인구 | F1: 0세 인구 | G1: 출생아수 | H1: 어린이집 수 | I1: 어린이집 정원 | J1: 어린이집 현원 | K1: 소아과 의원 수 | L1: 0~5세 1천명당 어린이집 | M1: 0~5세 1천명당 소아과 | N1: 정원 충족률 | O1: 0~5세 대비 정원 | P1: 출생아/0~5세 | Q1: 0~5세 3년 변화율 | R1: 출생아 3년 변화율 | S1: 소아과 3년 변화(곳) | T1: 어린이집 1년 변화율 | U1: 정원 1년 변화율 | V1: 소아과 0곳(현재 공백) | W1: 3년 후 어린이집 감소율 | X1: 어린이집 위험 | Y1: 소아과 위험 | Z1: 공백 위험(최종) | AA1: 고위험(둘 다) | AB1: 용도 | AC1: 국공립 수 | AD1: 민간 수 | AE1: 가정 수 | AF1: 직장 수 | AG1: 법인 수 | AH1: 협동 수 | AI1: 국공립 비율 | AJ1: 민간 비율 | AK1: 가정 비율 | AL1: 직장 비율 | AM1: 법인 비율 | AN1: 휴지 수 | AO1: 휴지 비율 | AP1: 1년 폐원 수 | AQ1: 1년 신규 수 | AR1: 1년 폐원율 | AS1: 1년 신규율 | AT1: 시도 소아과 개업(t) | AU1: 시도 소아과 폐업(t) | AV1: 시도 소아과 순증(t) | AW1: 시도 소아과 폐업률(t) | AX1: 시도 소아과 3년 누적 폐업 | AY1: 소아청소년과 진료 병원 수 | AZ1: 종합병원 수 | BA1: 병원 수(종합병원·병원) | BB1: 병원급 의료기관 수 | BC1: 소아과 의원+병원 수 | BD1: 0~5세 1천명당 소아과(의원+병원) | BE1: 소아과 진료 병원 3년 변화(곳) | BF1: 소아과 진료 병원 0곳 | BG1: 소아과 의원·병원 모두 0곳 | BH1: 기타 수(직장+법인+협동) | BI1: 기타 비율 | BJ1: 폐원+휴지 수(문 닫은 시설)
A2: 11110 | B2: 서울특별시 | C2: 종로구 | D2: 2016 | E2: 5133 | F2: 764 | G2: 846 | H2: 81 | I2: 4939 | J2: 3901 | K2: 4 | L2: 15.780245 | M2: 0.77927138 | N2: 0.789836 | O2: 0.96220534 | P2: 0.1648159 | Q2: -0.078456014 | R2: -0.030927835 | S2: 0 | V2: 0 | W2: -0.049382716 | X2: 0 | Y2: 0 | Z2: 0 | AA2: 0 | AB2: 학습 | AC2: 28 | AD2: 16 | AE2: 7 | AF2: 25 | AG2: 5 | AH2: 0 | AI2: 0.34567901 | AJ2: 0.19753086 | AK2: 0.086419753 | AL2: 0.30864198 | AM2: 0.061728395 | AN2: 0 | AO2: 0 | AT2: =SUMIFS(시도_소아과개폐업!$C$5:$C$293,시도_소아과개폐업!$A$5:$A$293,$D2,시도_소아과개폐업!$B$5:$B$293,$B2) -> 175 | AU2: =SUMIFS(시도_소아과개폐업!$D$5:$D$293,시도_소아과개폐업!$A$5:$A$293,$D2,시도_소아과개폐업!$B$5:$B$293,$B2) -> 91 | AV2: =SUMIFS(시도_소아과개폐업!$F$5:$F$293,시도_소아과개폐업!$A$5:$A$293,$D2,시도_소아과개폐업!$B$5:$B$293,$B2) -> 84 | AW2: =SUMIFS(시도_소아과개폐업!$G$5:$G$293,시도_소아과개폐업!$A$5:$A$293,$D2,시도_소아과개폐업!$B$5:$B$293,$B2) -> 0.17533719 | AX2: =SUMIFS(시도_소아과개폐업!$H$5:$H$293,시도_소아과개폐업!$A$5:$A$293,$D2,시도_소아과개폐업!$B$5:$B$293,$B2) -> 298 | AY2: =SUMIFS(시군구_병원급!$E$5:$E$3668,시군구_병원급!$A$5:$A$3668,$A2,시군구_병원급!$D$5:$D$3668,$D2) -> 5 | AZ2: =SUMIFS(시군구_병원급!$F$5:$F$3668,시군구_병원급!$A$5:$A$3668,$A2,시군구_병원급!$D$5:$D$3668,$D2) -> 4 | BA2: =SUMIFS(시군구_병원급!$G$5:$G$3668,시군구_병원급!$A$5:$A$3668,$A2,시군구_병원급!$D$5:$D$3668,$D2) -> 6 | BB2: =SUMIFS(시군구_병원급!$H$5:$H$3668,시군구_병원급!$A$5:$A$3668,$A2,시군구_병원급!$D$5:$D$3668,$D2) -> 8 | BC2: =K2+AY2 -> 9 | BD2: =IF(E2=0,"",(K2+AY2)/E2*1000) -> 1.7533606 | BE2: =AY2-SUMIFS(시군구_병원급!$E$5:$E$3668,시군구_병원급!$A$5:$A$3668,$A2,시군구_병원급!$D$5:$D$3668,$D2-3) -> 0 | BF2: =IF(AY2=0,1,0) -> 0 | BG2: =IF(K2+AY2=0,1,0) -> 0 | BH2: =AF2+AG2+AH2 -> 30 | BI2: =IF(H2=0,"",BH2/H2) -> 0.37037037 | BJ2: =IF(AP2="","",AP2+AN2)
A3: 11140 | B3: 서울특별시 | C3: 중구 | D3: 2016 | E3: 5085 | F3: 851 | G3: 959 | H3: 67 | I3: 4136 | J3: 3446 | K3: 5 | L3: 13.176008 | M3: 0.98328417 | N3: 0.83317215 | O3: 0.81337266 | P3: 0.1885939 | Q3: -0.099043232 | R3: -0.061643836 | S3: 1 | V3: 0 | W3: 0.029850746 | X3: 0 | Y3: 0 | Z3: 0 | AA3: 0 | AB3: 학습 | AC3: 19 | AD3: 8 | AE3: 15 | AF3: 18 | AG3: 7 | AH3: 0 | AI3: 0.28358209 | AJ3: 0.11940299 | AK3: 0.2238806 | AL3: 0.26865672 | AM3: 0.10447761 | AN3: 2 | AO3: 0.028985507 | AT3: =SUMIFS(시도_소아과개폐업!$C$5:$C$293,시도_소아과개폐업!$A$5:$A$293,$D3,시도_소아과개폐업!$B$5:$B$293,$B3) -> 175 | AU3: =SUMIFS(시도_소아과개폐업!$D$5:$D$293,시도_소아과개폐업!$A$5:$A$293,$D3,시도_소아과개폐업!$B$5:$B$293,$B3) -> 91 | AV3: =SUMIFS(시도_소아과개폐업!$F$5:$F$293,시도_소아과개폐업!$A$5:$A$293,$D3,시도_소아과개폐업!$B$5:$B$293,$B3) -> 84 | AW3: =SUMIFS(시도_소아과개폐업!$G$5:$G$293,시도_소아과개폐업!$A$5:$A$293,$D3,시도_소아과개폐업!$B$5:$B$293,$B3) -> 0.17533719 | AX3: =SUMIFS(시도_소아과개폐업!$H$5:$H$293,시도_소아과개폐업!$A$5:$A$293,$D3,시도_소아과개폐업!$B$5:$B$293,$B3) -> 298 | AY3: =SUMIFS(시군구_병원급!$E$5:$E$3668,시군구_병원급!$A$5:$A$3668,$A3,시군구_병원급!$D$5:$D$3668,$D3) -> 4 | AZ3: =SUMIFS(시군구_병원급!$F$5:$F$3668,시군구_병원급!$A$5:$A$3668,$A3,시군구_병원급!$D$5:$D$3668,$D3) -> 2 | BA3: =SUMIFS(시군구_병원급!$G$5:$G$3668,시군구_병원급!$A$5:$A$3668,$A3,시군구_병원급!$D$5:$D$3668,$D3) -> 6 | BB3: =SUMIFS(시군구_병원급!$H$5:$H$3668,시군구_병원급!$A$5:$A$3668,$A3,시군구_병원급!$D$5:$D$3668,$D3) -> 14 | BC3: =K3+AY3 -> 9 | BD3: =IF(E3=0,"",(K3+AY3)/E3*1000) -> 1.7699115 | BE3: =AY3-SUMIFS(시군구_병원급!$E$5:$E$3668,시군구_병원급!$A$5:$A$3668,$A3,시군구_병원급!$D$5:$D$3668,$D3-3) -> 0 | BF3: =IF(AY3=0,1,0) -> 0 | BG3: =IF(K3+AY3=0,1,0) -> 0 | BH3: =AF3+AG3+AH3 -> 25 | BI3: =IF(H3=0,"",BH3/H3) -> 0.37313433 | BJ3: =IF(AP3="","",AP3+AN3)
A4: 11170 | B4: 서울특별시 | C4: 용산구 | D4: 2016 | E4: 9965 | F4: 1577 | G4: 1708 | H4: 125 | I4: 5363 | J4: 4830 | K4: 9 | L4: 12.543904 | M4: 0.90316106 | N4: 0.90061533 | O4: 0.53818364 | P4: 0.1713999 | Q4: -0.10963188 | R4: -0.19774542 | S4: 0 | V4: 0 | W4: -0.048 | X4: 0 | Y4: 0 | Z4: 0 | AA4: 0 | AB4: 학습 | AC4: 22 | AD4: 32 | AE4: 51 | AF4: 8 | AG4: 11 | AH4: 1 | AI4: 0.176 | AJ4: 0.256 | AK4: 0.408 | AL4: 0.064 | AM4: 0.088 | AN4: 3 | AO4: 0.0234375 | AT4: =SUMIFS(시도_소아과개폐업!$C$5:$C$293,시도_소아과개폐업!$A$5:$A$293,$D4,시도_소아과개폐업!$B$5:$B$293,$B4) -> 175 | AU4: =SUMIFS(시도_소아과개폐업!$D$5:$D$293,시도_소아과개폐업!$A$5:$A$293,$D4,시도_소아과개폐업!$B$5:$B$293,$B4) -> 91 | AV4: =SUMIFS(시도_소아과개폐업!$F$5:$F$293,시도_소아과개폐업!$A$5:$A$293,$D4,시도_소아과개폐업!$B$5:$B$293,$B4) -> 84 | AW4: =SUMIFS(시도_소아과개폐업!$G$5:$G$293,시도_소아과개폐업!$A$5:$A$293,$D4,시도_소아과개폐업!$B$5:$B$293,$B4) -> 0.17533719 | AX4: =SUMIFS(시도_소아과개폐업!$H$5:$H$293,시도_소아과개폐업!$A$5:$A$293,$D4,시도_소아과개폐업!$B$5:$B$293,$B4) -> 298 | AY4: =SUMIFS(시군구_병원급!$E$5:$E$3668,시군구_병원급!$A$5:$A$3668,$A4,시군구_병원급!$D$5:$D$3668,$D4) -> 2 | AZ4: =SUMIFS(시군구_병원급!$F$5:$F$3668,시군구_병원급!$A$5:$A$3668,$A4,시군구_병원급!$D$5:$D$3668,$D4) -> 1 | BA4: =SUMIFS(시군구_병원급!$G$5:$G$3668,시군구_병원급!$A$5:$A$3668,$A4,시군구_병원급!$D$5:$D$3668,$D4) -> 3 | BB4: =SUMIFS(시군구_병원급!$H$5:$H$3668,시군구_병원급!$A$5:$A$3668,$A4,시군구_병원급!$D$5:$D$3668,$D4) -> 3 | BC4: =K4+AY4 -> 11 | BD4: =IF(E4=0,"",(K4+AY4)/E4*1000) -> 1.1038635 | BE4: =AY4-SUMIFS(시군구_병원급!$E$5:$E$3668,시군구_병원급!$A$5:$A$3668,$A4,시군구_병원급!$D$5:$D$3668,$D4-3) -> 0 | BF4: =IF(AY4=0,1,0) -> 0 | BG4: =IF(K4+AY4=0,1,0) -> 0 | BH4: =AF4+AG4+AH4 -> 20 | BI4: =IF(H4=0,"",BH4/H4) -> 0.16 | BJ4: =IF(AP4="","",AP4+AN4)
A5: 11200 | B5: 서울특별시 | C5: 성동구 | D5: 2016 | E5: 14817 | F5: 2470 | G5: 2531 | H5: 189 | I5: 8133 | J5: 7049 | K5: 20 | L5: 12.755619 | M5: 1.3498009 | N5: 0.86671585 | O5: 0.54889654 | P5: 0.1708173 | Q5: -0.0064373366 | R5: -0.10817477 | S5: 1 | V5: 0 | W5: -0.052910053 | X5: 0 | Y5: 0 | Z5: 0 | AA5: 0 | AB5: 학습 | AC5: 64 | AD5: 43 | AE5: 74 | AF5: 5 | AG5: 3 | AH5: 0 | AI5: 0.33862434 | AJ5: 0.22751323 | AK5: 0.39153439 | AL5: 0.026455026 | AM5: 0.015873016 | AN5: 4 | AO5: 0.020725389 | AT5: =SUMIFS(시도_소아과개폐업!$C$5:$C$293,시도_소아과개폐업!$A$5:$A$293,$D5,시도_소아과개폐업!$B$5:$B$293,$B5) -> 175 | AU5: =SUMIFS(시도_소아과개폐업!$D$5:$D$293,시도_소아과개폐업!$A$5:$A$293,$D5,시도_소아과개폐업!$B$5:$B$293,$B5) -> 91 | AV5: =SUMIFS(시도_소아과개폐업!$F$5:$F$293,시도_소아과개폐업!$A$5:$A$293,$D5,시도_소아과개폐업!$B$5:$B$293,$B5) -> 84 | AW5: =SUMIFS(시도_소아과개폐업!$G$5:$G$293,시도_소아과개폐업!$A$5:$A$293,$D5,시도_소아과개폐업!$B$5:$B$293,$B5) -> 0.17533719 | AX5: =SUMIFS(시도_소아과개폐업!$H$5:$H$293,시도_소아과개폐업!$A$5:$A$293,$D5,시도_소아과개폐업!$B$5:$B$293,$B5) -> 298 | AY5: =SUMIFS(시군구_병원급!$E$5:$E$3668,시군구_병원급!$A$5:$A$3668,$A5,시군구_병원급!$D$5:$D$3668,$D5) -> 5 | AZ5: =SUMIFS(시군구_병원급!$F$5:$F$3668,시군구_병원급!$A$5:$A$3668,$A5,시군구_병원급!$D$5:$D$3668,$D5) -> 2 | BA5: =SUMIFS(시군구_병원급!$G$5:$G$3668,시군구_병원급!$A$5:$A$3668,$A5,시군구_병원급!$D$5:$D$3668,$D5) -> 7 | BB5: =SUMIFS(시군구_병원급!$H$5:$H$3668,시군구_병원급!$A$5:$A$3668,$A5,시군구_병원급!$D$5:$D$3668,$D5) -> 10 | BC5: =K5+AY5 -> 25 | BD5: =IF(E5=0,"",(K5+AY5)/E5*1000) -> 1.6872511 | BE5: =AY5-SUMIFS(시군구_병원급!$E$5:$E$3668,시군구_병원급!$A$5:$A$3668,$A5,시군구_병원급!$D$5:$D$3668,$D5-3) -> 0 | BF5: =IF(AY5=0,1,0) -> 0 | BG5: =IF(K5+AY5=0,1,0) -> 0 | BH5: =AF5+AG5+AH5 -> 8 | BI5: =IF(H5=0,"",BH5/H5) -> 0.042328042 | BJ5: =IF(AP5="","",AP5+AN5)
A6: 11215 | B6: 서울특별시 | C6: 광진구 | D6: 2016 | E6: 15162 | F6: 2553 | G6: 2767 | H6: 217 | I6: 9297 | J6: 8046 | K6: 20 | L6: 14.312096 | M6: 1.3190872 | N6: 0.86544046 | O6: 0.61317768 | P6: 0.18249571 | Q6: -0.079025694 | R6: -0.07458194 | S6: -1 | V6: 0 | W6: -0.13364055 | X6: 0 | Y6: 0 | Z6: 0 | AA6: 0 | AB6: 학습 | AC6: 29 | AD6: 108 | AE6: 71 | AF6: 3 | AG6: 4 | AH6: 2 | AI6: 0.13364055 | AJ6: 0.49769585 | AK6: 0.32718894 | AL6: 0.013824885 | AM6: 0.01843318 | AN6: 23 | AO6: 0.095833333 | AT6: =SUMIFS(시도_소아과개폐업!$C$5:$C$293,시도_소아과개폐업!$A$5:$A$293,$D6,시도_소아과개폐업!$B$5:$B$293,$B6) -> 175 | AU6: =SUMIFS(시도_소아과개폐업!$D$5:$D$293,시도_소아과개폐업!$A$5:$A$293,$D6,시도_소아과개폐업!$B$5:$B$293,$B6) -> 91 | AV6: =SUMIFS(시도_소아과개폐업!$F$5:$F$293,시도_소아과개폐업!$A$5:$A$293,$D6,시도_소아과개폐업!$B$5:$B$293,$B6) -> 84 | AW6: =SUMIFS(시도_소아과개폐업!$G$5:$G$293,시도_소아과개폐업!$A$5:$A$293,$D6,시도_소아과개폐업!$B$5:$B$293,$B6) -> 0.17533719 | AX6: =SUMIFS(시도_소아과개폐업!$H$5:$H$293,시도_소아과개폐업!$A$5:$A$293,$D6,시도_소아과개폐업!$B$5:$B$293,$B6) -> 298 | AY6: =SUMIFS(시군구_병원급!$E$5:$E$3668,시군구_병원급!$A$5:$A$3668,$A6,시군구_병원급!$D$5:$D$3668,$D6) -> 2 | AZ6: =SUMIFS(시군구_병원급!$F$5:$F$3668,시군구_병원급!$A$5:$A$3668,$A6,시군구_병원급!$D$5:$D$3668,$D6) -> 2 | BA6: =SUMIFS(시군구_병원급!$G$5:$G$3668,시군구_병원급!$A$5:$A$3668,$A6,시군구_병원급!$D$5:$D$3668,$D6) -> 6 | BB6: =SUMIFS(시군구_병원급!$H$5:$H$3668,시군구_병원급!$A$5:$A$3668,$A6,시군구_병원급!$D$5:$D$3668,$D6) -> 10 | BC6: =K6+AY6 -> 22 | BD6: =IF(E6=0,"",(K6+AY6)/E6*1000) -> 1.4509959 | BE6: =AY6-SUMIFS(시군구_병원급!$E$5:$E$3668,시군구_병원급!$A$5:$A$3668,$A6,시군구_병원급!$D$5:$D$3668,$D6-3) -> -1 | BF6: =IF(AY6=0,1,0) -> 0 | BG6: =IF(K6+AY6=0,1,0) -> 0 | BH6: =AF6+AG6+AH6 -> 9 | BI6: =IF(H6=0,"",BH6/H6) -> 0.041474654 | BJ6: =IF(AP6="","",AP6+AN6)
A7: 11230 | B7: 서울특별시 | C7: 동대문구 | D7: 2016 | E7: 15044 | F7: 2241 | G7: 2383 | H7: 231 | I7: 9566 | J7: 8364 | K7: 17 | L7: 15.354959 | M7: 1.1300186 | N7: 0.87434664 | O7: 0.63586812 | P7: 0.15840202 | Q7: -0.089346247 | R7: -0.10109393 | S7: 1 | V7: 0 | W7: -0.069264069 | X7: 0 | Y7: 0 | Z7: 0 | AA7: 0 | AB7: 학습 | AC7: 48 | AD7: 73 | AE7: 99 | AF7: 8 | AG7: 3 | AH7: 0 | AI7: 0.20779221 | AJ7: 0.31601732 | AK7: 0.42857143 | AL7: 0.034632035 | AM7: 0.012987013 | AN7: 9 | AO7: 0.0375 | AT7: =SUMIFS(시도_소아과개폐업!$C$5:$C$293,시도_소아과개폐업!$A$5:$A$293,$D7,시도_소아과개폐업!$B$5:$B$293,$B7) -> 175 | AU7: =SUMIFS(시도_소아과개폐업!$D$5:$D$293,시도_소아과개폐업!$A$5:$A$293,$D7,시도_소아과개폐업!$B$5:$B$293,$B7) -> 91 | AV7: =SUMIFS(시도_소아과개폐업!$F$5:$F$293,시도_소아과개폐업!$A$5:$A$293,$D7,시도_소아과개폐업!$B$5:$B$293,$B7) -> 84 | AW7: =SUMIFS(시도_소아과개폐업!$G$5:$G$293,시도_소아과개폐업!$A$5:$A$293,$D7,시도_소아과개폐업!$B$5:$B$293,$B7) -> 0.17533719 | AX7: =SUMIFS(시도_소아과개폐업!$H$5:$H$293,시도_소아과개폐업!$A$5:$A$293,$D7,시도_소아과개폐업!$B$5:$B$293,$B7) -> 298 | AY7: =SUMIFS(시군구_병원급!$E$5:$E$3668,시군구_병원급!$A$5:$A$3668,$A7,시군구_병원급!$D$5:$D$3668,$D7) -> 8 | AZ7: =SUMIFS(시군구_병원급!$F$5:$F$3668,시군구_병원급!$A$5:$A$3668,$A7,시군구_병원급!$D$5:$D$3668,$D7) -> 5 | BA7: =SUMIFS(시군구_병원급!$G$5:$G$3668,시군구_병원급!$A$5:$A$3668,$A7,시군구_병원급!$D$5:$D$3668,$D7) -> 19 | BB7: =SUMIFS(시군구_병원급!$H$5:$H$3668,시군구_병원급!$A$5:$A$3668,$A7,시군구_병원급!$D$5:$D$3668,$D7) -> 33 | BC7: =K7+AY7 -> 25 | BD7: =IF(E7=0,"",(K7+AY7)/E7*1000) -> 1.6617921 | BE7: =AY7-SUMIFS(시군구_병원급!$E$5:$E$3668,시군구_병원급!$A$5:$A$3668,$A7,시군구_병원급!$D$5:$D$3668,$D7-3) -> 1 | BF7: =IF(AY7=0,1,0) -> 0 | BG7: =IF(K7+AY7=0,1,0) -> 0 | BH7: =AF7+AG7+AH7 -> 11 | BI7: =IF(H7=0,"",BH7/H7) -> 0.047619048 | BJ7: =IF(AP7="","",AP7+AN7)
A8: 11260 | B8: 서울특별시 | C8: 중랑구 | D8: 2016 | E8: 18040 | F8: 2843 | G8: 3085 | H8: 260 | I8: 11966 | J8: 10558 | K8: 19 | L8: 14.412417 | M8: 1.0532151 | N8: 0.88233328 | O8: 0.66330377 | P8: 0.17100887 | Q8: -0.038020583 | R8: -0.055130168 | S8: 0 | V8: 0 | W8: -0.11538462 | X8: 0 | Y8: 0 | Z8: 0 | AA8: 0 | AB8: 학습 | AC8: 34 | AD8: 107 | AE8: 112 | AF8: 2 | AG8: 5 | AH8: 0 | AI8: 0.13076923 | AJ8: 0.41153846 | AK8: 0.43076923 | AL8: 0.0076923077 | AM8: 0.019230769 | AN8: 3 | AO8: 0.011406844 | AT8: =SUMIFS(시도_소아과개폐업!$C$5:$C$293,시도_소아과개폐업!$A$5:$A$293,$D8,시도_소아과개폐업!$B$5:$B$293,$B8) -> 175 | AU8: =SUMIFS(시도_소아과개폐업!$D$5:$D$293,시도_소아과개폐업!$A$5:$A$293,$D8,시도_소아과개폐업!$B$5:$B$293,$B8) -> 91 | AV8: =SUMIFS(시도_소아과개폐업!$F$5:$F$293,시도_소아과개폐업!$A$5:$A$293,$D8,시도_소아과개폐업!$B$5:$B$293,$B8) -> 84 | AW8: =SUMIFS(시도_소아과개폐업!$G$5:$G$293,시도_소아과개폐업!$A$5:$A$293,$D8,시도_소아과개폐업!$B$5:$B$293,$B8) -> 0.17533719 | AX8: =SUMIFS(시도_소아과개폐업!$H$5:$H$293,시도_소아과개폐업!$A$5:$A$293,$D8,시도_소아과개폐업!$B$5:$B$293,$B8) -> 298 | AY8: =SUMIFS(시군구_병원급!$E$5:$E$3668,시군구_병원급!$A$5:$A$3668,$A8,시군구_병원급!$D$5:$D$3668,$D8) -> 6 | AZ8: =SUMIFS(시군구_병원급!$F$5:$F$3668,시군구_병원급!$A$5:$A$3668,$A8,시군구_병원급!$D$5:$D$3668,$D8) -> 3 | BA8: =SUMIFS(시군구_병원급!$G$5:$G$3668,시군구_병원급!$A$5:$A$3668,$A8,시군구_병원급!$D$5:$D$3668,$D8) -> 16 | BB8: =SUMIFS(시군구_병원급!$H$5:$H$3668,시군구_병원급!$A$5:$A$3668,$A8,시군구_병원급!$D$5:$D$3668,$D8) -> 20 | BC8: =K8+AY8 -> 25 | BD8: =IF(E8=0,"",(K8+AY8)/E8*1000) -> 1.3858093 | BE8: =AY8-SUMIFS(시군구_병원급!$E$5:$E$3668,시군구_병원급!$A$5:$A$3668,$A8,시군구_병원급!$D$5:$D$3668,$D8-3) -> 0 | BF8: =IF(AY8=0,1,0) -> 0 | BG8: =IF(K8+AY8=0,1,0) -> 0 | BH8: =AF8+AG8+AH8 -> 7 | BI8: =IF(H8=0,"",BH8/H8) -> 0.026923077 | BJ8: =IF(AP8="","",AP8+AN8)
A9: 11290 | B9: 서울특별시 | C9: 성북구 | D9: 2016 | E9: 20369 | F9: 2921 | G9: 3060 | H9: 310 | I9: 12033 | J9: 10493 | K9: 21 | L9: 15.219206 | M9: 1.0309784 | N9: 0.87201862 | O9: 0.59075065 | P9: 0.15022829 | Q9: -0.1468839 | R9: -0.20125294 | S9: -4 | V9: 0 | W9: -0.13870968 | X9: 0 | Y9: 0 | Z9: 0 | AA9: 0 | AB9: 학습 | AC9: 54 | AD9: 100 | AE9: 128 | AF9: 5 | AG9: 22 | AH9: 1 | AI9: 0.17419355 | AJ9: 0.32258065 | AK9: 0.41290323 | AL9: 0.016129032 | AM9: 0.070967742 | AN9: 6 | AO9: 0.018987342 | AT9: =SUMIFS(시도_소아과개폐업!$C$5:$C$293,시도_소아과개폐업!$A$5:$A$293,$D9,시도_소아과개폐업!$B$5:$B$293,$B9) -> 175 | AU9: =SUMIFS(시도_소아과개폐업!$D$5:$D$293,시도_소아과개폐업!$A$5:$A$293,$D9,시도_소아과개폐업!$B$5:$B$293,$B9) -> 91 | AV9: =SUMIFS(시도_소아과개폐업!$F$5:$F$293,시도_소아과개폐업!$A$5:$A$293,$D9,시도_소아과개폐업!$B$5:$B$293,$B9) -> 84 | AW9: =SUMIFS(시도_소아과개폐업!$G$5:$G$293,시도_소아과개폐업!$A$5:$A$293,$D9,시도_소아과개폐업!$B$5:$B$293,$B9) -> 0.17533719 | AX9: =SUMIFS(시도_소아과개폐업!$H$5:$H$293,시도_소아과개폐업!$A$5:$A$293,$D9,시도_소아과개폐업!$B$5:$B$293,$B9) -> 298 | AY9: =SUMIFS(시군구_병원급!$E$5:$E$3668,시군구_병원급!$A$5:$A$3668,$A9,시군구_병원급!$D$5:$D$3668,$D9) -> 5 | AZ9: =SUMIFS(시군구_병원급!$F$5:$F$3668,시군구_병원급!$A$5:$A$3668,$A9,시군구_병원급!$D$5:$D$3668,$D9) -> 1 | BA9: =SUMIFS(시군구_병원급!$G$5:$G$3668,시군구_병원급!$A$5:$A$3668,$A9,시군구_병원급!$D$5:$D$3668,$D9) -> 6 | BB9: =SUMIFS(시군구_병원급!$H$5:$H$3668,시군구_병원급!$A$5:$A$3668,$A9,시군구_병원급!$D$5:$D$3668,$D9) -> 13 | BC9: =K9+AY9 -> 26 | BD9: =IF(E9=0,"",(K9+AY9)/E9*1000) -> 1.2764495 | BE9: =AY9-SUMIFS(시군구_병원급!$E$5:$E$3668,시군구_병원급!$A$5:$A$3668,$A9,시군구_병원급!$D$5:$D$3668,$D9-3) -> 0 | BF9: =IF(AY9=0,1,0) -> 0 | BG9: =IF(K9+AY9=0,1,0) -> 0 | BH9: =AF9+AG9+AH9 -> 28 | BI9: =IF(H9=0,"",BH9/H9) -> 0.090322581 | BJ9: =IF(AP9="","",AP9+AN9)
A10: 11305 | B10: 서울특별시 | C10: 강북구 | D10: 2016 | E10: 12743 | F10: 1855 | G10: 1965 | H10: 182 | I10: 9017 | J10: 7947 | K10: 12 | L10: 14.282351 | M10: 0.94169348 | N10: 0.88133526 | O10: 0.70760417 | P10: 0.15420231 | Q10: -0.15357024 | R10: -0.21116018 | S10: -1 | V10: 0 | W10: -0.15934066 | X10: 0 | Y10: 0 | Z10: 0 | AA10: 0 | AB10: 학습 | AC10: 35 | AD10: 79 | AE10: 60 | AF10: 2 | AG10: 5 | AH10: 1 | AI10: 0.19230769 | AJ10: 0.43406593 | AK10: 0.32967033 | AL10: 0.010989011 | AM10: 0.027472527 | AN10: 8 | AO10: 0.042105263 | AT10: =SUMIFS(시도_소아과개폐업!$C$5:$C$293,시도_소아과개폐업!$A$5:$A$293,$D10,시도_소아과개폐업!$B$5:$B$293,$B10) -> 175 | AU10: =SUMIFS(시도_소아과개폐업!$D$5:$D$293,시도_소아과개폐업!$A$5:$A$293,$D10,시도_소아과개폐업!$B$5:$B$293,$B10) -> 91 | AV10: =SUMIFS(시도_소아과개폐업!$F$5:$F$293,시도_소아과개폐업!$A$5:$A$293,$D10,시도_소아과개폐업!$B$5:$B$293,$B10) -> 84 | AW10: =SUMIFS(시도_소아과개폐업!$G$5:$G$293,시도_소아과개폐업!$A$5:$A$293,$D10,시도_소아과개폐업!$B$5:$B$293,$B10) -> 0.17533719 | AX10: =SUMIFS(시도_소아과개폐업!$H$5:$H$293,시도_소아과개폐업!$A$5:$A$293,$D10,시도_소아과개폐업!$B$5:$B$293,$B10) -> 298 | AY10: =SUMIFS(시군구_병원급!$E$5:$E$3668,시군구_병원급!$A$5:$A$3668,$A10,시군구_병원급!$D$5:$D$3668,$D10) -> 2 | AZ10: =SUMIFS(시군구_병원급!$F$5:$F$3668,시군구_병원급!$A$5:$A$3668,$A10,시군구_병원급!$D$5:$D$3668,$D10) -> 2 | BA10: =SUMIFS(시군구_병원급!$G$5:$G$3668,시군구_병원급!$A$5:$A$3668,$A10,시군구_병원급!$D$5:$D$3668,$D10) -> 10 | BB10: =SUMIFS(시군구_병원급!$H$5:$H$3668,시군구_병원급!$A$5:$A$3668,$A10,시군구_병원급!$D$5:$D$3668,$D10) -> 15 | BC10: =K10+AY10 -> 14 | BD10: =IF(E10=0,"",(K10+AY10)/E10*1000) -> 1.0986424 | BE10: =AY10-SUMIFS(시군구_병원급!$E$5:$E$3668,시군구_병원급!$A$5:$A$3668,$A10,시군구_병원급!$D$5:$D$3668,$D10-3) -> 0 | BF10: =IF(AY10=0,1,0) -> 0 | BG10: =IF(K10+AY10=0,1,0) -> 0 | BH10: =AF10+AG10+AH10 -> 8 | BI10: =IF(H10=0,"",BH10/H10) -> 0.043956044 | BJ10: =IF(AP10="","",AP10+AN10)
A11: 11320 | B11: 서울특별시 | C11: 도봉구 | D11: 2016 | E11: 14705 | F11: 2179 | G11: 2249 | H11: 265 | I11: 10543 | J11: 9044 | K11: 17 | L11: 18.021081 | M11: 1.1560694 | N11: 0.85782035 | O11: 0.71696702 | P11: 0.15294118 | Q11: -0.08624868 | R11: -0.11106719 | S11: 1 | V11: 0 | W11: -0.13584906 | X11: 0 | Y11: 0 | Z11: 0 | AA11: 0 | AB11: 학습 | AC11: 32 | AD11: 80 | AE11: 146 | AF11: 2 | AG11: 3 | AH11: 2 | AI11: 0.12075472 | AJ11: 0.30188679 | AK11: 0.5509434 | AL11: 0.0075471698 | AM11: 0.011320755 | AN11: 13 | AO11: 0.04676259 | AT11: =SUMIFS(시도_소아과개폐업!$C$5:$C$293,시도_소아과개폐업!$A$5:$A$293,$D11,시도_소아과개폐업!$B$5:$B$293,$B11) -> 175 | AU11: =SUMIFS(시도_소아과개폐업!$D$5:$D$293,시도_소아과개폐업!$A$5:$A$293,$D11,시도_소아과개폐업!$B$5:$B$293,$B11) -> 91 | AV11: =SUMIFS(시도_소아과개폐업!$F$5:$F$293,시도_소아과개폐업!$A$5:$A$293,$D11,시도_소아과개폐업!$B$5:$B$293,$B11) -> 84 | AW11: =SUMIFS(시도_소아과개폐업!$G$5:$G$293,시도_소아과개폐업!$A$5:$A$293,$D11,시도_소아과개폐업!$B$5:$B$293,$B11) -> 0.17533719 | AX11: =SUMIFS(시도_소아과개폐업!$H$5:$H$293,시도_소아과개폐업!$A$5:$A$293,$D11,시도_소아과개폐업!$B$5:$B$293,$B11) -> 298 | AY11: =SUMIFS(시군구_병원급!$E$5:$E$3668,시군구_병원급!$A$5:$A$3668,$A11,시군구_병원급!$D$5:$D$3668,$D11) -> 3 | AZ11: =SUMIFS(시군구_병원급!$F$5:$F$3668,시군구_병원급!$A$5:$A$3668,$A11,시군구_병원급!$D$5:$D$3668,$D11) -> 1 | BA11: =SUMIFS(시군구_병원급!$G$5:$G$3668,시군구_병원급!$A$5:$A$3668,$A11,시군구_병원급!$D$5:$D$3668,$D11) -> 6 | BB11: =SUMIFS(시군구_병원급!$H$5:$H$3668,시군구_병원급!$A$5:$A$3668,$A11,시군구_병원급!$D$5:$D$3668,$D11) -> 20 | BC11: =K11+AY11 -> 20 | BD11: =IF(E11=0,"",(K11+AY11)/E11*1000) -> 1.3600816 | BE11: =AY11-SUMIFS(시군구_병원급!$E$5:$E$3668,시군구_병원급!$A$5:$A$3668,$A11,시군구_병원급!$D$5:$D$3668,$D11-3) -> 0 | BF11: =IF(AY11=0,1,0) -> 0 | BG11: =IF(K11+AY11=0,1,0) -> 0 | BH11: =AF11+AG11+AH11 -> 7 | BI11: =IF(H11=0,"",BH11/H11) -> 0.026415094 | BJ11: =IF(AP11="","",AP11+AN11)
A12: 11350 | B12: 서울특별시 | C12: 노원구 | D12: 2016 | E12: 25224 | F12: 3935 | G12: 4176 | H12: 494 | I12: 14436 | J12: 12748 | K12: 33 | L12: 19.584523 | M12: 1.3082778 | N12: 0.8830701 | O12: 0.57231208 | P12: 0.16555661 | Q12: -0.1014214 | R12: -0.10539846 | S12: -2 | V12: 0 | W12: -0.18016194 | X12: 1 | Y12: 0 | Z12: 1 | AA12: 0 | AB12: 학습 | AC12: 47 | AD12: 79 | AE12: 356 | AF12: 6 | AG12: 5 | AH12: 1 | AI12: 0.0951417 | AJ12: 0.15991903 | AK12: 0.72064777 | AL12: 0.012145749 | AM12: 0.010121457 | AN12: 24 | AO12: 0.046332046 | AT12: =SUMIFS(시도_소아과개폐업!$C$5:$C$293,시도_소아과개폐업!$A$5:$A$293,$D12,시도_소아과개폐업!$B$5:$B$293,$B12) -> 175 | AU12: =SUMIFS(시도_소아과개폐업!$D$5:$D$293,시도_소아과개폐업!$A$5:$A$293,$D12,시도_소아과개폐업!$B$5:$B$293,$B12) -> 91 | AV12: =SUMIFS(시도_소아과개폐업!$F$5:$F$293,시도_소아과개폐업!$A$5:$A$293,$D12,시도_소아과개폐업!$B$5:$B$293,$B12) -> 84 | AW12: =SUMIFS(시도_소아과개폐업!$G$5:$G$293,시도_소아과개폐업!$A$5:$A$293,$D12,시도_소아과개폐업!$B$5:$B$293,$B12) -> 0.17533719 | AX12: =SUMIFS(시도_소아과개폐업!$H$5:$H$293,시도_소아과개폐업!$A$5:$A$293,$D12,시도_소아과개폐업!$B$5:$B$293,$B12) -> 298 | AY12: =SUMIFS(시군구_병원급!$E$5:$E$3668,시군구_병원급!$A$5:$A$3668,$A12,시군구_병원급!$D$5:$D$3668,$D12) -> 8 | AZ12: =SUMIFS(시군구_병원급!$F$5:$F$3668,시군구_병원급!$A$5:$A$3668,$A12,시군구_병원급!$D$5:$D$3668,$D12) -> 3 | BA12: =SUMIFS(시군구_병원급!$G$5:$G$3668,시군구_병원급!$A$5:$A$3668,$A12,시군구_병원급!$D$5:$D$3668,$D12) -> 10 | BB12: =SUMIFS(시군구_병원급!$H$5:$H$3668,시군구_병원급!$A$5:$A$3668,$A12,시군구_병원급!$D$5:$D$3668,$D12) -> 21 | BC12: =K12+AY12 -> 41 | BD12: =IF(E12=0,"",(K12+AY12)/E12*1000) -> 1.6254361 | BE12: =AY12-SUMIFS(시군구_병원급!$E$5:$E$3668,시군구_병원급!$A$5:$A$3668,$A12,시군구_병원급!$D$5:$D$3668,$D12-3) -> -1 | BF12: =IF(AY12=0,1,0) -> 0 | BG12: =IF(K12+AY12=0,1,0) -> 0 | BH12: =AF12+AG12+AH12 -> 12 | BI12: =IF(H12=0,"",BH12/H12) -> 0.024291498 | BJ12: =IF(AP12="","",AP12+AN12)
A13: 11380 | B13: 서울특별시 | C13: 은평구 | D13: 2016 | E13: 22077 | F13: 3338 | G13: 3522 | H13: 314 | I13: 15002 | J13: 12746 | K13: 28 | L13: 14.222947 | M13: 1.2682883 | N13: 0.84962005 | O13: 0.67953073 | P13: 0.15953255 | Q13: -0.13089521 | R13: -0.15275439 | S13: -1 | V13: 0 | W13: -0.16242038 | X13: 0 | Y13: 0 | Z13: 0 | AA13: 0 | AB13: 학습 | AC13: 32 | AD13: 177 | AE13: 94 | AF13: 2 | AG13: 8 | AH13: 1 | AI13: 0.10191083 | AJ13: 0.56369427 | AK13: 0.29936306 | AL13: 0.0063694268 | AM13: 0.025477707 | AN13: 3 | AO13: 0.0094637224 | AT13: =SUMIFS(시도_소아과개폐업!$C$5:$C$293,시도_소아과개폐업!$A$5:$A$293,$D13,시도_소아과개폐업!$B$5:$B$293,$B13) -> 175 | AU13: =SUMIFS(시도_소아과개폐업!$D$5:$D$293,시도_소아과개폐업!$A$5:$A$293,$D13,시도_소아과개폐업!$B$5:$B$293,$B13) -> 91 | AV13: =SUMIFS(시도_소아과개폐업!$F$5:$F$293,시도_소아과개폐업!$A$5:$A$293,$D13,시도_소아과개폐업!$B$5:$B$293,$B13) -> 84 | AW13: =SUMIFS(시도_소아과개폐업!$G$5:$G$293,시도_소아과개폐업!$A$5:$A$293,$D13,시도_소아과개폐업!$B$5:$B$293,$B13) -> 0.17533719 | AX13: =SUMIFS(시도_소아과개폐업!$H$5:$H$293,시도_소아과개폐업!$A$5:$A$293,$D13,시도_소아과개폐업!$B$5:$B$293,$B13) -> 298 | AY13: =SUMIFS(시군구_병원급!$E$5:$E$3668,시군구_병원급!$A$5:$A$3668,$A13,시군구_병원급!$D$5:$D$3668,$D13) -> 10 | AZ13: =SUMIFS(시군구_병원급!$F$5:$F$3668,시군구_병원급!$A$5:$A$3668,$A13,시군구_병원급!$D$5:$D$3668,$D13) -> 2 | BA13: =SUMIFS(시군구_병원급!$G$5:$G$3668,시군구_병원급!$A$5:$A$3668,$A13,시군구_병원급!$D$5:$D$3668,$D13) -> 14 | BB13: =SUMIFS(시군구_병원급!$H$5:$H$3668,시군구_병원급!$A$5:$A$3668,$A13,시군구_병원급!$D$5:$D$3668,$D13) -> 25 | BC13: =K13+AY13 -> 38 | BD13: =IF(E13=0,"",(K13+AY13)/E13*1000) -> 1.7212484 | BE13: =AY13-SUMIFS(시군구_병원급!$E$5:$E$3668,시군구_병원급!$A$5:$A$3668,$A13,시군구_병원급!$D$5:$D$3668,$D13-3) -> 0 | BF13: =IF(AY13=0,1,0) -> 0 | BG13: =IF(K13+AY13=0,1,0) -> 0 | BH13: =AF13+AG13+AH13 -> 11 | BI13: =IF(H13=0,"",BH13/H13) -> 0.035031847 | BJ13: =IF(AP13="","",AP13+AN13)
... A230: 52800 | B230: 전북특별자치도 | C230: 부안군 | D230: 2016 | E230: 1884 | F230: 264 | G230: 268 | H230: 28 | I230: 1493 | J230: 1026 | K230: 1 | L230: 14.861996 | M230: 0.53078556 | N230: 0.68720697 | O230: 0.79246285 | P230: 0.14225053 | Q230: -0.1150775 | R230: -0.10067114 | S230: 0 | V230: 0 | W230: -0.17857143 | X230: 1 | Y230: 0 | Z230: 1 | AA230: 0 | AB230: 학습 | AC230: 1 | AD230: 20 | AE230: 3 | AF230: 1 | AG230: 3 | AH230: 0 | AI230: 0.035714286 | AJ230: 0.71428571 | AK230: 0.10714286 | AL230: 0.035714286 | AM230: 0.10714286 | AN230: 1 | AO230: 0.034482759 | AT230: =SUMIFS(시도_소아과개폐업!$C$5:$C$293,시도_소아과개폐업!$A$5:$A$293,$D230,시도_소아과개폐업!$B$5:$B$293,$B230) -> 24 | AU230: =SUMIFS(시도_소아과개폐업!$D$5:$D$293,시도_소아과개폐업!$A$5:$A$293,$D230,시도_소아과개폐업!$B$5:$B$293,$B230) -> 17 | AV230: =SUMIFS(시도_소아과개폐업!$F$5:$F$293,시도_소아과개폐업!$A$5:$A$293,$D230,시도_소아과개폐업!$B$5:$B$293,$B230) -> 7 | AW230: =SUMIFS(시도_소아과개폐업!$G$5:$G$293,시도_소아과개폐업!$A$5:$A$293,$D230,시도_소아과개폐업!$B$5:$B$293,$B230) -> 0.23611111 | AX230: =SUMIFS(시도_소아과개폐업!$H$5:$H$293,시도_소아과개폐업!$A$5:$A$293,$D230,시도_소아과개폐업!$B$5:$B$293,$B230) -> 53 | AY230: =SUMIFS(시군구_병원급!$E$5:$E$3668,시군구_병원급!$A$5:$A$3668,$A230,시군구_병원급!$D$5:$D$3668,$D230) -> 0 | AZ230: =SUMIFS(시군구_병원급!$F$5:$F$3668,시군구_병원급!$A$5:$A$3668,$A230,시군구_병원급!$D$5:$D$3668,$D230) -> 1 | BA230: =SUMIFS(시군구_병원급!$G$5:$G$3668,시군구_병원급!$A$5:$A$3668,$A230,시군구_병원급!$D$5:$D$3668,$D230) -> 6 | BB230: =SUMIFS(시군구_병원급!$H$5:$H$3668,시군구_병원급!$A$5:$A$3668,$A230,시군구_병원급!$D$5:$D$3668,$D230) -> 8 | BC230: =K230+AY230 -> 1 | BD230: =IF(E230=0,"",(K230+AY230)/E230*1000) -> 0.53078556 | BE230: =AY230-SUMIFS(시군구_병원급!$E$5:$E$3668,시군구_병원급!$A$5:$A$3668,$A230,시군구_병원급!$D$5:$D$3668,$D230-3) -> 0 | BF230: =IF(AY230=0,1,0) -> 1 | BG230: =IF(K230+AY230=0,1,0) -> 0 | BH230: =AF230+AG230+AH230 -> 4 | BI230: =IF(H230=0,"",BH230/H230) -> 0.14285714 | BJ230: =IF(AP230="","",AP230+AN230)
A231: 11110 | B231: 서울특별시 | C231: 종로구 | D231: 2017 | E231: 5157 | F231: 652 | G231: 689 | H231: 75 | I231: 4702 | J231: 3783 | K231: 4 | L231: 14.543339 | M231: 0.77564475 | N231: 0.80455125 | O231: 0.91177041 | P231: 0.13360481 | Q231: -0.030274539 | R231: -0.23867403 | S231: 0 | T231: -0.074074074 | U231: -0.047985422 | V231: 0 | W231: -0.013333333 | X231: 0 | Y231: 0 | Z231: 0 | AA231: 0 | AB231: 학습 | AC231: 28 | AD231: 11 | AE231: 5 | AF231: 26 | AG231: 5 | AH231: 0 | AI231: 0.37333333 | AJ231: 0.14666667 | AK231: 0.066666667 | AL231: 0.34666667 | AM231: 0.066666667 | AN231: 1 | AO231: 0.013157895 | AP231: 8 | AQ231: 3 | AR231: 0.098765432 | AS231: 0.037037037 | AT231: =SUMIFS(시도_소아과개폐업!$C$5:$C$293,시도_소아과개폐업!$A$5:$A$293,$D231,시도_소아과개폐업!$B$5:$B$293,$B231) -> 145 | AU231: =SUMIFS(시도_소아과개폐업!$D$5:$D$293,시도_소아과개폐업!$A$5:$A$293,$D231,시도_소아과개폐업!$B$5:$B$293,$B231) -> 107 | AV231: =SUMIFS(시도_소아과개폐업!$F$5:$F$293,시도_소아과개폐업!$A$5:$A$293,$D231,시도_소아과개폐업!$B$5:$B$293,$B231) -> 38 | AW231: =SUMIFS(시도_소아과개폐업!$G$5:$G$293,시도_소아과개폐업!$A$5:$A$293,$D231,시도_소아과개폐업!$B$5:$B$293,$B231) -> 0.20576923 | AX231: =SUMIFS(시도_소아과개폐업!$H$5:$H$293,시도_소아과개폐업!$A$5:$A$293,$D231,시도_소아과개폐업!$B$5:$B$293,$B231) -> 310 | AY231: =SUMIFS(시군구_병원급!$E$5:$E$3668,시군구_병원급!$A$5:$A$3668,$A231,시군구_병원급!$D$5:$D$3668,$D231) -> 5 | AZ231: =SUMIFS(시군구_병원급!$F$5:$F$3668,시군구_병원급!$A$5:$A$3668,$A231,시군구_병원급!$D$5:$D$3668,$D231) -> 4 | BA231: =SUMIFS(시군구_병원급!$G$5:$G$3668,시군구_병원급!$A$5:$A$3668,$A231,시군구_병원급!$D$5:$D$3668,$D231) -> 6 | BB231: =SUMIFS(시군구_병원급!$H$5:$H$3668,시군구_병원급!$A$5:$A$3668,$A231,시군구_병원급!$D$5:$D$3668,$D231) -> 8 | BC231: =K231+AY231 -> 9 | BD231: =IF(E231=0,"",(K231+AY231)/E231*1000) -> 1.7452007 | BE231: =AY231-SUMIFS(시군구_병원급!$E$5:$E$3668,시군구_병원급!$A$5:$A$3668,$A231,시군구_병원급!$D$5:$D$3668,$D231-3) -> 0 | BF231: =IF(AY231=0,1,0) -> 0 | BG231: =IF(K231+AY231=0,1,0) -> 0 | BH231: =AF231+AG231+AH231 -> 31 | BI231: =IF(H231=0,"",BH231/H231) -> 0.41333333 | BJ231: =IF(AP231="","",AP231+AN231) -> 9
A232: 11140 | B232: 서울특별시 | C232: 중구 | D232: 2017 | E232: 5001 | F232: 762 | G232: 808 | H232: 67 | I232: 4279 | J232: 3509 | K232: 5 | L232: 13.397321 | M232: 0.99980004 | N232: 0.82005141 | O232: 0.85562887 | P232: 0.16156769 | Q232: -0.06505889 | R232: -0.22382325 | S232: 2 | T232: 0 | U232: 0.034574468 | V232: 0 | W232: 0 | X232: 0 | Y232: 0 | Z232: 0 | AA232: 0 | AB232: 학습 | AC232: 21 | AD232: 7 | AE232: 14 | AF232: 18 | AG232: 7 | AH232: 0 | AI232: 0.31343284 | AJ232: 0.10447761 | AK232: 0.20895522 | AL232: 0.26865672 | AM232: 0.10447761 | AN232: 2 | AO232: 0.028985507 | AP232: 4 | AQ232: 4 | AR232: 0.057971014 | AS232: 0.057971014 | AT232: =SUMIFS(시도_소아과개폐업!$C$5:$C$293,시도_소아과개폐업!$A$5:$A$293,$D232,시도_소아과개폐업!$B$5:$B$293,$B232) -> 145 | AU232: =SUMIFS(시도_소아과개폐업!$D$5:$D$293,시도_소아과개폐업!$A$5:$A$293,$D232,시도_소아과개폐업!$B$5:$B$293,$B232) -> 107 | AV232: =SUMIFS(시도_소아과개폐업!$F$5:$F$293,시도_소아과개폐업!$A$5:$A$293,$D232,시도_소아과개폐업!$B$5:$B$293,$B232) -> 38 | AW232: =SUMIFS(시도_소아과개폐업!$G$5:$G$293,시도_소아과개폐업!$A$5:$A$293,$D232,시도_소아과개폐업!$B$5:$B$293,$B232) -> 0.20576923 | AX232: =SUMIFS(시도_소아과개폐업!$H$5:$H$293,시도_소아과개폐업!$A$5:$A$293,$D232,시도_소아과개폐업!$B$5:$B$293,$B232) -> 310 | AY232: =SUMIFS(시군구_병원급!$E$5:$E$3668,시군구_병원급!$A$5:$A$3668,$A232,시군구_병원급!$D$5:$D$3668,$D232) -> 4 | AZ232: =SUMIFS(시군구_병원급!$F$5:$F$3668,시군구_병원급!$A$5:$A$3668,$A232,시군구_병원급!$D$5:$D$3668,$D232) -> 2 | BA232: =SUMIFS(시군구_병원급!$G$5:$G$3668,시군구_병원급!$A$5:$A$3668,$A232,시군구_병원급!$D$5:$D$3668,$D232) -> 6 | BB232: =SUMIFS(시군구_병원급!$H$5:$H$3668,시군구_병원급!$A$5:$A$3668,$A232,시군구_병원급!$D$5:$D$3668,$D232) -> 13 | BC232: =K232+AY232 -> 9 | BD232: =IF(E232=0,"",(K232+AY232)/E232*1000) -> 1.7996401 | BE232: =AY232-SUMIFS(시군구_병원급!$E$5:$E$3668,시군구_병원급!$A$5:$A$3668,$A232,시군구_병원급!$D$5:$D$3668,$D232-3) -> 0 | BF232: =IF(AY232=0,1,0) -> 0 | BG232: =IF(K232+AY232=0,1,0) -> 0 | BH232: =AF232+AG232+AH232 -> 25 | BI232: =IF(H232=0,"",BH232/H232) -> 0.37313433 | BJ232: =IF(AP232="","",AP232+AN232) -> 6
A233: 11170 | B233: 서울특별시 | C233: 용산구 | D233: 2017 | E233: 9243 | F233: 1326 | G233: 1464 | H233: 128 | I233: 5554 | J233: 4753 | K233: 9 | L233: 13.848318 | M233: 0.97370983 | N233: 0.85577962 | O233: 0.60088716 | P233: 0.15839013 | Q233: -0.12925106 | R233: -0.25910931 | S233: -1 | T233: 0.024 | U233: 0.035614395 | V233: 0 | W233: -0.09375 | X233: 0 | Y233: 0 | Z233: 0 | AA233: 0 | AB233: 학습 | AC233: 28 | AD233: 28 | AE233: 51 | AF233: 9 | AG233: 11 | AH233: 1 | AI233: 0.21875 | AJ233: 0.21875 | AK233: 0.3984375 | AL233: 0.0703125 | AM233: 0.0859375 | AN233: 1 | AO233: 0.007751938 | AP233: 9 | AQ233: 10 | AR233: 0.0703125 | AS233: 0.078125 | AT233: =SUMIFS(시도_소아과개폐업!$C$5:$C$293,시도_소아과개폐업!$A$5:$A$293,$D233,시도_소아과개폐업!$B$5:$B$293,$B233) -> 145 | AU233: =SUMIFS(시도_소아과개폐업!$D$5:$D$293,시도_소아과개폐업!$A$5:$A$293,$D233,시도_소아과개폐업!$B$5:$B$293,$B233) -> 107 | AV233: =SUMIFS(시도_소아과개폐업!$F$5:$F$293,시도_소아과개폐업!$A$5:$A$293,$D233,시도_소아과개폐업!$B$5:$B$293,$B233) -> 38 | AW233: =SUMIFS(시도_소아과개폐업!$G$5:$G$293,시도_소아과개폐업!$A$5:$A$293,$D233,시도_소아과개폐업!$B$5:$B$293,$B233) -> 0.20576923 | AX233: =SUMIFS(시도_소아과개폐업!$H$5:$H$293,시도_소아과개폐업!$A$5:$A$293,$D233,시도_소아과개폐업!$B$5:$B$293,$B233) -> 310 | AY233: =SUMIFS(시군구_병원급!$E$5:$E$3668,시군구_병원급!$A$5:$A$3668,$A233,시군구_병원급!$D$5:$D$3668,$D233) -> 2 | AZ233: =SUMIFS(시군구_병원급!$F$5:$F$3668,시군구_병원급!$A$5:$A$3668,$A233,시군구_병원급!$D$5:$D$3668,$D233) -> 1 | BA233: =SUMIFS(시군구_병원급!$G$5:$G$3668,시군구_병원급!$A$5:$A$3668,$A233,시군구_병원급!$D$5:$D$3668,$D233) -> 3 | BB233: =SUMIFS(시군구_병원급!$H$5:$H$3668,시군구_병원급!$A$5:$A$3668,$A233,시군구_병원급!$D$5:$D$3668,$D233) -> 3 | BC233: =K233+AY233 -> 11 | BD233: =IF(E233=0,"",(K233+AY233)/E233*1000) -> 1.1900898 | BE233: =AY233-SUMIFS(시군구_병원급!$E$5:$E$3668,시군구_병원급!$A$5:$A$3668,$A233,시군구_병원급!$D$5:$D$3668,$D233-3) -> 0 | BF233: =IF(AY233=0,1,0) -> 0 | BG233: =IF(K233+AY233=0,1,0) -> 0 | BH233: =AF233+AG233+AH233 -> 21 | BI233: =IF(H233=0,"",BH233/H233) -> 0.1640625 | BJ233: =IF(AP233="","",AP233+AN233) -> 10
A234: 11200 | B234: 서울특별시 | C234: 성동구 | D234: 2017 | E234: 14876 | F234: 2336 | G234: 2462 | H234: 190 | I234: 8243 | J234: 7264 | K234: 23 | L234: 12.772251 | M234: 1.5461145 | N234: 0.88123256 | O234: 0.55411401 | P234: 0.16550148 | Q234: 0.030193906 | R234: -0.072343632 | S234: 4 | T234: 0.0052910053 | U234: 0.013525144 | V234: 0 | W234: -0.089473684 | X234: 0 | Y234: 0 | Z234: 0 | AA234: 0 | AB234: 학습 | AC234: 70 | AD234: 40 | AE234: 70 | AF234: 7 | AG234: 3 | AH234: 0 | AI234: 0.36842105 | AJ234: 0.21052632 | AK234: 0.36842105 | AL234: 0.036842105 | AM234: 0.015789474 | AN234: 3 | AO234: 0.015544041 | AP234: 12 | AQ234: 13 | AR234: 0.062176166 | AS234: 0.067357513 | AT234: =SUMIFS(시도_소아과개폐업!$C$5:$C$293,시도_소아과개폐업!$A$5:$A$293,$D234,시도_소아과개폐업!$B$5:$B$293,$B234) -> 145 | AU234: =SUMIFS(시도_소아과개폐업!$D$5:$D$293,시도_소아과개폐업!$A$5:$A$293,$D234,시도_소아과개폐업!$B$5:$B$293,$B234) -> 107 | AV234: =SUMIFS(시도_소아과개폐업!$F$5:$F$293,시도_소아과개폐업!$A$5:$A$293,$D234,시도_소아과개폐업!$B$5:$B$293,$B234) -> 38 | AW234: =SUMIFS(시도_소아과개폐업!$G$5:$G$293,시도_소아과개폐업!$A$5:$A$293,$D234,시도_소아과개폐업!$B$5:$B$293,$B234) -> 0.20576923 | AX234: =SUMIFS(시도_소아과개폐업!$H$5:$H$293,시도_소아과개폐업!$A$5:$A$293,$D234,시도_소아과개폐업!$B$5:$B$293,$B234) -> 310 | AY234: =SUMIFS(시군구_병원급!$E$5:$E$3668,시군구_병원급!$A$5:$A$3668,$A234,시군구_병원급!$D$5:$D$3668,$D234) -> 5 | AZ234: =SUMIFS(시군구_병원급!$F$5:$F$3668,시군구_병원급!$A$5:$A$3668,$A234,시군구_병원급!$D$5:$D$3668,$D234) -> 2 | BA234: =SUMIFS(시군구_병원급!$G$5:$G$3668,시군구_병원급!$A$5:$A$3668,$A234,시군구_병원급!$D$5:$D$3668,$D234) -> 9 | BB234: =SUMIFS(시군구_병원급!$H$5:$H$3668,시군구_병원급!$A$5:$A$3668,$A234,시군구_병원급!$D$5:$D$3668,$D234) -> 13 | BC234: =K234+AY234 -> 28 | BD234: =IF(E234=0,"",(K234+AY234)/E234*1000) -> 1.8822264 | BE234: =AY234-SUMIFS(시군구_병원급!$E$5:$E$3668,시군구_병원급!$A$5:$A$3668,$A234,시군구_병원급!$D$5:$D$3668,$D234-3) -> 0 | BF234: =IF(AY234=0,1,0) -> 0 | BG234: =IF(K234+AY234=0,1,0) -> 0 | BH234: =AF234+AG234+AH234 -> 10 | BI234: =IF(H234=0,"",BH234/H234) -> 0.052631579 | BJ234: =IF(AP234="","",AP234+AN234) -> 15
A235: 11215 | B235: 서울특별시 | C235: 광진구 | D235: 2017 | E235: 14497 | F235: 2183 | G235: 2347 | H235: 214 | I235: 9203 | J235: 7951 | K235: 20 | L235: 14.761675 | M235: 1.3795958 | N235: 0.86395741 | O235: 0.634821 | P235: 0.16189556 | Q235: -0.088124292 | R235: -0.22052474 | S235: -1 | T235: -0.013824885 | U235: -0.010110788 | V235: 0 | W235: -0.17757009 | X235: 0 | Y235: 0 | Z235: 0 | AA235: 0 | AB235: 학습 | AC235: 34 | AD235: 106 | AE235: 65 | AF235: 3 | AG235: 4 | AH235: 2 | AI235: 0.1588785 | AJ235: 0.4953271 | AK235: 0.30373832 | AL235: 0.014018692 | AM235: 0.018691589 | AN235: 21 | AO235: 0.089361702 | AP235: 11 | AQ235: 6 | AR235: 0.045833333 | AS235: 0.025 | AT235: =SUMIFS(시도_소아과개폐업!$C$5:$C$293,시도_소아과개폐업!$A$5:$A$293,$D235,시도_소아과개폐업!$B$5:$B$293,$B235) -> 145 | AU235: =SUMIFS(시도_소아과개폐업!$D$5:$D$293,시도_소아과개폐업!$A$5:$A$293,$D235,시도_소아과개폐업!$B$5:$B$293,$B235) -> 107 | AV235: =SUMIFS(시도_소아과개폐업!$F$5:$F$293,시도_소아과개폐업!$A$5:$A$293,$D235,시도_소아과개폐업!$B$5:$B$293,$B235) -> 38 | AW235: =SUMIFS(시도_소아과개폐업!$G$5:$G$293,시도_소아과개폐업!$A$5:$A$293,$D235,시도_소아과개폐업!$B$5:$B$293,$B235) -> 0.20576923 | AX235: =SUMIFS(시도_소아과개폐업!$H$5:$H$293,시도_소아과개폐업!$A$5:$A$293,$D235,시도_소아과개폐업!$B$5:$B$293,$B235) -> 310 | AY235: =SUMIFS(시군구_병원급!$E$5:$E$3668,시군구_병원급!$A$5:$A$3668,$A235,시군구_병원급!$D$5:$D$3668,$D235) -> 2 | AZ235: =SUMIFS(시군구_병원급!$F$5:$F$3668,시군구_병원급!$A$5:$A$3668,$A235,시군구_병원급!$D$5:$D$3668,$D235) -> 2 | BA235: =SUMIFS(시군구_병원급!$G$5:$G$3668,시군구_병원급!$A$5:$A$3668,$A235,시군구_병원급!$D$5:$D$3668,$D235) -> 6 | BB235: =SUMIFS(시군구_병원급!$H$5:$H$3668,시군구_병원급!$A$5:$A$3668,$A235,시군구_병원급!$D$5:$D$3668,$D235) -> 11 | BC235: =K235+AY235 -> 22 | BD235: =IF(E235=0,"",(K235+AY235)/E235*1000) -> 1.5175554 | BE235: =AY235-SUMIFS(시군구_병원급!$E$5:$E$3668,시군구_병원급!$A$5:$A$3668,$A235,시군구_병원급!$D$5:$D$3668,$D235-3) -> 0 | BF235: =IF(AY235=0,1,0) -> 0 | BG235: =IF(K235+AY235=0,1,0) -> 0 | BH235: =AF235+AG235+AH235 -> 9 | BI235: =IF(H235=0,"",BH235/H235) -> 0.042056075 | BJ235: =IF(AP235="","",AP235+AN235) -> 32
A236: 11230 | B236: 서울특별시 | C236: 동대문구 | D236: 2017 | E236: 14097 | F236: 2007 | G236: 2117 | H236: 228 | I236: 9413 | J236: 8167 | K236: 17 | L236: 16.173654 | M236: 1.2059303 | N236: 0.86762987 | O236: 0.66773072 | P236: 0.1501738 | Q236: -0.13647779 | R236: -0.19627942 | S236: 1 | T236: -0.012987013 | U236: -0.015994146 | V236: 0 | W236: -0.11842105 | X236: 0 | Y236: 0 | Z236: 0 | AA236: 0 | AB236: 학습 | AC236: 55 | AD236: 69 | AE236: 92 | AF236: 9 | AG236: 3 | AH236: 0 | AI236: 0.24122807 | AJ236: 0.30263158 | AK236: 0.40350877 | AL236: 0.039473684 | AM236: 0.013157895 | AN236: 7 | AO236: 0.029787234 | AP236: 11 | AQ236: 6 | AR236: 0.045833333 | AS236: 0.025 | AT236: =SUMIFS(시도_소아과개폐업!$C$5:$C$293,시도_소아과개폐업!$A$5:$A$293,$D236,시도_소아과개폐업!$B$5:$B$293,$B236) -> 145 | AU236: =SUMIFS(시도_소아과개폐업!$D$5:$D$293,시도_소아과개폐업!$A$5:$A$293,$D236,시도_소아과개폐업!$B$5:$B$293,$B236) -> 107 | AV236: =SUMIFS(시도_소아과개폐업!$F$5:$F$293,시도_소아과개폐업!$A$5:$A$293,$D236,시도_소아과개폐업!$B$5:$B$293,$B236) -> 38 | AW236: =SUMIFS(시도_소아과개폐업!$G$5:$G$293,시도_소아과개폐업!$A$5:$A$293,$D236,시도_소아과개폐업!$B$5:$B$293,$B236) -> 0.20576923 | AX236: =SUMIFS(시도_소아과개폐업!$H$5:$H$293,시도_소아과개폐업!$A$5:$A$293,$D236,시도_소아과개폐업!$B$5:$B$293,$B236) -> 310 | AY236: =SUMIFS(시군구_병원급!$E$5:$E$3668,시군구_병원급!$A$5:$A$3668,$A236,시군구_병원급!$D$5:$D$3668,$D236) -> 8 | AZ236: =SUMIFS(시군구_병원급!$F$5:$F$3668,시군구_병원급!$A$5:$A$3668,$A236,시군구_병원급!$D$5:$D$3668,$D236) -> 5 | BA236: =SUMIFS(시군구_병원급!$G$5:$G$3668,시군구_병원급!$A$5:$A$3668,$A236,시군구_병원급!$D$5:$D$3668,$D236) -> 18 | BB236: =SUMIFS(시군구_병원급!$H$5:$H$3668,시군구_병원급!$A$5:$A$3668,$A236,시군구_병원급!$D$5:$D$3668,$D236) -> 33 | BC236: =K236+AY236 -> 25 | BD236: =IF(E236=0,"",(K236+AY236)/E236*1000) -> 1.773427 | BE236: =AY236-SUMIFS(시군구_병원급!$E$5:$E$3668,시군구_병원급!$A$5:$A$3668,$A236,시군구_병원급!$D$5:$D$3668,$D236-3) -> 0 | BF236: =IF(AY236=0,1,0) -> 0 | BG236: =IF(K236+AY236=0,1,0) -> 0 | BH236: =AF236+AG236+AH236 -> 12 | BI236: =IF(H236=0,"",BH236/H236) -> 0.052631579 | BJ236: =IF(AP236="","",AP236+AN236) -> 18
A237: 11260 | B237: 서울특별시 | C237: 중랑구 | D237: 2017 | E237: 17108 | F237: 2536 | G237: 2744 | H237: 252 | I237: 11862 | J237: 10466 | K237: 19 | L237: 14.729951 | M237: 1.1105915 | N237: 0.88231327 | O237: 0.69335983 | P237: 0.1603928 | Q237: -0.10236634 | R237: -0.16545012 | S237: 0 | T237: -0.030769231 | U237: -0.008691292 | V237: 0 | W237: -0.12698413 | X237: 0 | Y237: 0 | Z237: 0 | AA237: 0 | AB237: 학습 | AC237: 39 | AD237: 101 | AE237: 105 | AF237: 2 | AG237: 5 | AH237: 0 | AI237: 0.1547619 | AJ237: 0.40079365 | AK237: 0.41666667 | AL237: 0.0079365079 | AM237: 0.01984127 | AN237: 3 | AO237: 0.011764706 | AP237: 14 | AQ237: 6 | AR237: 0.053231939 | AS237: 0.022813688 | AT237: =SUMIFS(시도_소아과개폐업!$C$5:$C$293,시도_소아과개폐업!$A$5:$A$293,$D237,시도_소아과개폐업!$B$5:$B$293,$B237) -> 145 | AU237: =SUMIFS(시도_소아과개폐업!$D$5:$D$293,시도_소아과개폐업!$A$5:$A$293,$D237,시도_소아과개폐업!$B$5:$B$293,$B237) -> 107 | AV237: =SUMIFS(시도_소아과개폐업!$F$5:$F$293,시도_소아과개폐업!$A$5:$A$293,$D237,시도_소아과개폐업!$B$5:$B$293,$B237) -> 38 | AW237: =SUMIFS(시도_소아과개폐업!$G$5:$G$293,시도_소아과개폐업!$A$5:$A$293,$D237,시도_소아과개폐업!$B$5:$B$293,$B237) -> 0.20576923 | AX237: =SUMIFS(시도_소아과개폐업!$H$5:$H$293,시도_소아과개폐업!$A$5:$A$293,$D237,시도_소아과개폐업!$B$5:$B$293,$B237) -> 310 | AY237: =SUMIFS(시군구_병원급!$E$5:$E$3668,시군구_병원급!$A$5:$A$3668,$A237,시군구_병원급!$D$5:$D$3668,$D237) -> 6 | AZ237: =SUMIFS(시군구_병원급!$F$5:$F$3668,시군구_병원급!$A$5:$A$3668,$A237,시군구_병원급!$D$5:$D$3668,$D237) -> 3 | BA237: =SUMIFS(시군구_병원급!$G$5:$G$3668,시군구_병원급!$A$5:$A$3668,$A237,시군구_병원급!$D$5:$D$3668,$D237) -> 15 | BB237: =SUMIFS(시군구_병원급!$H$5:$H$3668,시군구_병원급!$A$5:$A$3668,$A237,시군구_병원급!$D$5:$D$3668,$D237) -> 18 | BC237: =K237+AY237 -> 25 | BD237: =IF(E237=0,"",(K237+AY237)/E237*1000) -> 1.4613047 | BE237: =AY237-SUMIFS(시군구_병원급!$E$5:$E$3668,시군구_병원급!$A$5:$A$3668,$A237,시군구_병원급!$D$5:$D$3668,$D237-3) -> 0 | BF237: =IF(AY237=0,1,0) -> 0 | BG237: =IF(K237+AY237=0,1,0) -> 0 | BH237: =AF237+AG237+AH237 -> 7 | BI237: =IF(H237=0,"",BH237/H237) -> 0.027777778 | BJ237: =IF(AP237="","",AP237+AN237) -> 17
A238: 11290 | B238: 서울특별시 | C238: 성북구 | D238: 2017 | E238: 19082 | F238: 2508 | G238: 2631 | H238: 298 | I238: 11648 | J238: 10050 | K238: 19 | L238: 15.616812 | M238: 0.99570276 | N238: 0.86280907 | O238: 0.6104182 | P238: 0.13787863 | Q238: -0.14774453 | R238: -0.25614928 | S238: -5 | T238: -0.038709677 | U238: -0.031995346 | V238: 0 | W238: -0.17449664 | X238: 0 | Y238: 0 | Z238: 0 | AA238: 0 | AB238: 학습 | AC238: 66 | AD238: 95 | AE238: 110 | AF238: 6 | AG238: 20 | AH238: 1 | AI238: 0.22147651 | AJ238: 0.31879195 | AK238: 0.36912752 | AL238: 0.020134228 | AM238: 0.067114094 | AN238: 6 | AO238: 0.019736842 | AP238: 28 | AQ238: 17 | AR238: 0.088607595 | AS238: 0.053797468 | AT238: =SUMIFS(시도_소아과개폐업!$C$5:$C$293,시도_소아과개폐업!$A$5:$A$293,$D238,시도_소아과개폐업!$B$5:$B$293,$B238) -> 145 | AU238: =SUMIFS(시도_소아과개폐업!$D$5:$D$293,시도_소아과개폐업!$A$5:$A$293,$D238,시도_소아과개폐업!$B$5:$B$293,$B238) -> 107 | AV238: =SUMIFS(시도_소아과개폐업!$F$5:$F$293,시도_소아과개폐업!$A$5:$A$293,$D238,시도_소아과개폐업!$B$5:$B$293,$B238) -> 38 | AW238: =SUMIFS(시도_소아과개폐업!$G$5:$G$293,시도_소아과개폐업!$A$5:$A$293,$D238,시도_소아과개폐업!$B$5:$B$293,$B238) -> 0.20576923 | AX238: =SUMIFS(시도_소아과개폐업!$H$5:$H$293,시도_소아과개폐업!$A$5:$A$293,$D238,시도_소아과개폐업!$B$5:$B$293,$B238) -> 310 | AY238: =SUMIFS(시군구_병원급!$E$5:$E$3668,시군구_병원급!$A$5:$A$3668,$A238,시군구_병원급!$D$5:$D$3668,$D238) -> 5 | AZ238: =SUMIFS(시군구_병원급!$F$5:$F$3668,시군구_병원급!$A$5:$A$3668,$A238,시군구_병원급!$D$5:$D$3668,$D238) -> 1 | BA238: =SUMIFS(시군구_병원급!$G$5:$G$3668,시군구_병원급!$A$5:$A$3668,$A238,시군구_병원급!$D$5:$D$3668,$D238) -> 7 | BB238: =SUMIFS(시군구_병원급!$H$5:$H$3668,시군구_병원급!$A$5:$A$3668,$A238,시군구_병원급!$D$5:$D$3668,$D238) -> 14 | BC238: =K238+AY238 -> 24 | BD238: =IF(E238=0,"",(K238+AY238)/E238*1000) -> 1.2577298 | BE238: =AY238-SUMIFS(시군구_병원급!$E$5:$E$3668,시군구_병원급!$A$5:$A$3668,$A238,시군구_병원급!$D$5:$D$3668,$D238-3) -> 1 | BF238: =IF(AY238=0,1,0) -> 0 | BG238: =IF(K238+AY238=0,1,0) -> 0 | BH238: =AF238+AG238+AH238 -> 27 | BI238: =IF(H238=0,"",BH238/H238) -> 0.090604027 | BJ238: =IF(AP238="","",AP238+AN238) -> 34
A239: 11305 | B239: 서울특별시 | C239: 강북구 | D239: 2017 | E239: 11867 | F239: 1677 | G239: 1772 | H239: 174 | I239: 8817 | J239: 7635 | K239: 12 | L239: 14.662509 | M239: 1.0112076 | N239: 0.8659408 | O239: 0.74298475 | P239: 0.14932165 | Q239: -0.17773004 | R239: -0.24915254 | S239: -1 | T239: -0.043956044 | U239: -0.022180326 | V239: 0 | W239: -0.17241379 | X239: 0 | Y239: 0 | Z239: 0 | AA239: 0 | AB239: 학습 | AC239: 46 | AD239: 72 | AE239: 49 | AF239: 2 | AG239: 4 | AH239: 1 | AI239: 0.26436782 | AJ239: 0.4137931 | AK239: 0.2816092 | AL239: 0.011494253 | AM239: 0.022988506 | AN239: 2 | AO239: 0.011363636 | AP239: 26 | AQ239: 12 | AR239: 0.13684211 | AS239: 0.063157895 | AT239: =SUMIFS(시도_소아과개폐업!$C$5:$C$293,시도_소아과개폐업!$A$5:$A$293,$D239,시도_소아과개폐업!$B$5:$B$293,$B239) -> 145 | AU239: =SUMIFS(시도_소아과개폐업!$D$5:$D$293,시도_소아과개폐업!$A$5:$A$293,$D239,시도_소아과개폐업!$B$5:$B$293,$B239) -> 107 | AV239: =SUMIFS(시도_소아과개폐업!$F$5:$F$293,시도_소아과개폐업!$A$5:$A$293,$D239,시도_소아과개폐업!$B$5:$B$293,$B239) -> 38 | AW239: =SUMIFS(시도_소아과개폐업!$G$5:$G$293,시도_소아과개폐업!$A$5:$A$293,$D239,시도_소아과개폐업!$B$5:$B$293,$B239) -> 0.20576923 | AX239: =SUMIFS(시도_소아과개폐업!$H$5:$H$293,시도_소아과개폐업!$A$5:$A$293,$D239,시도_소아과개폐업!$B$5:$B$293,$B239) -> 310 | AY239: =SUMIFS(시군구_병원급!$E$5:$E$3668,시군구_병원급!$A$5:$A$3668,$A239,시군구_병원급!$D$5:$D$3668,$D239) -> 2 | AZ239: =SUMIFS(시군구_병원급!$F$5:$F$3668,시군구_병원급!$A$5:$A$3668,$A239,시군구_병원급!$D$5:$D$3668,$D239) -> 2 | BA239: =SUMIFS(시군구_병원급!$G$5:$G$3668,시군구_병원급!$A$5:$A$3668,$A239,시군구_병원급!$D$5:$D$3668,$D239) -> 10 | BB239: =SUMIFS(시군구_병원급!$H$5:$H$3668,시군구_병원급!$A$5:$A$3668,$A239,시군구_병원급!$D$5:$D$3668,$D239) -> 15 | BC239: =K239+AY239 -> 14 | BD239: =IF(E239=0,"",(K239+AY239)/E239*1000) -> 1.1797421 | BE239: =AY239-SUMIFS(시군구_병원급!$E$5:$E$3668,시군구_병원급!$A$5:$A$3668,$A239,시군구_병원급!$D$5:$D$3668,$D239-3) -> 0 | BF239: =IF(AY239=0,1,0) -> 0 | BG239: =IF(K239+AY239=0,1,0) -> 0 | BH239: =AF239+AG239+AH239 -> 7 | BI239: =IF(H239=0,"",BH239/H239) -> 0.040229885 | BJ239: =IF(AP239="","",AP239+AN239) -> 28
A240: 11320 | B240: 서울특별시 | C240: 도봉구 | D240: 2017 | E240: 13649 | F240: 1816 | G240: 1906 | H240: 255 | I240: 10297 | J240: 8795 | K240: 17 | L240: 18.682687 | M240: 1.2455125 | N240: 0.85413227 | O240: 0.75441424 | P240: 0.13964393 | Q240: -0.12528839 | R240: -0.25342734 | S240: 1 | T240: -0.037735849 | U240: -0.023333017 | V240: 0 | W240: -0.17647059 | X240: 0 | Y240: 0 | Z240: 0 | AA240: 0 | AB240: 학습 | AC240: 42 | AD240: 77 | AE240: 129 | AF240: 2 | AG240: 3 | AH240: 2 | AI240: 0.16470588 | AJ240: 0.30196078 | AK240: 0.50588235 | AL240: 0.0078431373 | AM240: 0.011764706 | AN240: 13 | AO240: 0.048507463 | AP240: 22 | AQ240: 12 | AR240: 0.079136691 | AS240: 0.043165468 | AT240: =SUMIFS(시도_소아과개폐업!$C$5:$C$293,시도_소아과개폐업!$A$5:$A$293,$D240,시도_소아과개폐업!$B$5:$B$293,$B240) -> 145 | AU240: =SUMIFS(시도_소아과개폐업!$D$5:$D$293,시도_소아과개폐업!$A$5:$A$293,$D240,시도_소아과개폐업!$B$5:$B$293,$B240) -> 107 | AV240: =SUMIFS(시도_소아과개폐업!$F$5:$F$293,시도_소아과개폐업!$A$5:$A$293,$D240,시도_소아과개폐업!$B$5:$B$293,$B240) -> 38 | AW240: =SUMIFS(시도_소아과개폐업!$G$5:$G$293,시도_소아과개폐업!$A$5:$A$293,$D240,시도_소아과개폐업!$B$5:$B$293,$B240) -> 0.20576923 | AX240: =SUMIFS(시도_소아과개폐업!$H$5:$H$293,시도_소아과개폐업!$A$5:$A$293,$D240,시도_소아과개폐업!$B$5:$B$293,$B240) -> 310 | AY240: =SUMIFS(시군구_병원급!$E$5:$E$3668,시군구_병원급!$A$5:$A$3668,$A240,시군구_병원급!$D$5:$D$3668,$D240) -> 3 | AZ240: =SUMIFS(시군구_병원급!$F$5:$F$3668,시군구_병원급!$A$5:$A$3668,$A240,시군구_병원급!$D$5:$D$3668,$D240) -> 1 | BA240: =SUMIFS(시군구_병원급!$G$5:$G$3668,시군구_병원급!$A$5:$A$3668,$A240,시군구_병원급!$D$5:$D$3668,$D240) -> 6 | BB240: =SUMIFS(시군구_병원급!$H$5:$H$3668,시군구_병원급!$A$5:$A$3668,$A240,시군구_병원급!$D$5:$D$3668,$D240) -> 20 | BC240: =K240+AY240 -> 20 | BD240: =IF(E240=0,"",(K240+AY240)/E240*1000) -> 1.4653088 | BE240: =AY240-SUMIFS(시군구_병원급!$E$5:$E$3668,시군구_병원급!$A$5:$A$3668,$A240,시군구_병원급!$D$5:$D$3668,$D240-3) -> 0 | BF240: =IF(AY240=0,1,0) -> 0 | BG240: =IF(K240+AY240=0,1,0) -> 0 | BH240: =AF240+AG240+AH240 -> 7 | BI240: =IF(H240=0,"",BH240/H240) -> 0.02745098 | BJ240: =IF(AP240="","",AP240+AN240) -> 35
A241: 11350 | B241: 서울특별시 | C241: 노원구 | D241: 2017 | E241: 23386 | F241: 3245 | G241: 3494 | H241: 478 | I241: 14186 | J241: 12483 | K241: 34 | L241: 20.439579 | M241: 1.4538613 | N241: 0.87995207 | O241: 0.60660224 | P241: 0.14940563 | Q241: -0.12794123 | R241: -0.25896076 | S241: -1 | T241: -0.032388664 | U241: -0.017317817 | V241: 0 | W241: -0.23849372 | X241: 1 | Y241: 0 | Z241: 1 | AA241: 0 | AB241: 학습 | AC241: 57 | AD241: 78 | AE241: 330 | AF241: 7 | AG241: 5 | AH241: 1 | AI241: 0.11924686 | AJ241: 0.16317992 | AK241: 0.69037657 | AL241: 0.014644351 | AM241: 0.010460251 | AN241: 19 | AO241: 0.038229376 | AP241: 35 | AQ241: 14 | AR241: 0.067567568 | AS241: 0.027027027 | AT241: =SUMIFS(시도_소아과개폐업!$C$5:$C$293,시도_소아과개폐업!$A$5:$A$293,$D241,시도_소아과개폐업!$B$5:$B$293,$B241) -> 145 | AU241: =SUMIFS(시도_소아과개폐업!$D$5:$D$293,시도_소아과개폐업!$A$5:$A$293,$D241,시도_소아과개폐업!$B$5:$B$293,$B241) -> 107 | AV241: =SUMIFS(시도_소아과개폐업!$F$5:$F$293,시도_소아과개폐업!$A$5:$A$293,$D241,시도_소아과개폐업!$B$5:$B$293,$B241) -> 38 | AW241: =SUMIFS(시도_소아과개폐업!$G$5:$G$293,시도_소아과개폐업!$A$5:$A$293,$D241,시도_소아과개폐업!$B$5:$B$293,$B241) -> 0.20576923 | AX241: =SUMIFS(시도_소아과개폐업!$H$5:$H$293,시도_소아과개폐업!$A$5:$A$293,$D241,시도_소아과개폐업!$B$5:$B$293,$B241) -> 310 | AY241: =SUMIFS(시군구_병원급!$E$5:$E$3668,시군구_병원급!$A$5:$A$3668,$A241,시군구_병원급!$D$5:$D$3668,$D241) -> 8 | AZ241: =SUMIFS(시군구_병원급!$F$5:$F$3668,시군구_병원급!$A$5:$A$3668,$A241,시군구_병원급!$D$5:$D$3668,$D241) -> 3 | BA241: =SUMIFS(시군구_병원급!$G$5:$G$3668,시군구_병원급!$A$5:$A$3668,$A241,시군구_병원급!$D$5:$D$3668,$D241) -> 10 | BB241: =SUMIFS(시군구_병원급!$H$5:$H$3668,시군구_병원급!$A$5:$A$3668,$A241,시군구_병원급!$D$5:$D$3668,$D241) -> 22 | BC241: =K241+AY241 -> 42 | BD241: =IF(E241=0,"",(K241+AY241)/E241*1000) -> 1.7959463 | BE241: =AY241-SUMIFS(시군구_병원급!$E$5:$E$3668,시군구_병원급!$A$5:$A$3668,$A241,시군구_병원급!$D$5:$D$3668,$D241-3) -> 0 | BF241: =IF(AY241=0,1,0) -> 0 | BG241: =IF(K241+AY241=0,1,0) -> 0 | BH241: =AF241+AG241+AH241 -> 13 | BI241: =IF(H241=0,"",BH241/H241) -> 0.027196653 | BJ241: =IF(AP241="","",AP241+AN241) -> 54
A242: 11380 | B242: 서울특별시 | C242: 은평구 | D242: 2017 | E242: 20553 | F242: 2793 | G242: 2930 | H242: 294 | I242: 14306 | J242: 12236 | K242: 27 | L242: 14.304481 | M242: 1.3136768 | N242: 0.85530547 | O242: 0.6960541 | P242: 0.14255826 | Q242: -0.14940198 | R242: -0.28274174 | S242: -1 | T242: -0.063694268 | U242: -0.046393814 | V242: 0 | W242: -0.16326531 | X242: 0 | Y242: 0 | Z242: 0 | AA242: 0 | AB242: 학습 | AC242: 41 | AD242: 158 | AE242: 84 | AF242: 2 | AG242: 8 | AH242: 1 | AI242: 0.13945578 | AJ242: 0.53741497 | AK242: 0.28571429 | AL242: 0.0068027211 | AM242: 0.027210884 | AN242: 3 | AO242: 0.01010101 | AP242: 30 | AQ242: 10 | AR242: 0.094637224 | AS242: 0.031545741 | AT242: =SUMIFS(시도_소아과개폐업!$C$5:$C$293,시도_소아과개폐업!$A$5:$A$293,$D242,시도_소아과개폐업!$B$5:$B$293,$B242) -> 145 | AU242: =SUMIFS(시도_소아과개폐업!$D$5:$D$293,시도_소아과개폐업!$A$5:$A$293,$D242,시도_소아과개폐업!$B$5:$B$293,$B242) -> 107 | AV242: =SUMIFS(시도_소아과개폐업!$F$5:$F$293,시도_소아과개폐업!$A$5:$A$293,$D242,시도_소아과개폐업!$B$5:$B$293,$B242) -> 38 | AW242: =SUMIFS(시도_소아과개폐업!$G$5:$G$293,시도_소아과개폐업!$A$5:$A$293,$D242,시도_소아과개폐업!$B$5:$B$293,$B242) -> 0.20576923 | AX242: =SUMIFS(시도_소아과개폐업!$H$5:$H$293,시도_소아과개폐업!$A$5:$A$293,$D242,시도_소아과개폐업!$B$5:$B$293,$B242) -> 310 | AY242: =SUMIFS(시군구_병원급!$E$5:$E$3668,시군구_병원급!$A$5:$A$3668,$A242,시군구_병원급!$D$5:$D$3668,$D242) -> 8 | AZ242: =SUMIFS(시군구_병원급!$F$5:$F$3668,시군구_병원급!$A$5:$A$3668,$A242,시군구_병원급!$D$5:$D$3668,$D242) -> 2 | BA242: =SUMIFS(시군구_병원급!$G$5:$G$3668,시군구_병원급!$A$5:$A$3668,$A242,시군구_병원급!$D$5:$D$3668,$D242) -> 12 | BB242: =SUMIFS(시군구_병원급!$H$5:$H$3668,시군구_병원급!$A$5:$A$3668,$A242,시군구_병원급!$D$5:$D$3668,$D242) -> 22 | BC242: =K242+AY242 -> 35 | BD242: =IF(E242=0,"",(K242+AY242)/E242*1000) -> 1.7029144 | BE242: =AY242-SUMIFS(시군구_병원급!$E$5:$E$3668,시군구_병원급!$A$5:$A$3668,$A242,시군구_병원급!$D$5:$D$3668,$D242-3) -> -2 | BF242: =IF(AY242=0,1,0) -> 0 | BG242: =IF(K242+AY242=0,1,0) -> 0 | BH242: =AF242+AG242+AH242 -> 11 | BI242: =IF(H242=0,"",BH242/H242) -> 0.037414966 | BJ242: =IF(AP242="","",AP242+AN242) -> 33
... A1604: 52800 | B1604: 전북특별자치도 | C1604: 부안군 | D1604: 2022 | E1604: 1046 | F1604: 139 | G1604: 138 | H1604: 17 | I1604: 911 | J1604: 622 | K1604: 1 | L1604: 16.25239 | M1604: 0.95602294 | N1604: 0.68276619 | O1604: 0.8709369 | P1604: 0.13193117 | Q1604: -0.28988459 | R1604: -0.38938053 | S1604: 0 | T1604: -0.10526316 | U1604: -0.098911968 | V1604: 0 | W1604: 0 | X1604: 0 | Y1604: 0 | Z1604: 0 | AA1604: 0 | AB1604: 검증 | AC1604: 3 | AD1604: 8 | AE1604: 3 | AF1604: 1 | AG1604: 2 | AH1604: 0 | AI1604: 0.17647059 | AJ1604: 0.47058824 | AK1604: 0.17647059 | AL1604: 0.058823529 | AM1604: 0.11764706 | AN1604: 4 | AO1604: 0.19047619 | AP1604: 1 | AQ1604: 0 | AR1604: 0.045454545 | AS1604: 0 | AT1604: =SUMIFS(시도_소아과개폐업!$C$5:$C$293,시도_소아과개폐업!$A$5:$A$293,$D1604,시도_소아과개폐업!$B$5:$B$293,$B1604) -> 15 | AU1604: =SUMIFS(시도_소아과개폐업!$D$5:$D$293,시도_소아과개폐업!$A$5:$A$293,$D1604,시도_소아과개폐업!$B$5:$B$293,$B1604) -> 10 | AV1604: =SUMIFS(시도_소아과개폐업!$F$5:$F$293,시도_소아과개폐업!$A$5:$A$293,$D1604,시도_소아과개폐업!$B$5:$B$293,$B1604) -> 5 | AW1604: =SUMIFS(시도_소아과개폐업!$G$5:$G$293,시도_소아과개폐업!$A$5:$A$293,$D1604,시도_소아과개폐업!$B$5:$B$293,$B1604) -> 0.15384615 | AX1604: =SUMIFS(시도_소아과개폐업!$H$5:$H$293,시도_소아과개폐업!$A$5:$A$293,$D1604,시도_소아과개폐업!$B$5:$B$293,$B1604) -> 38 | AY1604: =SUMIFS(시군구_병원급!$E$5:$E$3668,시군구_병원급!$A$5:$A$3668,$A1604,시군구_병원급!$D$5:$D$3668,$D1604) -> 0 | AZ1604: =SUMIFS(시군구_병원급!$F$5:$F$3668,시군구_병원급!$A$5:$A$3668,$A1604,시군구_병원급!$D$5:$D$3668,$D1604) -> 1 | BA1604: =SUMIFS(시군구_병원급!$G$5:$G$3668,시군구_병원급!$A$5:$A$3668,$A1604,시군구_병원급!$D$5:$D$3668,$D1604) -> 5 | BB1604: =SUMIFS(시군구_병원급!$H$5:$H$3668,시군구_병원급!$A$5:$A$3668,$A1604,시군구_병원급!$D$5:$D$3668,$D1604) -> 8 | BC1604: =K1604+AY1604 -> 1 | BD1604: =IF(E1604=0,"",(K1604+AY1604)/E1604*1000) -> 0.95602294 | BE1604: =AY1604-SUMIFS(시군구_병원급!$E$5:$E$3668,시군구_병원급!$A$5:$A$3668,$A1604,시군구_병원급!$D$5:$D$3668,$D1604-3) -> 0 | BF1604: =IF(AY1604=0,1,0) -> 1 | BG1604: =IF(K1604+AY1604=0,1,0) -> 0 | BH1604: =AF1604+AG1604+AH1604 -> 3 | BI1604: =IF(H1604=0,"",BH1604/H1604) -> 0.17647059 | BJ1604: =IF(AP1604="","",AP1604+AN1604) -> 5
A1605: 11110 | B1605: 서울특별시 | C1605: 종로구 | D1605: 2023 | E1605: 2894 | F1605: 390 | G1605: 396 | H1605: 66 | I1605: 4183 | J1605: 2466 | K1605: 4 | L1605: 22.805805 | M1605: 1.38217 | N1605: 0.58952905 | O1605: 1.4454043 | P1605: 0.13683483 | Q1605: -0.26229926 | R1605: -0.25141777 | S1605: 0 | T1605: -0.070422535 | U1605: -0.051258789 | V1605: 0 | AB1605: 예측(라벨 없음) | AC1605: 30 | AD1605: 4 | AE1605: 2 | AF1605: 28 | AG1605: 2 | AH1605: 0 | AI1605: 0.45454545 | AJ1605: 0.060606061 | AK1605: 0.03030303 | AL1605: 0.42424242 | AM1605: 0.03030303 | AN1605: 0 | AO1605: 0 | AP1605: 5 | AQ1605: 0 | AR1605: 0.070422535 | AS1605: 0 | AT1605: =SUMIFS(시도_소아과개폐업!$C$5:$C$293,시도_소아과개폐업!$A$5:$A$293,$D1605,시도_소아과개폐업!$B$5:$B$293,$B1605) -> 88 | AU1605: =SUMIFS(시도_소아과개폐업!$D$5:$D$293,시도_소아과개폐업!$A$5:$A$293,$D1605,시도_소아과개폐업!$B$5:$B$293,$B1605) -> 66 | AV1605: =SUMIFS(시도_소아과개폐업!$F$5:$F$293,시도_소아과개폐업!$A$5:$A$293,$D1605,시도_소아과개폐업!$B$5:$B$293,$B1605) -> 22 | AW1605: =SUMIFS(시도_소아과개폐업!$G$5:$G$293,시도_소아과개폐업!$A$5:$A$293,$D1605,시도_소아과개폐업!$B$5:$B$293,$B1605) -> 0.14473684 | AX1605: =SUMIFS(시도_소아과개폐업!$H$5:$H$293,시도_소아과개폐업!$A$5:$A$293,$D1605,시도_소아과개폐업!$B$5:$B$293,$B1605) -> 239 | AY1605: =SUMIFS(시군구_병원급!$E$5:$E$3668,시군구_병원급!$A$5:$A$3668,$A1605,시군구_병원급!$D$5:$D$3668,$D1605) -> 6 | AZ1605: =SUMIFS(시군구_병원급!$F$5:$F$3668,시군구_병원급!$A$5:$A$3668,$A1605,시군구_병원급!$D$5:$D$3668,$D1605) -> 4 | BA1605: =SUMIFS(시군구_병원급!$G$5:$G$3668,시군구_병원급!$A$5:$A$3668,$A1605,시군구_병원급!$D$5:$D$3668,$D1605) -> 7 | BB1605: =SUMIFS(시군구_병원급!$H$5:$H$3668,시군구_병원급!$A$5:$A$3668,$A1605,시군구_병원급!$D$5:$D$3668,$D1605) -> 11 | BC1605: =K1605+AY1605 -> 10 | BD1605: =IF(E1605=0,"",(K1605+AY1605)/E1605*1000) -> 3.455425 | BE1605: =AY1605-SUMIFS(시군구_병원급!$E$5:$E$3668,시군구_병원급!$A$5:$A$3668,$A1605,시군구_병원급!$D$5:$D$3668,$D1605-3) -> 0 | BF1605: =IF(AY1605=0,1,0) -> 0 | BG1605: =IF(K1605+AY1605=0,1,0) -> 0 | BH1605: =AF1605+AG1605+AH1605 -> 30 | BI1605: =IF(H1605=0,"",BH1605/H1605) -> 0.45454545 | BJ1605: =IF(AP1605="","",AP1605+AN1605) -> 5
A1606: 11140 | B1606: 서울특별시 | C1606: 중구 | D1606: 2023 | E1606: 3211 | F1606: 472 | G1606: 534 | H1606: 66 | I1606: 4158 | J1606: 2703 | K1606: 5 | L1606: 20.554344 | M1606: 1.5571473 | N1606: 0.65007215 | O1606: 1.2949237 | P1606: 0.16630333 | Q1606: -0.19925187 | R1606: -0.22608696 | S1606: 0 | T1606: 0.03125 | U1606: 0.0097134531 | V1606: 0 | AB1606: 예측(라벨 없음) | AC1606: 24 | AD1606: 3 | AE1606: 9 | AF1606: 24 | AG1606: 6 | AH1606: 0 | AI1606: 0.36363636 | AJ1606: 0.045454545 | AK1606: 0.13636364 | AL1606: 0.36363636 | AM1606: 0.090909091 | AN1606: 2 | AO1606: 0.029411765 | AP1606: 0 | AQ1606: 2 | AR1606: 0 | AS1606: 0.03030303 | AT1606: =SUMIFS(시도_소아과개폐업!$C$5:$C$293,시도_소아과개폐업!$A$5:$A$293,$D1606,시도_소아과개폐업!$B$5:$B$293,$B1606) -> 88 | AU1606: =SUMIFS(시도_소아과개폐업!$D$5:$D$293,시도_소아과개폐업!$A$5:$A$293,$D1606,시도_소아과개폐업!$B$5:$B$293,$B1606) -> 66 | AV1606: =SUMIFS(시도_소아과개폐업!$F$5:$F$293,시도_소아과개폐업!$A$5:$A$293,$D1606,시도_소아과개폐업!$B$5:$B$293,$B1606) -> 22 | AW1606: =SUMIFS(시도_소아과개폐업!$G$5:$G$293,시도_소아과개폐업!$A$5:$A$293,$D1606,시도_소아과개폐업!$B$5:$B$293,$B1606) -> 0.14473684 | AX1606: =SUMIFS(시도_소아과개폐업!$H$5:$H$293,시도_소아과개폐업!$A$5:$A$293,$D1606,시도_소아과개폐업!$B$5:$B$293,$B1606) -> 239 | AY1606: =SUMIFS(시군구_병원급!$E$5:$E$3668,시군구_병원급!$A$5:$A$3668,$A1606,시군구_병원급!$D$5:$D$3668,$D1606) -> 2 | AZ1606: =SUMIFS(시군구_병원급!$F$5:$F$3668,시군구_병원급!$A$5:$A$3668,$A1606,시군구_병원급!$D$5:$D$3668,$D1606) -> 1 | BA1606: =SUMIFS(시군구_병원급!$G$5:$G$3668,시군구_병원급!$A$5:$A$3668,$A1606,시군구_병원급!$D$5:$D$3668,$D1606) -> 4 | BB1606: =SUMIFS(시군구_병원급!$H$5:$H$3668,시군구_병원급!$A$5:$A$3668,$A1606,시군구_병원급!$D$5:$D$3668,$D1606) -> 10 | BC1606: =K1606+AY1606 -> 7 | BD1606: =IF(E1606=0,"",(K1606+AY1606)/E1606*1000) -> 2.1800062 | BE1606: =AY1606-SUMIFS(시군구_병원급!$E$5:$E$3668,시군구_병원급!$A$5:$A$3668,$A1606,시군구_병원급!$D$5:$D$3668,$D1606-3) -> -2 | BF1606: =IF(AY1606=0,1,0) -> 0 | BG1606: =IF(K1606+AY1606=0,1,0) -> 0 | BH1606: =AF1606+AG1606+AH1606 -> 30 | BI1606: =IF(H1606=0,"",BH1606/H1606) -> 0.45454545 | BJ1606: =IF(AP1606="","",AP1606+AN1606) -> 2
A1607: 11170 | B1607: 서울특별시 | C1607: 용산구 | D1607: 2023 | E1607: 6178 | F1607: 927 | G1607: 1012 | H1607: 100 | I1607: 4759 | J1607: 3472 | K1607: 9 | L1607: 16.186468 | M1607: 1.4567821 | N1607: 0.72956503 | O1607: 0.77031402 | P1607: 0.16380706 | Q1607: -0.20499292 | R1607: -0.13945578 | S1607: 0 | T1607: -0.056603774 | U1607: -0.04495284 | V1607: 0 | AB1607: 예측(라벨 없음) | AC1607: 36 | AD1607: 15 | AE1607: 28 | AF1607: 12 | AG1607: 9 | AH1607: 0 | AI1607: 0.36 | AJ1607: 0.15 | AK1607: 0.28 | AL1607: 0.12 | AM1607: 0.09 | AN1607: 0 | AO1607: 0 | AP1607: 7 | AQ1607: 1 | AR1607: 0.066037736 | AS1607: 0.0094339623 | AT1607: =SUMIFS(시도_소아과개폐업!$C$5:$C$293,시도_소아과개폐업!$A$5:$A$293,$D1607,시도_소아과개폐업!$B$5:$B$293,$B1607) -> 88 | AU1607: =SUMIFS(시도_소아과개폐업!$D$5:$D$293,시도_소아과개폐업!$A$5:$A$293,$D1607,시도_소아과개폐업!$B$5:$B$293,$B1607) -> 66 | AV1607: =SUMIFS(시도_소아과개폐업!$F$5:$F$293,시도_소아과개폐업!$A$5:$A$293,$D1607,시도_소아과개폐업!$B$5:$B$293,$B1607) -> 22 | AW1607: =SUMIFS(시도_소아과개폐업!$G$5:$G$293,시도_소아과개폐업!$A$5:$A$293,$D1607,시도_소아과개폐업!$B$5:$B$293,$B1607) -> 0.14473684 | AX1607: =SUMIFS(시도_소아과개폐업!$H$5:$H$293,시도_소아과개폐업!$A$5:$A$293,$D1607,시도_소아과개폐업!$B$5:$B$293,$B1607) -> 239 | AY1607: =SUMIFS(시군구_병원급!$E$5:$E$3668,시군구_병원급!$A$5:$A$3668,$A1607,시군구_병원급!$D$5:$D$3668,$D1607) -> 1 | AZ1607: =SUMIFS(시군구_병원급!$F$5:$F$3668,시군구_병원급!$A$5:$A$3668,$A1607,시군구_병원급!$D$5:$D$3668,$D1607) -> 1 | BA1607: =SUMIFS(시군구_병원급!$G$5:$G$3668,시군구_병원급!$A$5:$A$3668,$A1607,시군구_병원급!$D$5:$D$3668,$D1607) -> 2 | BB1607: =SUMIFS(시군구_병원급!$H$5:$H$3668,시군구_병원급!$A$5:$A$3668,$A1607,시군구_병원급!$D$5:$D$3668,$D1607) -> 2 | BC1607: =K1607+AY1607 -> 10 | BD1607: =IF(E1607=0,"",(K1607+AY1607)/E1607*1000) -> 1.6186468 | BE1607: =AY1607-SUMIFS(시군구_병원급!$E$5:$E$3668,시군구_병원급!$A$5:$A$3668,$A1607,시군구_병원급!$D$5:$D$3668,$D1607-3) -> -1 | BF1607: =IF(AY1607=0,1,0) -> 0 | BG1607: =IF(K1607+AY1607=0,1,0) -> 0 | BH1607: =AF1607+AG1607+AH1607 -> 21 | BI1607: =IF(H1607=0,"",BH1607/H1607) -> 0.21 | BJ1607: =IF(AP1607="","",AP1607+AN1607) -> 7
A1608: 11200 | B1608: 서울특별시 | C1608: 성동구 | D1608: 2023 | E1608: 9592 | F1608: 1409 | G1608: 1483 | H1608: 146 | I1608: 6952 | J1608: 4829 | K1608: 20 | L1608: 15.221018 | M1608: 2.0850709 | N1608: 0.69462025 | O1608: 0.72477064 | P1608: 0.15460801 | Q1608: -0.21933751 | R1608: -0.23753213 | S1608: -2 | T1608: -0.033112583 | U1608: -0.048323066 | V1608: 0 | AB1608: 예측(라벨 없음) | AC1608: 81 | AD1608: 16 | AE1608: 40 | AF1608: 7 | AG1608: 2 | AH1608: 0 | AI1608: 0.55479452 | AJ1608: 0.10958904 | AK1608: 0.2739726 | AL1608: 0.047945205 | AM1608: 0.01369863 | AN1608: 3 | AO1608: 0.020134228 | AP1608: 5 | AQ1608: 0 | AR1608: 0.032467532 | AS1608: 0 | AT1608: =SUMIFS(시도_소아과개폐업!$C$5:$C$293,시도_소아과개폐업!$A$5:$A$293,$D1608,시도_소아과개폐업!$B$5:$B$293,$B1608) -> 88 | AU1608: =SUMIFS(시도_소아과개폐업!$D$5:$D$293,시도_소아과개폐업!$A$5:$A$293,$D1608,시도_소아과개폐업!$B$5:$B$293,$B1608) -> 66 | AV1608: =SUMIFS(시도_소아과개폐업!$F$5:$F$293,시도_소아과개폐업!$A$5:$A$293,$D1608,시도_소아과개폐업!$B$5:$B$293,$B1608) -> 22 | AW1608: =SUMIFS(시도_소아과개폐업!$G$5:$G$293,시도_소아과개폐업!$A$5:$A$293,$D1608,시도_소아과개폐업!$B$5:$B$293,$B1608) -> 0.14473684 | AX1608: =SUMIFS(시도_소아과개폐업!$H$5:$H$293,시도_소아과개폐업!$A$5:$A$293,$D1608,시도_소아과개폐업!$B$5:$B$293,$B1608) -> 239 | AY1608: =SUMIFS(시군구_병원급!$E$5:$E$3668,시군구_병원급!$A$5:$A$3668,$A1608,시군구_병원급!$D$5:$D$3668,$D1608) -> 3 | AZ1608: =SUMIFS(시군구_병원급!$F$5:$F$3668,시군구_병원급!$A$5:$A$3668,$A1608,시군구_병원급!$D$5:$D$3668,$D1608) -> 2 | BA1608: =SUMIFS(시군구_병원급!$G$5:$G$3668,시군구_병원급!$A$5:$A$3668,$A1608,시군구_병원급!$D$5:$D$3668,$D1608) -> 6 | BB1608: =SUMIFS(시군구_병원급!$H$5:$H$3668,시군구_병원급!$A$5:$A$3668,$A1608,시군구_병원급!$D$5:$D$3668,$D1608) -> 10 | BC1608: =K1608+AY1608 -> 23 | BD1608: =IF(E1608=0,"",(K1608+AY1608)/E1608*1000) -> 2.3978315 | BE1608: =AY1608-SUMIFS(시군구_병원급!$E$5:$E$3668,시군구_병원급!$A$5:$A$3668,$A1608,시군구_병원급!$D$5:$D$3668,$D1608-3) -> 0 | BF1608: =IF(AY1608=0,1,0) -> 0 | BG1608: =IF(K1608+AY1608=0,1,0) -> 0 | BH1608: =AF1608+AG1608+AH1608 -> 9 | BI1608: =IF(H1608=0,"",BH1608/H1608) -> 0.061643836 | BJ1608: =IF(AP1608="","",AP1608+AN1608) -> 8
A1609: 11215 | B1609: 서울특별시 | C1609: 광진구 | D1609: 2023 | E1609: 7750 | F1609: 1120 | G1609: 1231 | H1609: 138 | I1609: 6083 | J1609: 4523 | K1609: 16 | L1609: 17.806452 | M1609: 2.0645161 | N1609: 0.74354759 | O1609: 0.78490323 | P1609: 0.15883871 | Q1609: -0.26288758 | R1609: -0.1964752 | S1609: -3 | T1609: -0.092105263 | U1609: -0.08291874 | V1609: 0 | AB1609: 예측(라벨 없음) | AC1609: 56 | AD1609: 40 | AE1609: 37 | AF1609: 4 | AG1609: 0 | AH1609: 1 | AI1609: 0.4057971 | AJ1609: 0.28985507 | AK1609: 0.26811594 | AL1609: 0.028985507 | AM1609: 0 | AN1609: 1 | AO1609: 0.0071942446 | AP1609: 16 | AQ1609: 2 | AR1609: 0.10457516 | AS1609: 0.013071895 | AT1609: =SUMIFS(시도_소아과개폐업!$C$5:$C$293,시도_소아과개폐업!$A$5:$A$293,$D1609,시도_소아과개폐업!$B$5:$B$293,$B1609) -> 88 | AU1609: =SUMIFS(시도_소아과개폐업!$D$5:$D$293,시도_소아과개폐업!$A$5:$A$293,$D1609,시도_소아과개폐업!$B$5:$B$293,$B1609) -> 66 | AV1609: =SUMIFS(시도_소아과개폐업!$F$5:$F$293,시도_소아과개폐업!$A$5:$A$293,$D1609,시도_소아과개폐업!$B$5:$B$293,$B1609) -> 22 | AW1609: =SUMIFS(시도_소아과개폐업!$G$5:$G$293,시도_소아과개폐업!$A$5:$A$293,$D1609,시도_소아과개폐업!$B$5:$B$293,$B1609) -> 0.14473684 | AX1609: =SUMIFS(시도_소아과개폐업!$H$5:$H$293,시도_소아과개폐업!$A$5:$A$293,$D1609,시도_소아과개폐업!$B$5:$B$293,$B1609) -> 239 | AY1609: =SUMIFS(시군구_병원급!$E$5:$E$3668,시군구_병원급!$A$5:$A$3668,$A1609,시군구_병원급!$D$5:$D$3668,$D1609) -> 2 | AZ1609: =SUMIFS(시군구_병원급!$F$5:$F$3668,시군구_병원급!$A$5:$A$3668,$A1609,시군구_병원급!$D$5:$D$3668,$D1609) -> 2 | BA1609: =SUMIFS(시군구_병원급!$G$5:$G$3668,시군구_병원급!$A$5:$A$3668,$A1609,시군구_병원급!$D$5:$D$3668,$D1609) -> 6 | BB1609: =SUMIFS(시군구_병원급!$H$5:$H$3668,시군구_병원급!$A$5:$A$3668,$A1609,시군구_병원급!$D$5:$D$3668,$D1609) -> 13 | BC1609: =K1609+AY1609 -> 18 | BD1609: =IF(E1609=0,"",(K1609+AY1609)/E1609*1000) -> 2.3225806 | BE1609: =AY1609-SUMIFS(시군구_병원급!$E$5:$E$3668,시군구_병원급!$A$5:$A$3668,$A1609,시군구_병원급!$D$5:$D$3668,$D1609-3) -> 0 | BF1609: =IF(AY1609=0,1,0) -> 0 | BG1609: =IF(K1609+AY1609=0,1,0) -> 0 | BH1609: =AF1609+AG1609+AH1609 -> 5 | BI1609: =IF(H1609=0,"",BH1609/H1609) -> 0.036231884 | BJ1609: =IF(AP1609="","",AP1609+AN1609) -> 17
